Workbook

Sheet RiskSim
A1: SLoYkPQu0APGq0MGAJtL/Znx8FCpo3cRlNPQCK/SFyLT/B4QTyMLOyBSaZwWhemND+QaxRaqbaokYwzkNEKoudMcp2llkonQIJ8RUhZJLOcPf2KwlDB5vgyLtFsNjh9EnCdjI3bdFnNru3MQvVP68pLjTs1Ebhh5aWEnoJXwgMOw5JbeZDEVdhYD46hUVw72MNXCm4OHn5F85WBxq7aWoVTR3uUf/csJNmMkO10Fc7G3LlnDwAeqVMzKP/4=
A2: MUgCgJOnYkm5j+UrD+6NuUtSY8JqaaZCNxQm//q0448CszIn2JibQlF4dfSSco0H1d8DVP0oQ1mtT/xHmDFPl3aLT7Uf00naMT+cv0rVWleqBtYO0lvw4Afibu2AMayXDs4Nf8dJ+b93GcWozDBteM2eWwNxDDeqUeHZLe4krvrI5ripOAtI5VvmmNRQDv09khYLxAZSySAwvOhPWNA4E638O6GQyv73lyaGpMakhLvF2mRzSF5wdaP3tRI=
A3: EUb9smIcD0l6CgXZ85Ws5wRU0XvX0tWcjBERchcCp+zckLJ8auqT02LoDER0DF+wg05rAwd5SwbqWGmtx9jmwDqrG0Xgev9dXBkGm1QCPZDeajcFFUGvnW/iHWTQnsdNpwUnJb+0hA9eky6j4aBVHYBksLLtWhIJ3bq6Fq/ny6Kx6pqrdd0vkdDXid9yTVXWt2PvKAahir8lpTSvxaC2kNVVIrdxfRDpQTl8XHseGkN2ozqWwkluA/1+TX0=
A4: qnGmY/mPshfzgZADqDZJf6rfR+COz3RyinSq9DtsO+0LvEilqhUaScz5kh+mYUS+ClFPsbHYkJpkC0IuRLsdIl+J6+au2tOh52lYqyBh6LnTVcePA0O4OY8YT7LioQIhLwOw53QG3VkzQMIWopHDNpFOuJXVX4UlSlCSgJnMe1y29JyBrBy0JWceHPtrMWg7ZF2CPD7IsGcEFyrAGsg/6IDhJWT3D74RSGZvUZZq/ca4H1lCTK+CamV0NKo=
A5: R4TFBXfN5cSMNW7Y21a7oQd/KX63cRQ626HnFW2GNhSUMk/Yl1+lwJSY2KbdLvvhwNetXiVagCAf4rY3MDtnYTMrvAzdV2Ap2Ltayoaq9B1giKO67cML301OoPOvdK119txgUgUDxgwEfbbi7s7iboHqT0gpA7RJZInx3elo8fojMNbXzslmdSqcolqYGq6JcijS01tu+k9zfE38rbA8FO3VFgElrXvwxse0yHhr8yyO1nIlgizwC9UYgaI=
A6: 9uIl0/E8YWjnSvrHASd9KNY2xvqnfj/yJ8jU+MG3EJqhM5URhE//7CKCtazG53a7YcILEm6uynI+ZjMf7P1bJ2jrZZMqyeSi/kGRtA64SWF4zkTd0BuH9SR5pvxaJdAfPk9liBf9jYHZp8wfS8MdHTMetO7nVJllQfGb82GjLgNp0aIy3Zrs9NlKHr3toXy1WBrHXOnkbZj8+2sK2NuzVllCTyDKEztGXkBduFL2mgo6hQUyafSmtdElP64=
A7: cgtYu5kbhRtmoV1uFoieM6HogBT4qbHGLJPtdEqObM0WnG6jfT0rPfit5ALuuE75YMEfqf87hFOEmAUc83t3h+nhulyK56PoR5B80mflaRs+4A1G5EsFbkYCZzRGfeBHQVxkqCV4u8vaKB4+JFUDuUw5k/aIQXkRk1O31FVePTEbyDbhsatLMssnl7fHfcBPGFurErPB5xOeBFtdZHR4sJ72xMrIHMrVYZPmLR7uplMCM29m6tb1uTicDWg=
A8: xxUhCQwsanceMKUOHH2lxhzMbmm9O92au5nq7dG53LdFu6GJwcUB/evYNDcho51kgCm+/iXOOCjWNDQkRQFw5q0fO+IlHoLQSMeuvkpCKCJr2J4kZXTrcEZa0J1QnjSKQlo6Lw7oEV7M01CTowOhGSBCN+1D5ThBZ2C9LNsDdsFydzNJXd/B1pfeibhFiC3r0N2KY/wQHkfoCooHrgDn26iE6Pq0LWPu/KKzug9+h9RX2J2dbbvEQwrw0Yg=
A9: tEcuD5XgkJM65E54Z4qO5fu4eDwVgjKJkEc74sFJ8bCiigOSclQmfeZabcR4WzT2BsMxyp0eiCYpY/MSBmrQPth0r1jZg733HMcCfBKJ3rVEbsQ/09C4ulIVy2RUSwhnwqN0dvZzdSoW59/C/vouTQ+G2zmYLAQ+N3TQvRla+/21hTV0NR9hZ0R1LP+8LLBJ0icZj4E9+y3cRsUoVTNxAIj6SGcwSnZCCwdr0XVgr5G6803gy8/c0tvQuig=
A10: tX9FxSmBPtk9D1ojkc5jV4FOvifS5iGJxJYXjtHiZCizxIKIYnI2mHuhHswIJxH6zeZiYdXqR5OaKNloYsO/0ir/CqEKO5gXh4n5MnSh1SXs47seH10augB1fWGIJG/o+I2LbznZVhQIKS0UKJtT88JbI+tgLoE+kSBbn5NGNDNxOov6E0DpD+blvTCCKP7NKuPg0HCafv9g7DfaWN/0fWOceXzc+YrbPFM2PjGcgUt6v2ydEl3K3uDb/PQ=
A11: wPcDONaGs5lSsKMCpMd5lTb1korMzc7QxMSP/KVtXDqhWXQvkbfKKPIoeOwJ0LxlG7MwpY1rF8wTpC+zR7XygZezhdI/3DH9/BHWZZag2/lZ0XJNhqDlkbU8xP3+7Du0dhKiyySgxeXbQ0QXWd5H0oZY3FaV0t7y2XGBrBHpFtVefcEsOg2f2bdKdvyUA7ftEhGRuHnGe1sNePM/LPZKdBR/Ji7dWcCMOVcgNj5DXbFsLQCAC1bl4Dbh2Zc=
A12: yjx6G3kpMZt1LEJiE1IPSOQup7MJDHg2xiN5VS2dydPSuhC9iBkqotlP18Yt8UvNdLKzR9UeJW+jstz4Nq2qsuAojOQ6/7rLiQUvjDsiKVHlekkDXfbEUsCNvIFxzuM825PXJlcLeNXKogZZBJ6eF5dtr+hKwuKsQbMyrsSBcJ3KdFhQdDhAnmBCZP3IENV+bWZ6V2oDJ5189uO4pUT8WAXF3EqMWxuyGZn00g0T+uvSe9AOYlSKSH3E05I=
... A1017: 76oMsGlG+ess+04GIMWAxegYb6Hq51IWfqsn9xjXUTlNUurHimCal6+5GrIvZCsVppP2/wdLgC1eVjF/RI4ycBxnJ3IFUl/8E52gSQ1Hnv138jH2G5hqh6aGMEdWKZYWdCSuLBSwgAAybkrkZzn6URRuAe7HDJUH

Sheet BD Original
A1: Fecha | B1: Apple | C1: Coca-Cola | D1: JPMorgan | E1: AT&T
A2: 45154 | B2: 175.67108 | C2: 58.602821 | D2: 146.50507 | E2: 13.196151
A3: 45155 | B3: 173.11415 | C3: 58.72879 | D3: 144.98335 | E3: 13.111919 | G3: Fuente: https://finance.yahoo.com/
A4: 45156 | B4: 173.60165 | C4: 59.058239 | D4: 145.315 | E4: 13.149357
A5: 45159 | B5: 174.94478 | C5: 58.554379 | D5: 145.8125 | E5: 13.196151
A6: 45160 | B6: 176.3277 | C6: 58.195862 | D6: 142.78856 | E6: 13.345895
A7: 45161 | B7: 180.19791 | C7: 58.399345 | D7: 143.75426 | E7: 13.252305
A8: 45162 | B8: 175.48202 | C8: 58.244312 | D8: 143.61769 | E8: 13.242945
A9: 45163 | B9: 177.7007 | C9: 58.515617 | D9: 143.44211 | E9: 13.205509
A10: 45166 | B10: 179.27266 | C10: 58.68034 | D10: 143.93961 | E10: 13.299099
A11: 45167 | B11: 183.18263 | C11: 58.622204 | D11: 145.11015 | E11: 13.823201
A12: 45168 | B12: 186.69466 | C12: 58.593136 | D12: 144.52487 | E12: 13.785766
A13: 45169 | B13: 186.91354 | C13: 57.973003 | D13: 142.73978 | E13: 13.841919
A14: 45170 | B14: 188.49547 | C14: 57.469139 | D14: 143.21776 | E14: 13.710893
A15: 45174 | B15: 188.73424 | C15: 56.994347 | D15: 141.63748 | E15: 13.551791
... A254: 45520 | B254: 226.05 | C254: 69.18 | D254: 213.97 | E254: 19.34

Sheet Precios
A1: Fecha | B1: Apple | C1: Coca-Cola | D1: JPMorgan | E1: AT&T
A2: 45154 | B2: 175.67108 | C2: 58.602821 | D2: 146.50507 | E2: 13.196151 | J2: 1. Ver cómo descargar datos desde Yahoo Finance
A3: 45155 | B3: 173.11415 | C3: 58.72879 | D3: 144.98335 | E3: 13.111919 | J3: 2. Análisis de Acciones
A4: 45156 | B4: 173.60165 | C4: 59.058239 | D4: 145.315 | E4: 13.149357 | J4: 3. Cálculo de Retorno
A5: 45159 | B5: 174.94478 | C5: 58.554379 | D5: 145.8125 | E5: 13.196151 | J5: 4. Análisis de Retornos
A6: 45160 | B6: 176.3277 | C6: 58.195862 | D6: 142.78856 | E6: 13.345895
A7: 45161 | B7: 180.19791 | C7: 58.399345 | D7: 143.75426 | E7: 13.252305 | O7: 1. Por qué son constantes CC y AT
A8: 45162 | B8: 175.48202 | C8: 58.244312 | D8: 143.61769 | E8: 13.242945 | O8: 2. Por qué JPMorgan no tiene cambios tan cambios abructos como Apple
A9: 45163 | B9: 177.7007 | C9: 58.515617 | D9: 143.44211 | E9: 13.205509
A10: 45166 | B10: 179.27266 | C10: 58.68034 | D10: 143.93961 | E10: 13.299099
A11: 45167 | B11: 183.18263 | C11: 58.622204 | D11: 145.11015 | E11: 13.823201
A12: 45168 | B12: 186.69466 | C12: 58.593136 | D12: 144.52487 | E12: 13.785766
A13: 45169 | B13: 186.91354 | C13: 57.973003 | D13: 142.73978 | E13: 13.841919
A14: 45170 | B14: 188.49547 | C14: 57.469139 | D14: 143.21776 | E14: 13.710893
A15: 45174 | B15: 188.73424 | C15: 56.994347 | D15: 141.63748 | E15: 13.551791
A16: 45175 | B16: 181.97881 | C16: 56.955589 | D16: 141.40341 | E16: 13.673458
A17: 45176 | B17: 176.65604 | C17: 56.519558 | D17: 140.1938 | E17: 13.673458
A18: 45177 | B18: 177.27286 | C18: 56.519558 | D18: 140.30112 | E18: 13.47692
A19: 45180 | B19: 178.44685 | C19: 57.052486 | D19: 140.91566 | E19: 13.589228
A20: 45181 | B20: 175.40245 | C20: 56.490486 | D20: 142.74954 | E20: 13.533073
... A254: 45520 | B254: 226.05 | C254: 69.18 | D254: 213.97 | E254: 19.34

Sheet Retorno
A1: Fecha | B1: Apple | C1: Coca-Cola | D1: JPMorgan | E1: AT&T | F1: Retornos Continuos | J1: Retornos Discretos | N1: t+1
A2: 45154 | B2: 175.67108 | C2: 58.602821 | D2: 146.50507 | E2: 13.196151 | F2: Apple | G2: Coca-Cola | H2: JPMorgan | I2: AT&T | J2: Apple | K2: Coca-Cola | L2: JPMorgan | M2: AT&T | N2: Apple t+1 | O2: Coca-Cola t+1 | P2: JPMorgan t+1 | Q2: AT&T t+1
A3: 45155 | B3: 173.11415 | C3: 58.72879 | D3: 144.98335 | E3: 13.111919 | F3: =LN(B3/B2) -> -0.014662185 | G3: =LN(C3/C2) -> 0.0021472312 | H3: =LN(D3/D2) -> -0.010441079 | I3: =LN(E3/E2) -> -0.0064035323 | J3: =(B3-B2)/B3 -> -0.014770202 | K3: =(C3-C2)/C3 -> 0.0021449276 | L3: =(D3-D2)/D3 -> -0.010495777 | M3: =(E3-E2)/E3 -> -0.0064240787 | N3: =F4 -> 0.0028121206 | O3: =G4 -> 0.0055939922 | P3: =H4 -> 0.0022848848 | Q3: =I4 -> 0.0028511962
A4: 45156 | B4: 173.60165 | C4: 59.058239 | D4: 145.315 | E4: 13.149357 | F4: =LN(B4/B3) -> 0.0028121206 | G4: =LN(C4/C3) -> 0.0055939922 | H4: =LN(D4/D3) -> 0.0022848848 | I4: =LN(E4/E3) -> 0.0028511962 | J4: =(B4-B3)/B4 -> 0.0028081702 | K4: =(C4-C3)/C4 -> 0.0055783749 | L4: =(D4-D3)/D4 -> 0.0022822764 | M4: =(E4-E3)/E4 -> 0.0028471354 | N4: =F5 -> 0.00770704 | O4: =G5 -> -0.0085681807 | P4: =H5 -> 0.0034177361 | Q4: =I5 -> 0.0035523361
A5: 45159 | B5: 174.94478 | C5: 58.554379 | D5: 145.8125 | E5: 13.196151 | F5: =LN(B5/B4) -> 0.00770704 | G5: =LN(C5/C4) -> -0.0085681807 | H5: =LN(D5/D4) -> 0.0034177361 | I5: =LN(E5/E4) -> 0.0035523361 | J5: =(B5-B4)/B5 -> 0.0076774169 | K5: =(C5-C4)/C5 -> -0.0086049926 | L5: =(D5-D4)/D5 -> 0.0034119023 | M5: =(E5-E4)/E5 -> 0.003546034 | N5: =F6 -> 0.0078738144 | O5: =G6 -> -0.0061416255 | P5: =H6 -> -0.020956622 | Q5: =I6 -> 0.011283651
A6: 45160 | B6: 176.3277 | C6: 58.195862 | D6: 142.78856 | E6: 13.345895 | F6: =LN(B6/B5) -> 0.0078738144 | G6: =LN(C6/C5) -> -0.0061416255 | H6: =LN(D6/D5) -> -0.020956622 | I6: =LN(E6/E5) -> 0.011283651 | J6: =(B6-B5)/B6 -> 0.0078428971 | K6: =(C6-C5)/C6 -> -0.0061605239 | L6: =(D6-D5)/D6 -> -0.021177754 | M6: =(E6-E5)/E6 -> 0.011220229 | N6: =F7 -> 0.02171154 | O6: =G7 -> 0.0034904215 | P6: =H7 -> 0.0067403655 | Q6: =I7 -> -0.0070373474
A7: 45161 | B7: 180.19791 | C7: 58.399345 | D7: 143.75426 | E7: 13.252305 | F7: =LN(B7/B6) -> 0.02171154 | G7: =LN(C7/C6) -> 0.0034904215 | H7: =LN(D7/D6) -> 0.0067403655 | I7: =LN(E7/E6) -> -0.0070373474 | J7: =(B7-B6)/B7 -> 0.021477541 | K7: =(C7-C6)/C7 -> 0.003484337 | L7: =(D7-D6)/D7 -> 0.0067177002 | M7: =(E7-E6)/E7 -> -0.0070621677 | N7: =F8 -> -0.026519109 | O7: =G8 -> -0.0026582344 | P7: =H8 -> -0.00095044775 | Q7: =I8 -> -0.00070654177
A8: 45162 | B8: 175.48202 | C8: 58.244312 | D8: 143.61769 | E8: 13.242945 | F8: =LN(B8/B7) -> -0.026519109 | G8: =LN(C8/C7) -> -0.0026582344 | H8: =LN(D8/D7) -> -0.00095044775 | I8: =LN(E8/E7) -> -0.00070654177 | J8: =(B8-B7)/B8 -> -0.026873869 | K8: =(C8-C7)/C8 -> -0.0026617706 | L8: =(D8-D7)/D8 -> -0.00095089957 | M8: =(E8-E7)/E8 -> -0.00070679143 | N8: =F9 -> 0.012564053 | O8: =G9 -> 0.0046472363 | P8: =H9 -> -0.0012233202 | Q8: =I9 -> -0.0028308668
A9: 45163 | B9: 177.7007 | C9: 58.515617 | D9: 143.44211 | E9: 13.205509 | F9: =LN(B9/B8) -> 0.012564053 | G9: =LN(C9/C8) -> 0.0046472363 | H9: =LN(D9/D8) -> -0.0012233202 | I9: =LN(E9/E8) -> -0.0028308668 | J9: =(B9-B8)/B9 -> 0.012485455 | K9: =(C9-C8)/C9 -> 0.0046364546 | L9: =(D9-D8)/D9 -> -0.0012240687 | M9: =(E9-E8)/E9 -> -0.0028348775 | N9: =F10 -> 0.0088072128 | O9: =G10 -> 0.0028110715 | P9: =H10 -> 0.0034622836 | Q9: =I10 -> 0.0070621976
A10: 45166 | B10: 179.27266 | C10: 58.68034 | D10: 143.93961 | E10: 13.299099 | F10: =LN(B10/B9) -> 0.0088072128 | G10: =LN(C10/C9) -> 0.0028110715 | H10: =LN(D10/D9) -> 0.0034622836 | I10: =LN(E10/E9) -> 0.0070621976 | J10: =(B10-B9)/B10 -> 0.0087685429 | K10: =(C10-C9)/C10 -> 0.0028071242 | L10: =(D10-D9)/D10 -> 0.0034562968 | M10: =(E10-E9)/E10 -> 0.0070373188 | N10: =F11 -> 0.021575763 | O10: =G11 -> -0.00099121473 | P10: =H11 -> 0.0080993211 | Q10: =I11 -> 0.038652124
A11: 45167 | B11: 183.18263 | C11: 58.622204 | D11: 145.11015 | E11: 13.823201 | F11: =LN(B11/B10) -> 0.021575763 | G11: =LN(C11/C10) -> -0.00099121473 | H11: =LN(D11/D10) -> 0.0080993211 | I11: =LN(E11/E10) -> 0.038652124 | J11: =(B11-B10)/B11 -> 0.021344671 | K11: =(C11-C10)/C11 -> -0.00099170615 | L11: =(D11-D10)/D11 -> 0.0080666099 | M11: =(E11-E10)/E11 -> 0.037914662 | N11: =F12 -> 0.018990782 | O11: =G12 -> -0.00049597605 | P11: =H12 -> -0.0040415126 | Q11: =I12 -> -0.0027118018
A12: 45168 | B12: 186.69466 | C12: 58.593136 | D12: 144.52487 | E12: 13.785766 | F12: =LN(B12/B11) -> 0.018990782 | G12: =LN(C12/C11) -> -0.00049597605 | H12: =LN(D12/D11) -> -0.0040415126 | I12: =LN(E12/E11) -> -0.0027118018 | J12: =(B12-B11)/B12 -> 0.018811594 | K12: =(C12-C11)/C12 -> -0.00049609907 | L12: =(D12-D11)/D12 -> -0.0040496905 | M12: =(E12-E11)/E12 -> -0.002715482 | N12: =F13 -> 0.0011717517 | O12: =G13 -> -0.01064012 | P12: =H13 -> -0.012428386 | Q12: =I13 -> 0.0040649861
A13: 45169 | B13: 186.91354 | C13: 57.973003 | D13: 142.73978 | E13: 13.841919 | F13: =LN(B13/B12) -> 0.0011717517 | G13: =LN(C13/C12) -> -0.01064012 | H13: =LN(D13/D12) -> -0.012428386 | I13: =LN(E13/E12) -> 0.0040649861 | J13: =(B13-B12)/B13 -> 0.0011710655 | K13: =(C13-C12)/C13 -> -0.010696927 | L13: =(D13-D12)/D13 -> -0.012505939 | M13: =(E13-E12)/E13 -> 0.0040567352 | N13: =F14 -> 0.0084277858 | O13: =G14 -> -0.008729346 | P13: =H14 -> 0.003343024 | Q13: =I14 -> -0.0095109703
A14: 45170 | B14: 188.49547 | C14: 57.469139 | D14: 143.21776 | E14: 13.710893 | F14: =LN(B14/B13) -> 0.0084277858 | G14: =LN(C14/C13) -> -0.008729346 | H14: =LN(D14/D13) -> 0.003343024 | I14: =LN(E14/E13) -> -0.0095109703 | J14: =(B14-B13)/B14 -> 0.0083923715 | K14: =(C14-C13)/C14 -> -0.0087675578 | L14: =(D14-D13)/D14 -> 0.0033374423 | M14: =(E14-E13)/E14 -> -0.0095563433 | N14: =F15 -> 0.0012659132 | O14: =G15 -> -0.0082960032 | P14: =H15 -> -0.011095406 | Q14: =I15 -> -0.011671911
... A23: 45184 | B23: 174.119 | C23: 56.587074 | D23: 145.15892 | E23: 14.253714 | F23: =LN(B23/B22) -> -0.0041626265 | G23: =LN(C23/C22) -> -0.0089348416 | H23: =LN(D23/D22) -> -0.0029524998 | I23: =LN(E23/E22) -> 0.011224979 | J23: =(B23-B22)/B23 -> -0.0041713023 | K23: =(C23-C22)/C23 -> -0.0089748765 | L23: =(D23-D22)/D23 -> -0.0029568627 | M23: =(E23-E22)/E23 -> 0.011162214 | N23: =F24 -> 0.016771886 | O23: =G24 -> 0.0061940864 | P23: =H24 -> 0.0020810602 | Q23: =I24 -> -0.0092349221
A24: 45187 | B24: 177.06393 | C24: 56.938667 | D24: 145.46132 | E24: 14.122688 | F24: =LN(B24/B23) -> 0.016771886 | G24: =LN(C24/C23) -> 0.0061940864 | H24: =LN(D24/D23) -> 0.0020810602 | I24: =LN(E24/E23) -> -0.0092349221 | J24: =(B24-B23)/B24 -> 0.016632021 | K24: =(C24-C23)/C24 -> 0.0061749426 | L24: =(D24-D23)/D24 -> 0.0020788963 | M24: =(E24-E23)/E24 -> -0.0092776956 | N24: =F25 -> 0.006161829 | O24: =G25 -> -0.0020603885 | P24: =H25 -> -0.0012750275 | Q24: =I25 -> 0.0079209278 | T24: Apple | U24: Coca-Cola | V24: JPMorgan | W24: AT&T | Z24: Apple | AA24: Coca-Cola | AB24: JPMorgan | AC24: AT&T
A25: 45188 | B25: 178.15834 | C25: 56.821472 | D25: 145.27597 | E25: 14.234997 | F25: =LN(B25/B24) -> 0.006161829 | G25: =LN(C25/C24) -> -0.0020603885 | H25: =LN(D25/D24) -> -0.0012750275 | I25: =LN(E25/E24) -> 0.0079209278 | J25: =(B25-B24)/B25 -> 0.0061428839 | K25: =(C25-C24)/C25 -> -0.0020625126 | L25: =(D25-D24)/D25 -> -0.0012758407 | M25: =(E25-E24)/E25 -> 0.0078896399 | N25: =F26 -> -0.02019469 | O25: =G26 -> 0.0044589358 | P25: =H26 -> -0.0042389693 | Q25: =I26 -> 0.022107528 | S25: Media | T25: 0.0010005668 | U25: 0.00065844829 | V25: 0.0015030786 | W25: 0.0015168662 | Y25: Apple | Z25: 1
A26: 45189 | B26: 174.59657 | C26: 57.075401 | D26: 144.66145 | E26: 14.553202 | F26: =LN(B26/B25) -> -0.02019469 | G26: =LN(C26/C25) -> 0.0044589358 | H26: =LN(D26/D25) -> -0.0042389693 | I26: =LN(E26/E25) -> 0.022107528 | J26: =(B26-B25)/B26 -> -0.020399982 | K26: =(C26-C25)/C26 -> 0.0044490095 | L26: =(D26-D25)/D26 -> -0.0042479665 | M26: =(E26-E25)/E26 -> 0.021864948 | N26: =F27 -> -0.0089290842 | O26: =G27 -> -0.015520182 | P26: =H27 -> -0.007852781 | Q26: =I27 -> -0.015554405 | S26: Error típico | T26: 0.00090188668 | U26: 0.00053006717 | V26: 0.00073330291 | W26: 0.00084396576 | Y26: Coca-Cola | Z26: 0.092908388 | AA26: 1
A27: 45190 | B27: 173.04452 | C27: 56.196419 | D27: 143.52991 | E27: 14.328587 | F27: =LN(B27/B26) -> -0.0089290842 | G27: =LN(C27/C26) -> -0.015520182 | H27: =LN(D27/D26) -> -0.007852781 | I27: =LN(E27/E26) -> -0.015554405 | J27: =(B27-B26)/B27 -> -0.0089690674 | K27: =(C27-C26)/C27 -> -0.015641246 | L27: =(D27-D26)/D27 -> -0.0078836949 | M27: =(E27-E26)/E27 -> -0.015676005 | N27: =F28 -> 0.0049321571 | O27: =G28 -> 0.0010421744 | P27: =H28 -> -0.009629071 | Q27: =I28 -> -0.012488017 | S27: Mediana | T27: 0.0019470367 | U27: 0.0010502723 | V27: 0.0020270955 | W27: 0.001411637 | Y27: JPMorgan | Z27: 0.047823405 | AA27: 0.18624002 | AB27: 1
A28: 45191 | B28: 173.90012 | C28: 56.255016 | D28: 142.15448 | E28: 14.150764 | F28: =LN(B28/B27) -> 0.0049321571 | G28: =LN(C28/C27) -> 0.0010421744 | H28: =LN(D28/D27) -> -0.009629071 | I28: =LN(E28/E27) -> -0.012488017 | J28: =(B28-B27)/B28 -> 0.004920014 | K28: =(C28-C27)/C28 -> 0.0010416316 | L28: =(D28-D27)/D28 -> -0.0096755797 | M28: =(E28-E27)/E28 -> -0.012566318 | N28: =F29 -> 0.0073532672 | O28: =G29 -> -0.01047125 | P28: =H29 -> 0.0049286703 | Q28: =I29 -> -0.0039760898 | S28: Moda | T28: #N/A | U28: 0 | V28: #N/A | W28: 0 | Y28: AT&T | Z28: -0.019839153 | AA28: 0.34877913 | AB28: 0.18621074 | AC28: 1
A29: 45194 | B29: 175.18356 | C29: 55.669029 | D29: 142.85684 | E29: 14.094611 | F29: =LN(B29/B28) -> 0.0073532672 | G29: =LN(C29/C28) -> -0.01047125 | H29: =LN(D29/D28) -> 0.0049286703 | I29: =LN(E29/E28) -> -0.0039760898 | J29: =(B29-B28)/B29 -> 0.0073262981 | K29: =(C29-C28)/C29 -> -0.010526266 | L29: =(D29-D28)/D29 -> 0.0049165444 | M29: =(E29-E28)/E29 -> -0.003984005 | N29: =F30 -> -0.02367657 | O29: =G30 -> -0.0082798818 | P29: =H30 -> -0.010433243 | Q29: =I30 -> -0.002659513 | S29: Desviación estándar | T29: 0.014317007 | U29: 0.0084145555 | V29: 0.011640823 | W29: 0.013397541
A30: 45195 | B30: 171.08453 | C30: 55.209999 | D30: 141.37413 | E30: 14.057176 | F30: =LN(B30/B29) -> -0.02367657 | G30: =LN(C30/C29) -> -0.0082798818 | H30: =LN(D30/D29) -> -0.010433243 | I30: =LN(E30/E29) -> -0.002659513 | J30: =(B30-B29)/B30 -> -0.023959086 | K30: =(C30-C29)/C30 -> -0.0083142548 | L30: =(D30-D29)/D30 -> -0.010487859 | M30: =(E30-E29)/E30 -> -0.0026630527 | N30: =F31 -> -0.0089372741 | O30: =G31 -> -0.010313022 | P30: =H31 -> 0.0058476761 | Q30: =I31 -> -0.010036916 | S30: Varianza de la muestra | T30: 0.00020497669 | U30: 7.0804744e-05 | V30: 0.00013550876 | W30: 0.00017949411
A31: 45196 | B31: 169.56232 | C31: 54.643543 | D31: 142.20326 | E31: 13.916791 | F31: =LN(B31/B30) -> -0.0089372741 | G31: =LN(C31/C30) -> -0.010313022 | H31: =LN(D31/D30) -> 0.0058476761 | I31: =LN(E31/E30) -> -0.010036916 | J31: =(B31-B30)/B31 -> -0.0089773307 | K31: =(C31-C30)/C31 -> -0.010366385 | L31: =(D31-D30)/D31 -> 0.0058306117 | M31: =(E31-E30)/E31 -> -0.010087455 | N31: =F32 -> 0.0015245124 | O31: =G32 -> -0.0025052794 | P31: =H32 -> 0.012339653 | Q31: =I32 -> 0.0093709133 | S31: Curtosis | T31: 3.1993752 | U31: 5.0354703 | V31: 5.9450521 | W31: 2.3858239
A32: 45197 | B32: 169.82101 | C32: 54.506817 | D32: 143.96887 | E32: 14.047817 | F32: =LN(B32/B31) -> 0.0015245124 | G32: =LN(C32/C31) -> -0.0025052794 | H32: =LN(D32/D31) -> 0.012339653 | I32: =LN(E32/E31) -> 0.0093709133 | J32: =(B32-B31)/B32 -> 0.0015233509 | K32: =(C32-C31)/C32 -> -0.0025084202 | L32: =(D32-D31)/D32 -> 0.012263832 | M32: =(E32-E31)/E32 -> 0.0093271431 | N32: =F33 -> 0.0030418118 | O32: =G33 -> 0.0030412832 | P32: =H33 -> -0.017566588 | Q32: =I33 -> 0.00066600268 | S32: Coeficiente de asimetría | T32: 0.26385726 | U32: -0.51847268 | V32: -1.4361975 | W32: 0.55654666
A33: 45198 | B33: 170.33836 | C33: 54.67284 | D33: 141.46191 | E33: 14.057176 | F33: =LN(B33/B32) -> 0.0030418118 | G33: =LN(C33/C32) -> 0.0030412832 | H33: =LN(D33/D32) -> -0.017566588 | I33: =LN(E33/E32) -> 0.00066600268 | J33: =(B33-B32)/B33 -> 0.0030371901 | K33: =(C33-C32)/C33 -> 0.0030366632 | L33: =(D33-D32)/D33 -> -0.017721788 | M33: =(E33-E32)/E33 -> 0.00066578095 | N33: =F34 -> 0.014726613 | O33: =G34 -> -0.0089718562 | P33: =H34 -> -0.0086567489 | Q33: =I34 -> -0.023578125 | S33: Rango | T33: 0.11949705 | U33: 0.077973266 | V33: 0.094393619 | W33: 0.10225349
A34: 45201 | B34: 172.86543 | C34: 54.184517 | D34: 140.2426 | E34: 13.729611 | F34: =LN(B34/B33) -> 0.014726613 | G34: =LN(C34/C33) -> -0.0089718562 | H34: =LN(D34/D33) -> -0.0086567489 | I34: =LN(E34/E33) -> -0.023578125 | J34: =(B34-B33)/B34 -> 0.014618706 | K34: =(C34-C33)/C34 -> -0.0090122239 | L34: =(D34-D33)/D34 -> -0.0086943269 | M34: =(E34-E33)/E34 -> -0.023858287 | N34: =F35 -> -0.0078002014 | O34: =G35 -> -0.010873561 | P34: =H35 -> -0.0074001161 | Q34: =I35 -> 0.0074704184 | S34: Mínimo | T34: -0.049365633 | U34: -0.049535374 | V34: -0.066864291 | W34: -0.038675611
A35: 45202 | B35: 171.52229 | C35: 53.59853 | D35: 139.20862 | E35: 13.832561 | F35: =LN(B35/B34) -> -0.0078002014 | G35: =LN(C35/C34) -> -0.010873561 | H35: =LN(D35/D34) -> -0.0074001161 | I35: =LN(E35/E34) -> 0.0074704184 | J35: =(B35-B34)/B35 -> -0.0078307022 | K35: =(C35-C34)/C35 -> -0.010932893 | L35: =(D35-D34)/D35 -> -0.0074275646 | M35: =(E35-E34)/E35 -> 0.0074425842 | N35: =F36 -> 0.0072820978 | O35: =G36 -> 0.00291123 | P35: =H36 -> 0.0044743813 | Q35: =I36 -> -0.0088346793 | S35: Máximo | T35: 0.070131414 | U35: 0.028437891 | V35: 0.027529327 | W35: 0.063577877
A36: 45203 | B36: 172.77589 | C36: 53.754795 | D36: 139.83289 | E36: 13.710893 | F36: =LN(B36/B35) -> 0.0072820978 | G36: =LN(C36/C35) -> 0.00291123 | H36: =LN(D36/D35) -> 0.0044743813 | I36: =LN(E36/E35) -> -0.0088346793 | J36: =(B36-B35)/B36 -> 0.0072556476 | K36: =(C36-C35)/C36 -> 0.0029069965 | L36: =(D36-D35)/D36 -> 0.0044643862 | M36: =(E36-E35)/E36 -> -0.0088738203 | N36: =F37 -> 0.0071721957 | O36: =G37 -> -0.049535374 | P36: =H37 -> 0.0042075902 | Q36: =I37 -> 0.012211858 | S36: Suma | T36: 0.25214283 | U36: 0.16592897 | V36: 0.37877581 | W36: 0.38225029
A37: 45204 | B37: 174.01953 | C37: 51.156906 | D37: 140.42248 | E37: 13.879355 | F37: =LN(B37/B36) -> 0.0071721957 | G37: =LN(C37/C36) -> -0.049535374 | H37: =LN(D37/D36) -> 0.0042075902 | I37: =LN(E37/E36) -> 0.012211858 | J37: =(B37-B36)/B37 -> 0.0071465369 | K37: =(C37-C36)/C37 -> -0.050782762 | L37: =(D37-D36)/D37 -> 0.0041987506 | M37: =(E37-E36)/E37 -> 0.012137596 | N37: =F38 -> 0.014642797 | O37: =G38 -> 0.014405069 | P37: =H38 -> 0.015278133 | Q37: =I38 -> -0.0070340122 | S37: Cuenta | T37: 252 | U37: 252 | V37: 252 | W37: 252
A38: 45205 | B38: 176.58641 | C38: 51.899158 | D38: 142.58435 | E38: 13.78207 | F38: =LN(B38/B37) -> 0.014642797 | G38: =LN(C38/C37) -> 0.014405069 | H38: =LN(D38/D37) -> 0.015278133 | I38: =LN(E38/E37) -> -0.0070340122 | J38: =(B38-B37)/B38 -> 0.014536113 | K38: =(C38-C37)/C38 -> 0.014301812 | L38: =(D38-D37)/D38 -> 0.015162015 | M38: =(E38-E37)/E38 -> -0.007058809 | N38: =F39 -> 0.0084155365 | O38: =G39 -> -0.0049046695 | P38: =H39 -> -0.0022767876 | Q38: =I39 -> 0.019191787
A39: 45208 | B39: 178.07875 | C39: 51.645233 | D39: 142.26009 | E39: 14.049127 | F39: =LN(B39/B38) -> 0.0084155365 | G39: =LN(C39/C38) -> -0.0049046695 | H39: =LN(D39/D38) -> -0.0022767876 | I39: =LN(E39/E38) -> 0.019191787 | J39: =(B39-B38)/B39 -> 0.008380225 | K39: =(C39-C38)/C39 -> -0.0049167171 | L39: =(D39-D38)/D39 -> -0.0022793814 | M39: =(E39-E38)/E39 -> 0.019008797 | N39: =F40 -> -0.0033577377 | O39: =G40 -> 0.021514156 | P39: =H40 -> 0.0060600171 | Q39: =I40 -> 0.015493841 | S39: Máxima JPMorgan | T39: =_xlfn.PERCENTRANK.INC(F3:F254,$V$35) -> 0.979 | U39: =_xlfn.PERCENTRANK.INC(G3:G254,$V$35) -> 0.999 | V39: =_xlfn.PERCENTRANK.INC(H3:H254,$V$35) -> #N/A | W39: =_xlfn.PERCENTRANK.INC(I3:I254,$V$35) -> 0.96
A40: 45209 | B40: 177.48181 | C40: 52.768375 | D40: 143.1248 | E40: 14.268497 | F40: =LN(B40/B39) -> -0.0033577377 | G40: =LN(C40/C39) -> 0.021514156 | H40: =LN(D40/D39) -> 0.0060600171 | I40: =LN(E40/E39) -> 0.015493841 | J40: =(B40-B39)/B40 -> -0.0033633813 | K40: =(C40-C39)/C40 -> 0.021284377 | L40: =(D40-D39)/D40 -> 0.0060416922 | M40: =(E40-E39)/E40 -> 0.015374429 | N40: =F41 -> 0.0078729257 | O40: =G41 -> -0.0059402086 | P40: =H41 -> 0.0034271246 | Q40: =I41 -> -0.012781979
A41: 45210 | B41: 178.88463 | C41: 52.455849 | D41: 143.61615 | E41: 14.087278 | F41: =LN(B41/B40) -> 0.0078729257 | G41: =LN(C41/C40) -> -0.0059402086 | H41: =LN(D41/D40) -> 0.0034271246 | I41: =LN(E41/E40) -> -0.012781979 | J41: =(B41-B40)/B41 -> 0.0078420154 | K41: =(C41-C40)/C41 -> -0.0059578866 | L41: =(D41-D40)/D41 -> 0.0034212587 | M41: =(E41-E40)/E41 -> -0.012864018 | N41: =F42 -> 0.0050484915 | O41: =G42 -> -0.016898606 | P41: =H42 -> -0.0023292037 | Q41: =I42 -> -0.021903649 | S41: H0: La variable se distribuye como una normal
A42: 45211 | B42: 179.79001 | C42: 51.576866 | D42: 143.28203 | E42: 13.78207 | F42: =LN(B42/B41) -> 0.0050484915 | G42: =LN(C42/C41) -> -0.016898606 | H42: =LN(D42/D41) -> -0.0023292037 | I42: =LN(E42/E41) -> -0.021903649 | J42: =(B42-B41)/B42 -> 0.0050357693 | K42: =(C42-C41)/C42 -> -0.017042195 | L42: =(D42-D41)/D42 -> -0.0023319184 | M42: =(E42-E41)/E42 -> -0.022145295 | N42: =F43 -> -0.010346128 | O42: =G43 -> 0.0015136609 | P42: =H43 -> 0.014908028 | Q42: =I43 -> -0.0062479325 | S42: Test de Jarque-Beta | T42: =(T32^2)/6+(T31^2)/24 -> 0.43810351 | U42: =(U32^2)/6+(U31^2)/24 -> 1.1013007 | V42: =(V32^2)/6+(V31^2)/24 -> 1.8164291 | W42: =(W32^2)/6+(W31^2)/24 -> 0.28879719
A43: 45212 | B43: 177.93947 | C43: 51.654995 | D43: 145.43408 | E43: 13.696229 | F43: =LN(B43/B42) -> -0.010346128 | G43: =LN(C43/C42) -> 0.0015136609 | H43: =LN(D43/D42) -> 0.014908028 | I43: =LN(E43/E42) -> -0.0062479325 | J43: =(B43-B42)/B43 -> -0.010399834 | K43: =(C43-C42)/C43 -> 0.0015125159 | L43: =(D43-D42)/D43 -> 0.014797453 | M43: =(E43-E42)/E43 -> -0.0062674916 | N43: =F44 -> -0.00072710134 | O43: =G44 -> 0.010158067 | P43: =H44 -> -0.0010140315 | Q43: =I44 -> 0.0034759323 | S43: p-value | T43: =CHIDIST(T42,2) -> 0.80328014 | U43: =CHIDIST(U42,2) -> 0.57657472 | V43: =CHIDIST(V42,2) -> 0.40324356 | W43: =CHIDIST(W42,2) -> 0.86554268
A44: 45215 | B44: 177.81014 | C44: 52.182384 | D44: 145.28668 | E44: 13.743919 | F44: =LN(B44/B43) -> -0.00072710134 | G44: =LN(C44/C43) -> 0.010158067 | H44: =LN(D44/D43) -> -0.0010140315 | I44: =LN(E44/E43) -> 0.0034759323 | J44: =(B44-B43)/B44 -> -0.00072736574 | K44: =(C44-C43)/C44 -> 0.010106648 | L44: =(D44-D43)/D44 -> -0.0010145458 | M44: =(E44-E43)/E44 -> 0.0034698982 | N44: =F45 -> -0.0088236168 | O44: =G45 -> 0.011907237 | P44: =H45 -> -0.0021668113 | Q44: =I45 -> 0.011728317
A45: 45216 | B45: 176.24811 | C45: 52.807446 | D45: 144.97221 | E45: 13.906061 | F45: =LN(B45/B44) -> -0.0088236168 | G45: =LN(C45/C44) -> 0.011907237 | H45: =LN(D45/D44) -> -0.0021668113 | I45: =LN(E45/E44) -> 0.011728317 | J45: =(B45-B44)/B45 -> -0.0088626597 | K45: =(C45-C44)/C45 -> 0.011836626 | L45: =(D45-D44)/D45 -> -0.0021691605 | M45: =(E45-E44)/E45 -> 0.011659808 | N45: =F46 -> -0.007422337 | O45: =G46 -> -0.00037001628 | P45: =H46 -> -0.011041381 | Q45: =I46 -> -0.017993647
A46: 45217 | B46: 174.94478 | C46: 52.78791 | D46: 143.38032 | E46: 13.658078 | F46: =LN(B46/B45) -> -0.007422337 | G46: =LN(C46/C45) -> -0.00037001628 | H46: =LN(D46/D45) -> -0.011041381 | I46: =LN(E46/E45) -> -0.017993647 | J46: =(B46-B45)/B46 -> -0.0074499509 | K46: =(C46-C45)/C46 -> -0.00037008474 | L46: =(D46-D45)/D46 -> -0.011102562 | M46: =(E46-E45)/E46 -> -0.018156508 | N46: =F47 -> -0.0021632257 | O46: =G47 -> 0.0055350153 | P46: =H47 -> -0.0042583678 | Q46: =I47 -> 0.063577877
A47: 45218 | B47: 174.56674 | C47: 53.080902 | D47: 142.77106 | E47: 14.554628 | F47: =LN(B47/B46) -> -0.0021632257 | G47: =LN(C47/C46) -> 0.0055350153 | H47: =LN(D47/D46) -> -0.0042583678 | I47: =LN(E47/E46) -> 0.063577877 | J47: =(B47-B46)/B47 -> -0.0021655671 | K47: =(C47-C46)/C47 -> 0.0055197253 | L47: =(D47-D46)/D47 -> -0.0042674476 | M47: =(E47-E46)/E47 -> 0.061598964 | N47: =F48 -> -0.014813464 | O47: =G48 -> 0.0040397446 | P47: =H48 -> -0.016236772 | Q47: =I48 -> 0.007833063
A48: 45219 | B48: 171.99986 | C48: 53.295769 | D48: 140.47163 | E48: 14.669083 | F48: =LN(B48/B47) -> -0.014813464 | G48: =LN(C48/C47) -> 0.0040397446 | H48: =LN(D48/D47) -> -0.016236772 | I48: =LN(E48/E47) -> 0.007833063 | J48: =(B48-B47)/B48 -> -0.014923727 | K48: =(C48-C47)/C48 -> 0.0040315958 | L48: =(D48-D47)/D48 -> -0.016369305 | M48: =(E48-E47)/E48 -> 0.0078024645 | N48: =F49 -> 0.0006938528 | O48: =G49 -> -0.0090198437 | P48: =H49 -> -0.013735077 | Q48: =I49 -> -0.028356671
...

Sheet Portafolio
A1: Fecha | B1: Apple | C1: Coca-Cola | D1: JPMorgan | E1: AT&T | F1: Rentabilidad
A2: 45154 | B2: 175.67108 | C2: 58.602821 | D2: 146.50507 | E2: 13.196151 | F2: ="r_"&B1 -> r_Apple | G2: ="r_"&C1 -> r_Coca-Cola | H2: ="r_"&D1 -> r_JPMorgan | I2: ="r_"&E1 -> r_AT&T | J2: Portafolio
A3: 45155 | B3: 173.11415 | C3: 58.72879 | D3: 144.98335 | E3: 13.111919 | F3: =LN(B3/B2) -> -0.014662185 | G3: =LN(C3/C2) -> 0.0021472312 | H3: =LN(D3/D2) -> -0.010441079 | I3: =LN(E3/E2) -> -0.0064035323 | J3: =SUMPRODUCT(F3:I3,$M$37:$P$37) -> -0.009467057
A4: 45156 | B4: 173.60165 | C4: 59.058239 | D4: 145.315 | E4: 13.149357 | F4: =LN(B4/B3) -> 0.0028121206 | G4: =LN(C4/C3) -> 0.0055939922 | H4: =LN(D4/D3) -> 0.0022848848 | I4: =LN(E4/E3) -> 0.0028511962 | J4: =SUMPRODUCT(F4:I4,$M$37:$P$37) -> 0.0027076334
A5: 45159 | B5: 174.94478 | C5: 58.554379 | D5: 145.8125 | E5: 13.196151 | F5: =LN(B5/B4) -> 0.00770704 | G5: =LN(C5/C4) -> -0.0085681807 | H5: =LN(D5/D4) -> 0.0034177361 | I5: =LN(E5/E4) -> 0.0035523361 | J5: =SUMPRODUCT(F5:I5,$M$37:$P$37) -> 0.0038265778
A6: 45160 | B6: 176.3277 | C6: 58.195862 | D6: 142.78856 | E6: 13.345895 | F6: =LN(B6/B5) -> 0.0078738144 | G6: =LN(C6/C5) -> -0.0061416255 | H6: =LN(D6/D5) -> -0.020956622 | I6: =LN(E6/E5) -> 0.011283651 | J6: =SUMPRODUCT(F6:I6,$M$37:$P$37) -> -0.004214152
A7: 45161 | B7: 180.19791 | C7: 58.399345 | D7: 143.75426 | E7: 13.252305 | F7: =LN(B7/B6) -> 0.02171154 | G7: =LN(C7/C6) -> 0.0034904215 | H7: =LN(D7/D6) -> 0.0067403655 | I7: =LN(E7/E6) -> -0.0070373474 | J7: =SUMPRODUCT(F7:I7,$M$37:$P$37) -> 0.0051511975
A8: 45162 | B8: 175.48202 | C8: 58.244312 | D8: 143.61769 | E8: 13.242945 | F8: =LN(B8/B7) -> -0.026519109 | G8: =LN(C8/C7) -> -0.0026582344 | H8: =LN(D8/D7) -> -0.00095044775 | I8: =LN(E8/E7) -> -0.00070654177 | J8: =SUMPRODUCT(F8:I8,$M$37:$P$37) -> -0.0060379501
A9: 45163 | B9: 177.7007 | C9: 58.515617 | D9: 143.44211 | E9: 13.205509 | F9: =LN(B9/B8) -> 0.012564053 | G9: =LN(C9/C8) -> 0.0046472363 | H9: =LN(D9/D8) -> -0.0012233202 | I9: =LN(E9/E8) -> -0.0028308668 | J9: =SUMPRODUCT(F9:I9,$M$37:$P$37) -> 0.0012464294
A10: 45166 | B10: 179.27266 | C10: 58.68034 | D10: 143.93961 | E10: 13.299099 | F10: =LN(B10/B9) -> 0.0088072128 | G10: =LN(C10/C9) -> 0.0028110715 | H10: =LN(D10/D9) -> 0.0034622836 | I10: =LN(E10/E9) -> 0.0070621976 | J10: =SUMPRODUCT(F10:I10,$M$37:$P$37) -> 0.0056612861
A11: 45167 | B11: 183.18263 | C11: 58.622204 | D11: 145.11015 | E11: 13.823201 | F11: =LN(B11/B10) -> 0.021575763 | G11: =LN(C11/C10) -> -0.00099121473 | H11: =LN(D11/D10) -> 0.0080993211 | I11: =LN(E11/E10) -> 0.038652124 | J11: =SUMPRODUCT(F11:I11,$M$37:$P$37) -> 0.020261285
A12: 45168 | B12: 186.69466 | C12: 58.593136 | D12: 144.52487 | E12: 13.785766 | F12: =LN(B12/B11) -> 0.018990782 | G12: =LN(C12/C11) -> -0.00049597605 | H12: =LN(D12/D11) -> -0.0040415126 | I12: =LN(E12/E11) -> -0.0027118018 | J12: =SUMPRODUCT(F12:I12,$M$37:$P$37) -> 0.0011226617
A13: 45169 | B13: 186.91354 | C13: 57.973003 | D13: 142.73978 | E13: 13.841919 | F13: =LN(B13/B12) -> 0.0011717517 | G13: =LN(C13/C12) -> -0.01064012 | H13: =LN(D13/D12) -> -0.012428386 | I13: =LN(E13/E12) -> 0.0040649861 | J13: =SUMPRODUCT(F13:I13,$M$37:$P$37) -> -0.0043288022
A14: 45170 | B14: 188.49547 | C14: 57.469139 | D14: 143.21776 | E14: 13.710893 | F14: =LN(B14/B13) -> 0.0084277858 | G14: =LN(C14/C13) -> -0.008729346 | H14: =LN(D14/D13) -> 0.003343024 | I14: =LN(E14/E13) -> -0.0095109703 | J14: =SUMPRODUCT(F14:I14,$M$37:$P$37) -> -0.00027929642
... A23: 45184 | B23: 174.119 | C23: 56.587074 | D23: 145.15892 | E23: 14.253714 | F23: =LN(B23/B22) -> -0.0041626265 | G23: =LN(C23/C22) -> -0.0089348416 | H23: =LN(D23/D22) -> -0.0029524998 | I23: =LN(E23/E22) -> 0.011224979 | J23: =SUMPRODUCT(F23:I23,$M$37:$P$37) -> 0.001131343
A24: 45187 | B24: 177.06393 | C24: 56.938667 | D24: 145.46132 | E24: 14.122688 | F24: =LN(B24/B23) -> 0.016771886 | G24: =LN(C24/C23) -> 0.0061940864 | H24: =LN(D24/D23) -> 0.0020810602 | I24: =LN(E24/E23) -> -0.0092349221 | J24: =SUMPRODUCT(F24:I24,$M$37:$P$37) -> 0.0015301137 | L24: diario | M24: Apple | N24: Coca-Cola | O24: JPMorgan | P24: AT&T
A25: 45188 | B25: 178.15834 | C25: 56.821472 | D25: 145.27597 | E25: 14.234997 | F25: =LN(B25/B24) -> 0.006161829 | G25: =LN(C25/C24) -> -0.0020603885 | H25: =LN(D25/D24) -> -0.0012750275 | I25: =LN(E25/E24) -> 0.0079209278 | J25: =SUMPRODUCT(F25:I25,$M$37:$P$37) -> 0.0031390479 | L25: promedio | M25: =AVERAGE(F3:F254) -> 0.0010005668 | N25: =AVERAGE(G3:G254) -> 0.00065844829 | O25: =AVERAGE(H3:H254) -> 0.0015030786 | P25: =AVERAGE(I3:I254) -> 0.0015168662
A26: 45189 | B26: 174.59657 | C26: 57.075401 | D26: 144.66145 | E26: 14.553202 | F26: =LN(B26/B25) -> -0.02019469 | G26: =LN(C26/C25) -> 0.0044589358 | H26: =LN(D26/D25) -> -0.0042389693 | I26: =LN(E26/E25) -> 0.022107528 | J26: =SUMPRODUCT(F26:I26,$M$37:$P$37) -> 0.0014273245 | L26: mediana | M26: =MEDIAN(F3:F254) -> 0.0019470367 | N26: =MEDIAN(G3:G254) -> 0.0010502723 | O26: =MEDIAN(H3:H254) -> 0.0020270955 | P26: =MEDIAN(I3:I254) -> 0.001411637
A27: 45190 | B27: 173.04452 | C27: 56.196419 | D27: 143.52991 | E27: 14.328587 | F27: =LN(B27/B26) -> -0.0089290842 | G27: =LN(C27/C26) -> -0.015520182 | H27: =LN(D27/D26) -> -0.007852781 | I27: =LN(E27/E26) -> -0.015554405 | J27: =SUMPRODUCT(F27:I27,$M$37:$P$37) -> -0.010862645 | L27: stdev | M27: =_xlfn.STDEV.S(F3:F254) -> 0.014317007 | N27: =_xlfn.STDEV.S(G3:G254) -> 0.0084145555 | O27: =_xlfn.STDEV.S(H3:H254) -> 0.011640823 | P27: =_xlfn.STDEV.S(I3:I254) -> 0.013397541
A28: 45191 | B28: 173.90012 | C28: 56.255016 | D28: 142.15448 | E28: 14.150764 | F28: =LN(B28/B27) -> 0.0049321571 | G28: =LN(C28/C27) -> 0.0010421744 | H28: =LN(D28/D27) -> -0.009629071 | I28: =LN(E28/E27) -> -0.012488017 | J28: =SUMPRODUCT(F28:I28,$M$37:$P$37) -> -0.0072123448
A29: 45194 | B29: 175.18356 | C29: 55.669029 | D29: 142.85684 | E29: 14.094611 | F29: =LN(B29/B28) -> 0.0073532672 | G29: =LN(C29/C28) -> -0.01047125 | H29: =LN(D29/D28) -> 0.0049286703 | I29: =LN(E29/E28) -> -0.0039760898 | J29: =SUMPRODUCT(F29:I29,$M$37:$P$37) -> 0.0019130568 | L29: anualizado | M29: =M24 -> Apple | N29: =N24 -> Coca-Cola | O29: =O24 -> JPMorgan | P29: =P24 -> AT&T
A30: 45195 | B30: 171.08453 | C30: 55.209999 | D30: 141.37413 | E30: 14.057176 | F30: =LN(B30/B29) -> -0.02367657 | G30: =LN(C30/C29) -> -0.0082798818 | H30: =LN(D30/D29) -> -0.010433243 | I30: =LN(E30/E29) -> -0.002659513 | J30: =SUMPRODUCT(F30:I30,$M$37:$P$37) -> -0.010479527 | L30: promedio | M30: =((1+M25)^250)-1 -> 0.28404678 | N30: =((1+N25)^250)-1 -> 0.17887183 | O30: =((1+O25)^250)-1 -> 0.45570095 | P30: =((1+P25)^250)-1 -> 0.46071967
A31: 45196 | B31: 169.56232 | C31: 54.643543 | D31: 142.20326 | E31: 13.916791 | F31: =LN(B31/B30) -> -0.0089372741 | G31: =LN(C31/C30) -> -0.010313022 | H31: =LN(D31/D30) -> 0.0058476761 | I31: =LN(E31/E30) -> -0.010036916 | J31: =SUMPRODUCT(F31:I31,$M$37:$P$37) -> -0.002878807 | L31: mediana | M31: =(1+M26)^250-1 -> 0.62626493 | N31: =(1+N26)^250-1 -> 0.30008584 | O31: =(1+O26)^250-1 -> 0.65907619 | P31: =(1+P26)^250-1 -> 0.42284786
A32: 45197 | B32: 169.82101 | C32: 54.506817 | D32: 143.96887 | E32: 14.047817 | F32: =LN(B32/B31) -> 0.0015245124 | G32: =LN(C32/C31) -> -0.0025052794 | H32: =LN(D32/D31) -> 0.012339653 | I32: =LN(E32/E31) -> 0.0093709133 | J32: =SUMPRODUCT(F32:I32,$M$37:$P$37) -> 0.0086209084 | L32: stdev | M32: =M27*SQRT(250) -> 0.22637176 | N32: =N27*SQRT(250) -> 0.1330458 | O32: =O27*SQRT(250) -> 0.18405757 | P32: =P27*SQRT(250) -> 0.21183372
A33: 45198 | B33: 170.33836 | C33: 54.67284 | D33: 141.46191 | E33: 14.057176 | F33: =LN(B33/B32) -> 0.0030418118 | G33: =LN(C33/C32) -> 0.0030412832 | H33: =LN(D33/D32) -> -0.017566588 | I33: =LN(E33/E32) -> 0.00066600268 | J33: =SUMPRODUCT(F33:I33,$M$37:$P$37) -> -0.0067410009 | L33: sharpe | M33: =M30/M32 -> 1.2547801 | N33: =N30/N32 -> 1.3444379 | O33: =O30/O32 -> 2.4758609 | P33: =P30/P32 -> 2.1749118
A34: 45201 | B34: 172.86543 | C34: 54.184517 | D34: 140.2426 | E34: 13.729611 | F34: =LN(B34/B33) -> 0.014726613 | G34: =LN(C34/C33) -> -0.0089718562 | H34: =LN(D34/D33) -> -0.0086567489 | I34: =LN(E34/E33) -> -0.023578125 | J34: =SUMPRODUCT(F34:I34,$M$37:$P$37) -> -0.0088179369
A35: 45202 | B35: 171.52229 | C35: 53.59853 | D35: 139.20862 | E35: 13.832561 | F35: =LN(B35/B34) -> -0.0078002014 | G35: =LN(C35/C34) -> -0.010873561 | H35: =LN(D35/D34) -> -0.0074001161 | I35: =LN(E35/E34) -> 0.0074704184 | J35: =SUMPRODUCT(F35:I35,$M$37:$P$37) -> -0.0028289856
A36: 45203 | B36: 172.77589 | C36: 53.754795 | D36: 139.83289 | E36: 13.710893 | F36: =LN(B36/B35) -> 0.0072820978 | G36: =LN(C36/C35) -> 0.00291123 | H36: =LN(D36/D35) -> 0.0044743813 | I36: =LN(E36/E35) -> -0.0088346793 | J36: =SUMPRODUCT(F36:I36,$M$37:$P$37) -> 0.00068071291 | L36: ponderador | M36: ="w_"&B1 -> w_Apple | N36: ="w_"&C1 -> w_Coca-Cola | O36: ="w_"&D1 -> w_JPMorgan | P36: ="w_"&E1 -> w_AT&T
A37: 45204 | B37: 174.01953 | C37: 51.156906 | D37: 140.42248 | E37: 13.879355 | F37: =LN(B37/B36) -> 0.0071721957 | G37: =LN(C37/C36) -> -0.049535374 | H37: =LN(D37/D36) -> 0.0042075902 | I37: =LN(E37/E36) -> 0.012211858 | J37: =SUMPRODUCT(F37:I37,$M$37:$P$37) -> 0.0051834638 | L37: wi | M37: 0.19932092 | N37: 0.040838545 | O37: 0.4375437 | P37: 0.32229684 | Q37: =SUM(M37:P37) -> 1
A38: 45205 | B38: 176.58641 | C38: 51.899158 | D38: 142.58435 | E38: 13.78207 | F38: =LN(B38/B37) -> 0.014642797 | G38: =LN(C38/C37) -> 0.014405069 | H38: =LN(D38/D37) -> 0.015278133 | I38: =LN(E38/E37) -> -0.0070340122 | J38: =SUMPRODUCT(F38:I38,$M$37:$P$37) -> 0.0079247087
A39: 45208 | B39: 178.07875 | C39: 51.645233 | D39: 142.26009 | E39: 14.049127 | F39: =LN(B39/B38) -> 0.0084155365 | G39: =LN(C39/C38) -> -0.0049046695 | H39: =LN(D39/D38) -> -0.0022767876 | I39: =LN(E39/E38) -> 0.019191787 | J39: =SUMPRODUCT(F39:I39,$M$37:$P$37) -> 0.006666351 | L39: promedio | M39: =AVERAGE(J3:J254) -> 0.0013728677 | N39: =((1+M39)^250)-1 -> 0.40914277 | P39: Treasury 1term | Q39: 0.0452
A40: 45209 | B40: 177.48181 | C40: 52.768375 | D40: 143.1248 | E40: 14.268497 | F40: =LN(B40/B39) -> -0.0033577377 | G40: =LN(C40/C39) -> 0.021514156 | H40: =LN(D40/D39) -> 0.0060600171 | I40: =LN(E40/E39) -> 0.015493841 | J40: =SUMPRODUCT(F40:I40,$M$37:$P$37) -> 0.0078544779 | L40: riesgo | M40: {=SQRT(MMULT(MMULT(M37:P37,M44:P47),TRANSPOSE(M37:P37)))} -> 0.0079850612 | N40: =M40*SQRT(250) -> 0.1262549 | P40: diario | Q40: =((1+Q39)^(1/250))-1 -> 0.00017684865
A41: 45210 | B41: 178.88463 | C41: 52.455849 | D41: 143.61615 | E41: 14.087278 | F41: =LN(B41/B40) -> 0.0078729257 | G41: =LN(C41/C40) -> -0.0059402086 | H41: =LN(D41/D40) -> 0.0034271246 | I41: =LN(E41/E40) -> -0.012781979 | J41: =SUMPRODUCT(F41:I41,$M$37:$P$37) -> -0.0012934256 | L41: sharpe | M41: =(M39-Q40)/M40 -> 0.14978208 | N41: =(N39-Q39)/N40 -> 2.882603
A42: 45211 | B42: 179.79001 | C42: 51.576866 | D42: 143.28203 | E42: 13.78207 | F42: =LN(B42/B41) -> 0.0050484915 | G42: =LN(C42/C41) -> -0.016898606 | H42: =LN(D42/D41) -> -0.0023292037 | I42: =LN(E42/E41) -> -0.021903649 | J42: =SUMPRODUCT(F42:I42,$M$37:$P$37) -> -0.0077624497
A43: 45212 | B43: 177.93947 | C43: 51.654995 | D43: 145.43408 | E43: 13.696229 | F43: =LN(B43/B42) -> -0.010346128 | G43: =LN(C43/C42) -> 0.0015136609 | H43: =LN(D43/D42) -> 0.014908028 | I43: =LN(E43/E42) -> -0.0062479325 | J43: =SUMPRODUCT(F43:I43,$M$37:$P$37) -> 0.0025088405 | L43: matriz_cov | M43: =M29 -> Apple | N43: =N29 -> Coca-Cola | O43: =O29 -> JPMorgan | P43: =P29 -> AT&T
A44: 45215 | B44: 177.81014 | C44: 52.182384 | D44: 145.28668 | E44: 13.743919 | F44: =LN(B44/B43) -> -0.00072710134 | G44: =LN(C44/C43) -> 0.010158067 | H44: =LN(D44/D43) -> -0.0010140315 | I44: =LN(E44/E43) -> 0.0034759323 | J44: =SUMPRODUCT(F44:I44,$M$37:$P$37) -> 0.00094651306 | L44: =M43 -> Apple | M44: =VARP(Portafolio!$F$3:$F$254) -> 0.00020416329 | N44: =M45 -> 1.1148374e-05 | O44: =M46 -> 7.9387037e-06 | P44: =M47 -> -2.200623e-06
A45: 45216 | B45: 176.24811 | C45: 52.807446 | D45: 144.97221 | E45: 13.906061 | F45: =LN(B45/B44) -> -0.0088236168 | G45: =LN(C45/C44) -> 0.011907237 | H45: =LN(D45/D44) -> -0.0021668113 | I45: =LN(E45/E44) -> 0.011728317 | J45: =SUMPRODUCT(F45:I45,$M$37:$P$37) -> 0.0015594676 | L45: =N43 -> Coca-Cola | M45: =_xlfn.COVARIANCE.P($F$3:$F$254,G3:G254) -> 1.1148374e-05 | N45: =VARP(Portafolio!$G$3:$G$254) -> 7.0523772e-05 | O45: =N46 -> 1.8170256e-05 | P45: =N47 -> 3.916336e-05
A46: 45217 | B46: 174.94478 | C46: 52.78791 | D46: 143.38032 | E46: 13.658078 | F46: =LN(B46/B45) -> -0.007422337 | G46: =LN(C46/C45) -> -0.00037001628 | H46: =LN(D46/D45) -> -0.011041381 | I46: =LN(E46/E45) -> -0.017993647 | J46: =SUMPRODUCT(F46:I46,$M$37:$P$37) -> -0.01212492 | L46: =O43 -> JPMorgan | M46: =_xlfn.COVARIANCE.P($F$3:$F$254,H3:H254) -> 7.9387037e-06 | N46: =_xlfn.COVARIANCE.P($G$3:$G$254,H3:H254) -> 1.8170256e-05 | O46: =VARP(Portafolio!$H$3:$H$254) -> 0.00013497102 | P46: =O47 -> 2.8925886e-05
A47: 45218 | B47: 174.56674 | C47: 53.080902 | D47: 142.77106 | E47: 14.554628 | F47: =LN(B47/B46) -> -0.0021632257 | G47: =LN(C47/C46) -> 0.0055350153 | H47: =LN(D47/D46) -> -0.0042583678 | I47: =LN(E47/E46) -> 0.063577877 | J47: =SUMPRODUCT(F47:I47,$M$37:$P$37) -> 0.018422593 | L47: =P43 -> AT&T | M47: =_xlfn.COVARIANCE.P($F$3:$F$254,I5:I256) -> -2.200623e-06 | N47: =_xlfn.COVARIANCE.P($G$3:$G$254,I3:I254) -> 3.916336e-05 | O47: =_xlfn.COVARIANCE.P($H$3:$H$254,I3:I254) -> 2.8925886e-05 | P47: =VARP(Portafolio!$I$3:$I$254) -> 0.00017878183
A48: 45219 | B48: 171.99986 | C48: 53.295769 | D48: 140.47163 | E48: 14.669083 | F48: =LN(B48/B47) -> -0.014813464 | G48: =LN(C48/C47) -> 0.0040397446 | H48: =LN(D48/D47) -> -0.016236772 | I48: =LN(E48/E47) -> 0.007833063 | J48: =SUMPRODUCT(F48:I48,$M$37:$P$37) -> -0.0073673817
...

Sheet VaR (Volt. Hist)
A1: Rentabilidad
A2: =Portafolio!F2 -> r_Apple | B2: =Portafolio!G2 -> r_Coca-Cola | C2: =Portafolio!H2 -> r_JPMorgan | D2: =Portafolio!I2 -> r_AT&T | E2: =Portafolio!J2 -> Portafolio | G2: Volatilidad Historica (Desviación Estandar)
A3: =Portafolio!F3 -> -0.014662185 | B3: =Portafolio!G3 -> 0.0021472312 | C3: =Portafolio!H3 -> -0.010441079 | D3: =Portafolio!I3 -> -0.0064035323 | E3: =Portafolio!J3 -> -0.009467057
A4: =Portafolio!F4 -> 0.0028121206 | B4: =Portafolio!G4 -> 0.0055939922 | C4: =Portafolio!H4 -> 0.0022848848 | D4: =Portafolio!I4 -> 0.0028511962 | E4: =Portafolio!J4 -> 0.0027076334
A5: =Portafolio!F5 -> 0.00770704 | B5: =Portafolio!G5 -> -0.0085681807 | C5: =Portafolio!H5 -> 0.0034177361 | D5: =Portafolio!I5 -> 0.0035523361 | E5: =Portafolio!J5 -> 0.0038265778 | G5: Activos | H5: =A2 -> r_Apple | I5: =B2 -> r_Coca-Cola | J5: =C2 -> r_JPMorgan | K5: =D2 -> r_AT&T | L5: =E2 -> Portafolio
A6: =Portafolio!F6 -> 0.0078738144 | B6: =Portafolio!G6 -> -0.0061416255 | C6: =Portafolio!H6 -> -0.020956622 | D6: =Portafolio!I6 -> 0.011283651 | E6: =Portafolio!J6 -> -0.004214152 | G6: Desv. Estad. | H6: =_xlfn.STDEV.S(A3:A254) -> 0.014317007 | I6: =_xlfn.STDEV.S(B3:B254) -> 0.0084145555 | J6: =_xlfn.STDEV.S(C3:C254) -> 0.011640823 | K6: =_xlfn.STDEV.S(D3:D254) -> 0.013397541 | L6: =_xlfn.STDEV.S(E3:E254) -> 0.0079881271
A7: =Portafolio!F7 -> 0.02171154 | B7: =Portafolio!G7 -> 0.0034904215 | C7: =Portafolio!H7 -> 0.0067403655 | D7: =Portafolio!I7 -> -0.0070373474 | E7: =Portafolio!J7 -> 0.0051511975 | G7: t día(s) | H7: 1
A8: =Portafolio!F8 -> -0.026519109 | B8: =Portafolio!G8 -> -0.0026582344 | C8: =Portafolio!H8 -> -0.00095044775 | D8: =Portafolio!I8 -> -0.00070654177 | E8: =Portafolio!J8 -> -0.0060379501 | G8: Nivel de Confianza | H8: 0.95
A9: =Portafolio!F9 -> 0.012564053 | B9: =Portafolio!G9 -> 0.0046472363 | C9: =Portafolio!H9 -> -0.0012233202 | D9: =Portafolio!I9 -> -0.0028308668 | E9: =Portafolio!J9 -> 0.0012464294 | G9: Normal Estandar | H9: =NORMSINV(H8) -> 1.6448536
A10: =Portafolio!F10 -> 0.0088072128 | B10: =Portafolio!G10 -> 0.0028110715 | C10: =Portafolio!H10 -> 0.0034622836 | D10: =Portafolio!I10 -> 0.0070621976 | E10: =Portafolio!J10 -> 0.0056612861
A11: =Portafolio!F11 -> 0.021575763 | B11: =Portafolio!G11 -> -0.00099121473 | C11: =Portafolio!H11 -> 0.0080993211 | D11: =Portafolio!I11 -> 0.038652124 | E11: =Portafolio!J11 -> 0.020261285 | G11: No-Diversificado
A12: =Portafolio!F12 -> 0.018990782 | B12: =Portafolio!G12 -> -0.00049597605 | C12: =Portafolio!H12 -> -0.0040415126 | D12: =Portafolio!I12 -> -0.0027118018 | E12: =Portafolio!J12 -> 0.0011226617 | G12: VaR Diario 95% (%) | H12: =H6*SQRT($H$7)*$H$9 -> 0.023549381 | I12: =I6*SQRT($H$7)*$H$9 -> 0.013840712 | J12: =J6*SQRT($H$7)*$H$9 -> 0.01914745 | K12: =K6*SQRT($H$7)*$H$9 -> 0.022036994
A13: =Portafolio!F13 -> 0.0011717517 | B13: =Portafolio!G13 -> -0.01064012 | C13: =Portafolio!H13 -> -0.012428386 | D13: =Portafolio!I13 -> 0.0040649861 | E13: =Portafolio!J13 -> -0.0043288022 | G13: Exposición ($) | H13: 100000
A14: =Portafolio!F14 -> 0.0084277858 | B14: =Portafolio!G14 -> -0.008729346 | C14: =Portafolio!H14 -> 0.003343024 | D14: =Portafolio!I14 -> -0.0095109703 | E14: =Portafolio!J14 -> -0.00027929642 | G14: Perdida ($) al 95% | H14: =SUM(H12:K12)*H13 -> 7857.4537
A15: =Portafolio!F15 -> 0.0012659132 | B15: =Portafolio!G15 -> -0.0082960032 | C15: =Portafolio!H15 -> -0.011095406 | D15: =Portafolio!I15 -> -0.011671911 | E15: =Portafolio!J15 -> -0.0087030184
A16: =Portafolio!F16 -> -0.036449648 | B16: =Portafolio!G16 -> -0.00068026368 | C16: =Portafolio!H16 -> -0.0016539663 | D16: =Portafolio!I16 -> 0.0089378657 | E16: =Portafolio!J16 -> -0.0051359948 | G16: Diversificado
A17: =Portafolio!F17 -> -0.029685687 | B17: =Portafolio!G17 -> -0.0076850863 | C17: =Portafolio!H17 -> -0.0085911179 | D17: =Portafolio!I17 -> 0 | E17: =Portafolio!J17 -> -0.0099898157 | G17: VaR Diario 95% (%) | H17: =SQRT($H$7)*H9*L6 -> 0.0131393
A18: =Portafolio!F18 -> 0.0034855737 | B18: =Portafolio!G18 -> 0 | C18: =Portafolio!H18 -> 0.00076518324 | D18: =Portafolio!I18 -> -0.014477989 | E18: =Portafolio!J18 -> -0.0036366612 | G18: Exposición ($) | H18: 100000
A19: =Portafolio!F19 -> 0.006600704 | B19: =Portafolio!G19 -> 0.0093849136 | C19: =Portafolio!H19 -> 0.0043706423 | D19: =Portafolio!I19 -> 0.0082988273 | E19: =Portafolio!J19 -> 0.0062859574 | G19: Perdida ($) al 95% | H19: =H17*H18 -> 1313.93
A20: =Portafolio!F20 -> -0.017207767 | B20: =Portafolio!G20 -> -0.0098994166 | C20: =Portafolio!H20 -> 0.012930049 | D20: =Portafolio!I20 -> -0.0041408788 | E20: =Portafolio!J20 -> 0.00048872381
A21: =Portafolio!F21 -> -0.011925629 | B21: =Portafolio!G21 -> 0.0023984991 | C21: =Portafolio!H21 -> 0.00047822692 | D21: =Portafolio!I21 -> 0.011004271 | E21: =Portafolio!J21 -> 0.0014768109 | G21: Beneficio Diversificación | H21: =H14-H19 -> 6543.5237
A22: =Portafolio!F22 -> 0.0087441923 | B22: =Portafolio!G22 -> 0.0082446925 | C22: =Portafolio!H22 -> 0.019211775 | D22: =Portafolio!I22 -> 0.029651714 | E22: =Portafolio!J22 -> 0.020042246 | G22: Beneficio Diversificación | H22: =1-(H17/H12) -> 0.44205329
A23: =Portafolio!F23 -> -0.0041626265 | B23: =Portafolio!G23 -> -0.0089348416 | C23: =Portafolio!H23 -> -0.0029524998 | D23: =Portafolio!I23 -> 0.011224979 | E23: =Portafolio!J23 -> 0.001131343
A24: =Portafolio!F24 -> 0.016771886 | B24: =Portafolio!G24 -> 0.0061940864 | C24: =Portafolio!H24 -> 0.0020810602 | D24: =Portafolio!I24 -> -0.0092349221 | E24: =Portafolio!J24 -> 0.0015301137
A25: =Portafolio!F25 -> 0.006161829 | B25: =Portafolio!G25 -> -0.0020603885 | C25: =Portafolio!H25 -> -0.0012750275 | D25: =Portafolio!I25 -> 0.0079209278 | E25: =Portafolio!J25 -> 0.0031390479
A26: =Portafolio!F26 -> -0.02019469 | B26: =Portafolio!G26 -> 0.0044589358 | C26: =Portafolio!H26 -> -0.0042389693 | D26: =Portafolio!I26 -> 0.022107528 | E26: =Portafolio!J26 -> 0.0014273245
A27: =Portafolio!F27 -> -0.0089290842 | B27: =Portafolio!G27 -> -0.015520182 | C27: =Portafolio!H27 -> -0.007852781 | D27: =Portafolio!I27 -> -0.015554405 | E27: =Portafolio!J27 -> -0.010862645
A28: =Portafolio!F28 -> 0.0049321571 | B28: =Portafolio!G28 -> 0.0010421744 | C28: =Portafolio!H28 -> -0.009629071 | D28: =Portafolio!I28 -> -0.012488017 | E28: =Portafolio!J28 -> -0.0072123448
A29: =Portafolio!F29 -> 0.0073532672 | B29: =Portafolio!G29 -> -0.01047125 | C29: =Portafolio!H29 -> 0.0049286703 | D29: =Portafolio!I29 -> -0.0039760898 | E29: =Portafolio!J29 -> 0.0019130568
A30: =Portafolio!F30 -> -0.02367657 | B30: =Portafolio!G30 -> -0.0082798818 | C30: =Portafolio!H30 -> -0.010433243 | D30: =Portafolio!I30 -> -0.002659513 | E30: =Portafolio!J30 -> -0.010479527
A31: =Portafolio!F31 -> -0.0089372741 | B31: =Portafolio!G31 -> -0.010313022 | C31: =Portafolio!H31 -> 0.0058476761 | D31: =Portafolio!I31 -> -0.010036916 | E31: =Portafolio!J31 -> -0.002878807
A32: =Portafolio!F32 -> 0.0015245124 | B32: =Portafolio!G32 -> -0.0025052794 | C32: =Portafolio!H32 -> 0.012339653 | D32: =Portafolio!I32 -> 0.0093709133 | E32: =Portafolio!J32 -> 0.0086209084
A33: =Portafolio!F33 -> 0.0030418118 | B33: =Portafolio!G33 -> 0.0030412832 | C33: =Portafolio!H33 -> -0.017566588 | D33: =Portafolio!I33 -> 0.00066600268 | E33: =Portafolio!J33 -> -0.0067410009
A34: =Portafolio!F34 -> 0.014726613 | B34: =Portafolio!G34 -> -0.0089718562 | C34: =Portafolio!H34 -> -0.0086567489 | D34: =Portafolio!I34 -> -0.023578125 | E34: =Portafolio!J34 -> -0.0088179369
... A254: =Portafolio!F254 -> 0.0059010398 | B254: =Portafolio!G254 -> 0.0076906422 | C254: =Portafolio!H254 -> 0.011374432 | D254: =Portafolio!I254 -> 0.013010852 | E254: =Portafolio!J254 -> 0.010660443

Sheet VaR (No-Param) 
A1: Rentabilidad
A2: =Portafolio!F2 -> r_Apple | B2: =Portafolio!G2 -> r_Coca-Cola | C2: =Portafolio!H2 -> r_JPMorgan | D2: =Portafolio!I2 -> r_AT&T | E2: =Portafolio!J2 -> Portafolio | G2: Volatilidad No parámetrica
A3: =Portafolio!F3 -> -0.014662185 | B3: =Portafolio!G3 -> 0.0021472312 | C3: =Portafolio!H3 -> -0.010441079 | D3: =Portafolio!I3 -> -0.0064035323 | E3: =Portafolio!J3 -> -0.009467057
A4: =Portafolio!F4 -> 0.0028121206 | B4: =Portafolio!G4 -> 0.0055939922 | C4: =Portafolio!H4 -> 0.0022848848 | D4: =Portafolio!I4 -> 0.0028511962 | E4: =Portafolio!J4 -> 0.0027076334
A5: =Portafolio!F5 -> 0.00770704 | B5: =Portafolio!G5 -> -0.0085681807 | C5: =Portafolio!H5 -> 0.0034177361 | D5: =Portafolio!I5 -> 0.0035523361 | E5: =Portafolio!J5 -> 0.0038265778 | G5: Activos | H5: =A2 -> r_Apple | I5: =B2 -> r_Coca-Cola | J5: =C2 -> r_JPMorgan | K5: =D2 -> r_AT&T | L5: =E2 -> Portafolio
A6: =Portafolio!F6 -> 0.0078738144 | B6: =Portafolio!G6 -> -0.0061416255 | C6: =Portafolio!H6 -> -0.020956622 | D6: =Portafolio!I6 -> 0.011283651 | E6: =Portafolio!J6 -> -0.004214152 | G6: percentíl 5% | H6: =_xlfn.PERCENTILE.INC(A3:A254,1-$H$8) -> -0.022730961 | I6: =_xlfn.PERCENTILE.INC(B3:B254,1-$H$8) -> -0.010745168 | J6: =_xlfn.PERCENTILE.INC(C3:C254,1-$H$8) -> -0.014154741 | K6: =_xlfn.PERCENTILE.INC(D3:D254,1-$H$8) -> -0.018590929 | L6: =_xlfn.PERCENTILE.INC(E3:E254,1-$H$8) -> -0.011444323
A7: =Portafolio!F7 -> 0.02171154 | B7: =Portafolio!G7 -> 0.0034904215 | C7: =Portafolio!H7 -> 0.0067403655 | D7: =Portafolio!I7 -> -0.0070373474 | E7: =Portafolio!J7 -> 0.0051511975 | G7: t día(s) | H7: 1
A8: =Portafolio!F8 -> -0.026519109 | B8: =Portafolio!G8 -> -0.0026582344 | C8: =Portafolio!H8 -> -0.00095044775 | D8: =Portafolio!I8 -> -0.00070654177 | E8: =Portafolio!J8 -> -0.0060379501 | G8: Nivel de Confianza | H8: 0.95
A9: =Portafolio!F9 -> 0.012564053 | B9: =Portafolio!G9 -> 0.0046472363 | C9: =Portafolio!H9 -> -0.0012233202 | D9: =Portafolio!I9 -> -0.0028308668 | E9: =Portafolio!J9 -> 0.0012464294
A10: =Portafolio!F10 -> 0.0088072128 | B10: =Portafolio!G10 -> 0.0028110715 | C10: =Portafolio!H10 -> 0.0034622836 | D10: =Portafolio!I10 -> 0.0070621976 | E10: =Portafolio!J10 -> 0.0056612861
A11: =Portafolio!F11 -> 0.021575763 | B11: =Portafolio!G11 -> -0.00099121473 | C11: =Portafolio!H11 -> 0.0080993211 | D11: =Portafolio!I11 -> 0.038652124 | E11: =Portafolio!J11 -> 0.020261285 | G11: No-Diversificado
A12: =Portafolio!F12 -> 0.018990782 | B12: =Portafolio!G12 -> -0.00049597605 | C12: =Portafolio!H12 -> -0.0040415126 | D12: =Portafolio!I12 -> -0.0027118018 | E12: =Portafolio!J12 -> 0.0011226617 | G12: VaR Diario 95% (%) | H12: =-(H6*SQRT($H$7)) -> 0.022730961 | I12: =-(I6*SQRT($H$7)) -> 0.010745168 | J12: =-(J6*SQRT($H$7)) -> 0.014154741 | K12: =-(K6*SQRT($H$7)) -> 0.018590929
A13: =Portafolio!F13 -> 0.0011717517 | B13: =Portafolio!G13 -> -0.01064012 | C13: =Portafolio!H13 -> -0.012428386 | D13: =Portafolio!I13 -> 0.0040649861 | E13: =Portafolio!J13 -> -0.0043288022 | G13: Exposición ($) | H13: 100000
A14: =Portafolio!F14 -> 0.0084277858 | B14: =Portafolio!G14 -> -0.008729346 | C14: =Portafolio!H14 -> 0.003343024 | D14: =Portafolio!I14 -> -0.0095109703 | E14: =Portafolio!J14 -> -0.00027929642 | G14: Perdida ($) al 95% | H14: =SUM(H12:K12)*H13 -> 6622.18
A15: =Portafolio!F15 -> 0.0012659132 | B15: =Portafolio!G15 -> -0.0082960032 | C15: =Portafolio!H15 -> -0.011095406 | D15: =Portafolio!I15 -> -0.011671911 | E15: =Portafolio!J15 -> -0.0087030184
A16: =Portafolio!F16 -> -0.036449648 | B16: =Portafolio!G16 -> -0.00068026368 | C16: =Portafolio!H16 -> -0.0016539663 | D16: =Portafolio!I16 -> 0.0089378657 | E16: =Portafolio!J16 -> -0.0051359948 | G16: Diversificado
A17: =Portafolio!F17 -> -0.029685687 | B17: =Portafolio!G17 -> -0.0076850863 | C17: =Portafolio!H17 -> -0.0085911179 | D17: =Portafolio!I17 -> 0 | E17: =Portafolio!J17 -> -0.0099898157 | G17: VaR Diario 95% (%) | H17: =-(SQRT($H$7)*$L$6) -> 0.011444323
A18: =Portafolio!F18 -> 0.0034855737 | B18: =Portafolio!G18 -> 0 | C18: =Portafolio!H18 -> 0.00076518324 | D18: =Portafolio!I18 -> -0.014477989 | E18: =Portafolio!J18 -> -0.0036366612 | G18: Exposición ($) | H18: 100000
A19: =Portafolio!F19 -> 0.006600704 | B19: =Portafolio!G19 -> 0.0093849136 | C19: =Portafolio!H19 -> 0.0043706423 | D19: =Portafolio!I19 -> 0.0082988273 | E19: =Portafolio!J19 -> 0.0062859574 | G19: Perdida ($) al 95% | H19: =H17*H18 -> 1144.4323
A20: =Portafolio!F20 -> -0.017207767 | B20: =Portafolio!G20 -> -0.0098994166 | C20: =Portafolio!H20 -> 0.012930049 | D20: =Portafolio!I20 -> -0.0041408788 | E20: =Portafolio!J20 -> 0.00048872381
A21: =Portafolio!F21 -> -0.011925629 | B21: =Portafolio!G21 -> 0.0023984991 | C21: =Portafolio!H21 -> 0.00047822692 | D21: =Portafolio!I21 -> 0.011004271 | E21: =Portafolio!J21 -> 0.0014768109 | G21: Beneficio Diversificación | H21: =H14-H19 -> 5477.7477
A22: =Portafolio!F22 -> 0.0087441923 | B22: =Portafolio!G22 -> 0.0082446925 | C22: =Portafolio!H22 -> 0.019211775 | D22: =Portafolio!I22 -> 0.029651714 | E22: =Portafolio!J22 -> 0.020042246 | G22: Beneficio Diversificación | H22: =1-(H17/H12) -> 0.49653149
A23: =Portafolio!F23 -> -0.0041626265 | B23: =Portafolio!G23 -> -0.0089348416 | C23: =Portafolio!H23 -> -0.0029524998 | D23: =Portafolio!I23 -> 0.011224979 | E23: =Portafolio!J23 -> 0.001131343
A24: =Portafolio!F24 -> 0.016771886 | B24: =Portafolio!G24 -> 0.0061940864 | C24: =Portafolio!H24 -> 0.0020810602 | D24: =Portafolio!I24 -> -0.0092349221 | E24: =Portafolio!J24 -> 0.0015301137
A25: =Portafolio!F25 -> 0.006161829 | B25: =Portafolio!G25 -> -0.0020603885 | C25: =Portafolio!H25 -> -0.0012750275 | D25: =Portafolio!I25 -> 0.0079209278 | E25: =Portafolio!J25 -> 0.0031390479
A26: =Portafolio!F26 -> -0.02019469 | B26: =Portafolio!G26 -> 0.0044589358 | C26: =Portafolio!H26 -> -0.0042389693 | D26: =Portafolio!I26 -> 0.022107528 | E26: =Portafolio!J26 -> 0.0014273245
A27: =Portafolio!F27 -> -0.0089290842 | B27: =Portafolio!G27 -> -0.015520182 | C27: =Portafolio!H27 -> -0.007852781 | D27: =Portafolio!I27 -> -0.015554405 | E27: =Portafolio!J27 -> -0.010862645
A28: =Portafolio!F28 -> 0.0049321571 | B28: =Portafolio!G28 -> 0.0010421744 | C28: =Portafolio!H28 -> -0.009629071 | D28: =Portafolio!I28 -> -0.012488017 | E28: =Portafolio!J28 -> -0.0072123448
A29: =Portafolio!F29 -> 0.0073532672 | B29: =Portafolio!G29 -> -0.01047125 | C29: =Portafolio!H29 -> 0.0049286703 | D29: =Portafolio!I29 -> -0.0039760898 | E29: =Portafolio!J29 -> 0.0019130568
A30: =Portafolio!F30 -> -0.02367657 | B30: =Portafolio!G30 -> -0.0082798818 | C30: =Portafolio!H30 -> -0.010433243 | D30: =Portafolio!I30 -> -0.002659513 | E30: =Portafolio!J30 -> -0.010479527
A31: =Portafolio!F31 -> -0.0089372741 | B31: =Portafolio!G31 -> -0.010313022 | C31: =Portafolio!H31 -> 0.0058476761 | D31: =Portafolio!I31 -> -0.010036916 | E31: =Portafolio!J31 -> -0.002878807
A32: =Portafolio!F32 -> 0.0015245124 | B32: =Portafolio!G32 -> -0.0025052794 | C32: =Portafolio!H32 -> 0.012339653 | D32: =Portafolio!I32 -> 0.0093709133 | E32: =Portafolio!J32 -> 0.0086209084
A33: =Portafolio!F33 -> 0.0030418118 | B33: =Portafolio!G33 -> 0.0030412832 | C33: =Portafolio!H33 -> -0.017566588 | D33: =Portafolio!I33 -> 0.00066600268 | E33: =Portafolio!J33 -> -0.0067410009
A34: =Portafolio!F34 -> 0.014726613 | B34: =Portafolio!G34 -> -0.0089718562 | C34: =Portafolio!H34 -> -0.0086567489 | D34: =Portafolio!I34 -> -0.023578125 | E34: =Portafolio!J34 -> -0.0088179369
... A254: =Portafolio!F254 -> 0.0059010398 | B254: =Portafolio!G254 -> 0.0076906422 | C254: =Portafolio!H254 -> 0.011374432 | D254: =Portafolio!I254 -> 0.013010852 | E254: =Portafolio!J254 -> 0.010660443

Sheet VaR (Montecarlos)
A1: Rentabilidad
A2: =Portafolio!F2 -> r_Apple | B2: =Portafolio!G2 -> r_Coca-Cola | C2: =Portafolio!H2 -> r_JPMorgan | D2: =Portafolio!I2 -> r_AT&T | E2: =Portafolio!J2 -> Portafolio | G2: Volatilidad Simulación Montecarlos
A3: =Portafolio!F3 -> -0.014662185 | B3: =Portafolio!G3 -> 0.0021472312 | C3: =Portafolio!H3 -> -0.010441079 | D3: =Portafolio!I3 -> -0.0064035323 | E3: =Portafolio!J3 -> -0.009467057
A4: =Portafolio!F4 -> 0.0028121206 | B4: =Portafolio!G4 -> 0.0055939922 | C4: =Portafolio!H4 -> 0.0022848848 | D4: =Portafolio!I4 -> 0.0028511962 | E4: =Portafolio!J4 -> 0.0027076334
A5: =Portafolio!F5 -> 0.00770704 | B5: =Portafolio!G5 -> -0.0085681807 | C5: =Portafolio!H5 -> 0.0034177361 | D5: =Portafolio!I5 -> 0.0035523361 | E5: =Portafolio!J5 -> 0.0038265778 | G5: Activos | H5: =A2 -> r_Apple | I5: =B2 -> r_Coca-Cola | J5: =C2 -> r_JPMorgan | K5: =D2 -> r_AT&T | L5: =E2 -> Portafolio
A6: =Portafolio!F6 -> 0.0078738144 | B6: =Portafolio!G6 -> -0.0061416255 | C6: =Portafolio!H6 -> -0.020956622 | D6: =Portafolio!I6 -> 0.011283651 | E6: =Portafolio!J6 -> -0.004214152 | G6: entrada | H6: 0.0010005668 | I6: 0.00065844829 | J6: 0.0015030786
A7: =Portafolio!F7 -> 0.02171154 | B7: =Portafolio!G7 -> 0.0034904215 | C7: =Portafolio!H7 -> 0.0067403655 | D7: =Portafolio!I7 -> -0.0070373474 | E7: =Portafolio!J7 -> 0.0051511975 | G7: salida | H7: =H6 -> 0.0010005668 | I7: =I6 -> 0.00065844829 | J7: =J6 -> 0.0015030786 | K7: =K6 -> 0 | L7: =L6 -> 0
A8: =Portafolio!F8 -> -0.026519109 | B8: =Portafolio!G8 -> -0.0026582344 | C8: =Portafolio!H8 -> -0.00095044775 | D8: =Portafolio!I8 -> -0.00070654177 | E8: =Portafolio!J8 -> -0.0060379501 | G8: t día(s) | H8: 1
A9: =Portafolio!F9 -> 0.012564053 | B9: =Portafolio!G9 -> 0.0046472363 | C9: =Portafolio!H9 -> -0.0012233202 | D9: =Portafolio!I9 -> -0.0028308668 | E9: =Portafolio!J9 -> 0.0012464294
A10: =Portafolio!F10 -> 0.0088072128 | B10: =Portafolio!G10 -> 0.0028110715 | C10: =Portafolio!H10 -> 0.0034622836 | D10: =Portafolio!I10 -> 0.0070621976 | E10: =Portafolio!J10 -> 0.0056612861
A11: =Portafolio!F11 -> 0.021575763 | B11: =Portafolio!G11 -> -0.00099121473 | C11: =Portafolio!H11 -> 0.0080993211 | D11: =Portafolio!I11 -> 0.038652124 | E11: =Portafolio!J11 -> 0.020261285 | G11: No-Diversificado
A12: =Portafolio!F12 -> 0.018990782 | B12: =Portafolio!G12 -> -0.00049597605 | C12: =Portafolio!H12 -> -0.0040415126 | D12: =Portafolio!I12 -> -0.0027118018 | E12: =Portafolio!J12 -> 0.0011226617 | G12: VaR Diario 95% (%) | H12: {=_xll.ROV.RiskSim.RSFunctions.RSForecastStatistic(H7,"Percentile0.05")*SQRT($H$8)} -> -0.018754889 | I12: {=_xll.ROV.RiskSim.RSFunctions.RSForecastStatistic(I7,"Percentile0.05")*SQRT($H$8)} -> -0.013878689 | J12: {=_xll.ROV.RiskSim.RSFunctions.RSForecastStatistic(J7,"Percentile0.05")*SQRT($H$8)} -> -0.015062499 | K12: {=_xll.ROV.RiskSim.RSFunctions.RSForecastStatistic(K7,"Percentile0.05")*SQRT($H$8)} -> -0.019501455
A13: =Portafolio!F13 -> 0.0011717517 | B13: =Portafolio!G13 -> -0.01064012 | C13: =Portafolio!H13 -> -0.012428386 | D13: =Portafolio!I13 -> 0.0040649861 | E13: =Portafolio!J13 -> -0.0043288022 | G13: Exposición ($) | H13: 100000
A14: =Portafolio!F14 -> 0.0084277858 | B14: =Portafolio!G14 -> -0.008729346 | C14: =Portafolio!H14 -> 0.003343024 | D14: =Portafolio!I14 -> -0.0095109703 | E14: =Portafolio!J14 -> -0.00027929642 | G14: Perdida ($) al 95% | H14: =SUM(H12:K12)*H13 -> -6719.7532
A15: =Portafolio!F15 -> 0.0012659132 | B15: =Portafolio!G15 -> -0.0082960032 | C15: =Portafolio!H15 -> -0.011095406 | D15: =Portafolio!I15 -> -0.011671911 | E15: =Portafolio!J15 -> -0.0087030184
