Workbook

Sheet Base de Datos
A1: accion | B1: fecha | C1: retorno | D1: presion3 | E1: const | F1: prediccion | G1: id1
A2: AESGENER | B2: 37591 | C2: -0.11538462 | D2: 0 | E2: 1 | G2: 1
A3: AESGENER | B3: 37622 | C3: -0.02173913 | D3: 0 | E3: 1 | G3: 1
A4: AESGENER | B4: 37653 | C4: -0.044444444 | D4: 0 | E4: 1 | G4: 1
A5: AESGENER | B5: 37681 | C5: -0.069767442 | D5: 0 | E5: 1 | G5: 1
A6: AESGENER | B6: 37712 | C6: 0.175 | D6: 0 | E6: 1 | G6: 1
A7: AESGENER | B7: 37742 | C7: 0.44415635 | D7: 0 | E7: 1 | G7: 1
A8: AESGENER | B8: 37773 | C8: 0.03030303 | D8: 0 | E8: 1 | G8: 1
A9: AESGENER | B9: 37803 | C9: 0.0089222166 | D9: 0 | E9: 1 | G9: 1
A10: AESGENER | B10: 37834 | C10: 0.23076923 | D10: 0 | E10: 1 | F10: 0.065259507 | G10: 1
A11: AESGENER | B11: 37865 | C11: 0.12375 | D11: 0 | E11: 1 | F11: 0.072651968 | G11: 1
A12: AESGENER | B12: 37895 | C12: 0.18898776 | D12: 0 | E12: 1 | F12: 0.077769072 | G12: 1
A13: AESGENER | B13: 37926 | C13: 0.029095332 | D13: 0 | E13: 1 | F13: 0.077651801 | G13: 1
A14: AESGENER | B14: 37956 | C14: -0.022727273 | D14: 5.288438e-10 | E14: 1 | F14: 0.065476204 | G14: 1
A15: AESGENER | B15: 37987 | C15: -0.13860465 | E15: 1 | F15: 0.063942672 | G15: 1
A16: AESGENER | B16: 38018 | C16: 0.23557824 | E16: 1 | F16: 0.060231173 | G16: 1
A17: AESGENER | B17: 38047 | C17: -0.18954996 | D17: 0 | E17: 1 | F17: 0.060099467 | G17: 1
A18: AESGENER | B18: 38078 | C18: -0.035294118 | D18: 0 | E18: 1 | F18: 0.051801208 | G18: 1
A19: AESGENER | B19: 38108 | C19: 0.0011248549 | D19: 0 | E19: 1 | F19: 0.045432344 | G19: 1
A20: AESGENER | B20: 38139 | C20: 0.073170732 | D20: 0 | E20: 1 | F20: 0.043555217 | G20: 1
A21: AESGENER | B21: 38169 | C21: -0.014204545 | D21: 0 | E21: 1 | F21: 0.046171292 | G21: 1
A22: AESGENER | B22: 38200 | C22: 0.0028818444 | D22: 0 | E22: 1 | F22: 0.033735981 | G22: 1
A23: AESGENER | B23: 38231 | C23: 0.091944023 | D23: 0 | E23: 1 | F23: 0.026747774 | G23: 1
A24: AESGENER | B24: 38261 | C24: -0.032150538 | D24: 0 | E24: 1 | F24: 0.0346893 | G24: 1
A25: AESGENER | B25: 38292 | C25: 0.025441618 | D25: 0 | E25: 1 | F25: 0.034626304 | G25: 1
A26: AESGENER | B26: 38322 | C26: 0.12870193 | D26: 0 | E26: 1 | F26: 0.035270102 | G26: 1
A27: AESGENER | B27: 38353 | C27: -0.10891089 | D27: 0 | E27: 1 | F27: 0.036778623 | G27: 1
A28: AESGENER | B28: 38384 | C28: 0.048888889 | D28: 0 | E28: 1 | F28: 0.034242807 | G28: 1
... A74: AESGENER | B74: 39783 | C74: 0.015820106 | D74: 0.0028330539 | E74: 1 | F74: 0.013378299 | G74: 1
A75: AGUASA | B75: 37591 | C75: -0.054693487 | D75: 0.060920168 | E75: 1 | G75: 2
A76: AGUASA | B76: 37622 | C76: -0.028776978 | D76: 0.00088920147 | E76: 1 | G76: 2
A77: AGUASA | B77: 37653 | C77: -0.0074074074 | D77: 0.00052202865 | E77: 1 | G77: 2
A78: AGUASA | B78: 37681 | C78: -0.014925373 | D78: 8.1329272e-05 | E78: 1 | G78: 2
A79: AGUASA | B79: 37712 | C79: 0.20454545 | D79: 0.00042639792 | E79: 1 | G79: 2
A80: AGUASA | B80: 37742 | C80: -0.032300881 | D80: 0.001106039 | E80: 1 | G80: 2
A81: AGUASA | B81: 37773 | C81: -0.060810811 | D81: 0.00032588583 | E81: 1 | G81: 2
A82: AGUASA | B82: 37803 | C82: -0.028776978 | D82: -8.6316722e-05 | E82: 1 | G82: 2
A83: AGUASA | B83: 37834 | C83: 0.14074074 | D83: 0.0067009926 | E83: 1 | F83: 0.014535392 | G83: 2
A84: AGUASA | B84: 37865 | C84: 0.10292212 | D84: -0.00041325108 | E84: 1 | F84: 0.018633714 | G84: 2
A85: AGUASA | B85: 37895 | C85: 0.11804526 | D85: 0.0011754908 | E85: 1 | F85: 0.02177433 | G85: 2
...

Sheet Cálculos
A1: Transformación Panel a Serie de Tiempo | G1: Retornos Brutos | L1: Retornos Anormales
A2: fecha | B2: Retorno_1 | C2: Retorno_2 | D2: Predicción_1 | E2: Predicción_2 | G2: Spread | H2: SpreadCUM | I2: INN | J2: INP | L2: Spread | M2: SpreadRA | N2: INNRA | O2: INPRA
A3: 37591 | B3: =AVERAGEIFS('Base de Datos'!$C$2:$C$6863,'Base de Datos'!$B$2:$B$6863,Cálculos!$A3,'Base de Datos'!$G$2:$G$6863,1) -> 0.050765751 | C3: =AVERAGEIFS('Base de Datos'!$C$2:$C$6863,'Base de Datos'!$B$2:$B$6863,Cálculos!$A3,'Base de Datos'!$G$2:$G$6863,2) -> 0.029688486 | D3: =AVERAGEIFS('Base de Datos'!$F$2:$F$6863,'Base de Datos'!$B$2:$B$6863,Cálculos!$A3,'Base de Datos'!$G$2:$G$6863,1) -> #DIV/0! | E3: =AVERAGEIFS('Base de Datos'!$F$2:$F$6863,'Base de Datos'!$B$2:$B$6863,Cálculos!$A3,'Base de Datos'!$G$2:$G$6863,2) -> #DIV/0! | G3: =B3-C3 -> 0.021077265 | L3: =(B3-D3)-(C3-E3) -> #DIV/0!
A4: 37622 | B4: =AVERAGEIFS('Base de Datos'!$C$2:$C$6863,'Base de Datos'!$B$2:$B$6863,Cálculos!$A4,'Base de Datos'!$G$2:$G$6863,1) -> 0.0035911662 | C4: =AVERAGEIFS('Base de Datos'!$C$2:$C$6863,'Base de Datos'!$B$2:$B$6863,Cálculos!$A4,'Base de Datos'!$G$2:$G$6863,2) -> 0.0068498331 | D4: =AVERAGEIFS('Base de Datos'!$F$2:$F$6863,'Base de Datos'!$B$2:$B$6863,Cálculos!$A4,'Base de Datos'!$G$2:$G$6863,1) -> #DIV/0! | E4: =AVERAGEIFS('Base de Datos'!$F$2:$F$6863,'Base de Datos'!$B$2:$B$6863,Cálculos!$A4,'Base de Datos'!$G$2:$G$6863,2) -> #DIV/0! | G4: =B4-C4 -> -0.0032586669 | L4: =(B4-D4)-(C4-E4) -> #DIV/0!
A5: 37653 | B5: =AVERAGEIFS('Base de Datos'!$C$2:$C$6863,'Base de Datos'!$B$2:$B$6863,Cálculos!$A5,'Base de Datos'!$G$2:$G$6863,1) -> 0.0029798679 | C5: =AVERAGEIFS('Base de Datos'!$C$2:$C$6863,'Base de Datos'!$B$2:$B$6863,Cálculos!$A5,'Base de Datos'!$G$2:$G$6863,2) -> -0.0039535396 | D5: =AVERAGEIFS('Base de Datos'!$F$2:$F$6863,'Base de Datos'!$B$2:$B$6863,Cálculos!$A5,'Base de Datos'!$G$2:$G$6863,1) -> #DIV/0! | E5: =AVERAGEIFS('Base de Datos'!$F$2:$F$6863,'Base de Datos'!$B$2:$B$6863,Cálculos!$A5,'Base de Datos'!$G$2:$G$6863,2) -> #DIV/0! | G5: =B5-C5 -> 0.0069334075 | L5: =(B5-D5)-(C5-E5) -> #DIV/0!
A6: 37681 | B6: =AVERAGEIFS('Base de Datos'!$C$2:$C$6863,'Base de Datos'!$B$2:$B$6863,Cálculos!$A6,'Base de Datos'!$G$2:$G$6863,1) -> 0.0066219994 | C6: =AVERAGEIFS('Base de Datos'!$C$2:$C$6863,'Base de Datos'!$B$2:$B$6863,Cálculos!$A6,'Base de Datos'!$G$2:$G$6863,2) -> 0.0061880027 | D6: =AVERAGEIFS('Base de Datos'!$F$2:$F$6863,'Base de Datos'!$B$2:$B$6863,Cálculos!$A6,'Base de Datos'!$G$2:$G$6863,1) -> #DIV/0! | E6: =AVERAGEIFS('Base de Datos'!$F$2:$F$6863,'Base de Datos'!$B$2:$B$6863,Cálculos!$A6,'Base de Datos'!$G$2:$G$6863,2) -> #DIV/0! | G6: =B6-C6 -> 0.00043399669 | L6: =(B6-D6)-(C6-E6) -> #DIV/0!
A7: 37712 | B7: =AVERAGEIFS('Base de Datos'!$C$2:$C$6863,'Base de Datos'!$B$2:$B$6863,Cálculos!$A7,'Base de Datos'!$G$2:$G$6863,1) -> 0.22240968 | C7: =AVERAGEIFS('Base de Datos'!$C$2:$C$6863,'Base de Datos'!$B$2:$B$6863,Cálculos!$A7,'Base de Datos'!$G$2:$G$6863,2) -> 0.10868096 | D7: =AVERAGEIFS('Base de Datos'!$F$2:$F$6863,'Base de Datos'!$B$2:$B$6863,Cálculos!$A7,'Base de Datos'!$G$2:$G$6863,1) -> #DIV/0! | E7: =AVERAGEIFS('Base de Datos'!$F$2:$F$6863,'Base de Datos'!$B$2:$B$6863,Cálculos!$A7,'Base de Datos'!$G$2:$G$6863,2) -> #DIV/0! | G7: =B7-C7 -> 0.11372873 | L7: =(B7-D7)-(C7-E7) -> #DIV/0!
A8: 37742 | B8: =AVERAGEIFS('Base de Datos'!$C$2:$C$6863,'Base de Datos'!$B$2:$B$6863,Cálculos!$A8,'Base de Datos'!$G$2:$G$6863,1) -> 0.077228221 | C8: =AVERAGEIFS('Base de Datos'!$C$2:$C$6863,'Base de Datos'!$B$2:$B$6863,Cálculos!$A8,'Base de Datos'!$G$2:$G$6863,2) -> 0.082941823 | D8: =AVERAGEIFS('Base de Datos'!$F$2:$F$6863,'Base de Datos'!$B$2:$B$6863,Cálculos!$A8,'Base de Datos'!$G$2:$G$6863,1) -> #DIV/0! | E8: =AVERAGEIFS('Base de Datos'!$F$2:$F$6863,'Base de Datos'!$B$2:$B$6863,Cálculos!$A8,'Base de Datos'!$G$2:$G$6863,2) -> #DIV/0! | G8: =B8-C8 -> -0.0057136012 | L8: =(B8-D8)-(C8-E8) -> #DIV/0!
A9: 37773 | B9: =AVERAGEIFS('Base de Datos'!$C$2:$C$6863,'Base de Datos'!$B$2:$B$6863,Cálculos!$A9,'Base de Datos'!$G$2:$G$6863,1) -> 0.016128364 | C9: =AVERAGEIFS('Base de Datos'!$C$2:$C$6863,'Base de Datos'!$B$2:$B$6863,Cálculos!$A9,'Base de Datos'!$G$2:$G$6863,2) -> 0.0048727179 | D9: =AVERAGEIFS('Base de Datos'!$F$2:$F$6863,'Base de Datos'!$B$2:$B$6863,Cálculos!$A9,'Base de Datos'!$G$2:$G$6863,1) -> #DIV/0! | E9: =AVERAGEIFS('Base de Datos'!$F$2:$F$6863,'Base de Datos'!$B$2:$B$6863,Cálculos!$A9,'Base de Datos'!$G$2:$G$6863,2) -> #DIV/0! | G9: =B9-C9 -> 0.011255646 | L9: =(B9-D9)-(C9-E9) -> #DIV/0!
A10: 37803 | B10: =AVERAGEIFS('Base de Datos'!$C$2:$C$6863,'Base de Datos'!$B$2:$B$6863,Cálculos!$A10,'Base de Datos'!$G$2:$G$6863,1) -> 0.058686935 | C10: =AVERAGEIFS('Base de Datos'!$C$2:$C$6863,'Base de Datos'!$B$2:$B$6863,Cálculos!$A10,'Base de Datos'!$G$2:$G$6863,2) -> 0.050277668 | D10: =AVERAGEIFS('Base de Datos'!$F$2:$F$6863,'Base de Datos'!$B$2:$B$6863,Cálculos!$A10,'Base de Datos'!$G$2:$G$6863,1) -> #DIV/0! | E10: =AVERAGEIFS('Base de Datos'!$F$2:$F$6863,'Base de Datos'!$B$2:$B$6863,Cálculos!$A10,'Base de Datos'!$G$2:$G$6863,2) -> #DIV/0! | G10: =B10-C10 -> 0.0084092676 | L10: =(B10-D10)-(C10-E10) -> #DIV/0!
A11: 37834 | B11: =AVERAGEIFS('Base de Datos'!$C$2:$C$6863,'Base de Datos'!$B$2:$B$6863,Cálculos!$A11,'Base de Datos'!$G$2:$G$6863,1) -> 0.081165383 | C11: =AVERAGEIFS('Base de Datos'!$C$2:$C$6863,'Base de Datos'!$B$2:$B$6863,Cálculos!$A11,'Base de Datos'!$G$2:$G$6863,2) -> 0.11753348 | D11: =AVERAGEIFS('Base de Datos'!$F$2:$F$6863,'Base de Datos'!$B$2:$B$6863,Cálculos!$A11,'Base de Datos'!$G$2:$G$6863,1) -> 0.036860071 | E11: =AVERAGEIFS('Base de Datos'!$F$2:$F$6863,'Base de Datos'!$B$2:$B$6863,Cálculos!$A11,'Base de Datos'!$G$2:$G$6863,2) -> 0.040097374 | G11: =B11-C11 -> -0.036368096 | L11: =(B11-D11)-(C11-E11) -> -0.033130794
A12: 37865 | B12: =AVERAGEIFS('Base de Datos'!$C$2:$C$6863,'Base de Datos'!$B$2:$B$6863,Cálculos!$A12,'Base de Datos'!$G$2:$G$6863,1) -> 0.033420366 | C12: =AVERAGEIFS('Base de Datos'!$C$2:$C$6863,'Base de Datos'!$B$2:$B$6863,Cálculos!$A12,'Base de Datos'!$G$2:$G$6863,2) -> 0.036584238 | D12: =AVERAGEIFS('Base de Datos'!$F$2:$F$6863,'Base de Datos'!$B$2:$B$6863,Cálculos!$A12,'Base de Datos'!$G$2:$G$6863,1) -> 0.038662042 | E12: =AVERAGEIFS('Base de Datos'!$F$2:$F$6863,'Base de Datos'!$B$2:$B$6863,Cálculos!$A12,'Base de Datos'!$G$2:$G$6863,2) -> 0.045325677 | G12: =B12-C12 -> -0.0031638719 | L12: =(B12-D12)-(C12-E12) -> 0.0034997628
A13: 37895 | B13: =AVERAGEIFS('Base de Datos'!$C$2:$C$6863,'Base de Datos'!$B$2:$B$6863,Cálculos!$A13,'Base de Datos'!$G$2:$G$6863,1) -> 0.076333889 | C13: =AVERAGEIFS('Base de Datos'!$C$2:$C$6863,'Base de Datos'!$B$2:$B$6863,Cálculos!$A13,'Base de Datos'!$G$2:$G$6863,2) -> 0.10112334 | D13: =AVERAGEIFS('Base de Datos'!$F$2:$F$6863,'Base de Datos'!$B$2:$B$6863,Cálculos!$A13,'Base de Datos'!$G$2:$G$6863,1) -> 0.03944543 | E13: =AVERAGEIFS('Base de Datos'!$F$2:$F$6863,'Base de Datos'!$B$2:$B$6863,Cálculos!$A13,'Base de Datos'!$G$2:$G$6863,2) -> 0.045142702 | G13: =B13-C13 -> -0.024789453 | L13: =(B13-D13)-(C13-E13) -> -0.019092181
A14: 37926 | B14: =AVERAGEIFS('Base de Datos'!$C$2:$C$6863,'Base de Datos'!$B$2:$B$6863,Cálculos!$A14,'Base de Datos'!$G$2:$G$6863,1) -> -0.039302163 | C14: =AVERAGEIFS('Base de Datos'!$C$2:$C$6863,'Base de Datos'!$B$2:$B$6863,Cálculos!$A14,'Base de Datos'!$G$2:$G$6863,2) -> -0.0075176928 | D14: =AVERAGEIFS('Base de Datos'!$F$2:$F$6863,'Base de Datos'!$B$2:$B$6863,Cálculos!$A14,'Base de Datos'!$G$2:$G$6863,1) -> 0.03505354 | E14: =AVERAGEIFS('Base de Datos'!$F$2:$F$6863,'Base de Datos'!$B$2:$B$6863,Cálculos!$A14,'Base de Datos'!$G$2:$G$6863,2) -> 0.045598828 | G14: =B14-C14 -> -0.03178447 | L14: =(B14-D14)-(C14-E14) -> -0.021239182
... A55: 39173 | B55: =AVERAGEIFS('Base de Datos'!$C$2:$C$6863,'Base de Datos'!$B$2:$B$6863,Cálculos!$A55,'Base de Datos'!$G$2:$G$6863,1) -> 0.074579733 | C55: =AVERAGEIFS('Base de Datos'!$C$2:$C$6863,'Base de Datos'!$B$2:$B$6863,Cálculos!$A55,'Base de Datos'!$G$2:$G$6863,2) -> 0.055668117 | D55: =AVERAGEIFS('Base de Datos'!$F$2:$F$6863,'Base de Datos'!$B$2:$B$6863,Cálculos!$A55,'Base de Datos'!$G$2:$G$6863,1) -> 0.019795133 | E55: =AVERAGEIFS('Base de Datos'!$F$2:$F$6863,'Base de Datos'!$B$2:$B$6863,Cálculos!$A55,'Base de Datos'!$G$2:$G$6863,2) -> 0.023297259 | G55: =B55-C55 -> 0.018911616 | L55: =(B55-D55)-(C55-E55) -> 0.022413741
A56: 39203 | B56: =AVERAGEIFS('Base de Datos'!$C$2:$C$6863,'Base de Datos'!$B$2:$B$6863,Cálculos!$A56,'Base de Datos'!$G$2:$G$6863,1) -> 0.033015535 | C56: =AVERAGEIFS('Base de Datos'!$C$2:$C$6863,'Base de Datos'!$B$2:$B$6863,Cálculos!$A56,'Base de Datos'!$G$2:$G$6863,2) -> 0.038214928 | D56: =AVERAGEIFS('Base de Datos'!$F$2:$F$6863,'Base de Datos'!$B$2:$B$6863,Cálculos!$A56,'Base de Datos'!$G$2:$G$6863,1) -> 0.020778827 | E56: =AVERAGEIFS('Base de Datos'!$F$2:$F$6863,'Base de Datos'!$B$2:$B$6863,Cálculos!$A56,'Base de Datos'!$G$2:$G$6863,2) -> 0.023675252 | G56: =B56-C56 -> -0.0051993925 | H56: =+G56 -> -0.0051993925 | I56: =H56-(1.96*(_xlfn.STDEV.S($H$56:$H$75)/SQRT(COUNT($H$56:$H$75)))) -> -0.019327567 | J56: =H56+(1.96*(_xlfn.STDEV.S($H$56:$H$75)/SQRT(COUNT($H$56:$H$75)))) -> 0.0089287824 | L56: =(B56-D56)-(C56-E56) -> -0.0023029679 | M56: =+L56 -> -0.0023029679 | N56: =M56-(1.96*(_xlfn.STDEV.S($M$56:$M$75)/SQRT(COUNT(M$56:M$75)))) -> -0.021425337 | O56: =M56+(1.96*(_xlfn.STDEV.S($M$56:$M$75)/SQRT(COUNT($M$56:$M$75)))) -> 0.016819401
A57: 39234 | B57: =AVERAGEIFS('Base de Datos'!$C$2:$C$6863,'Base de Datos'!$B$2:$B$6863,Cálculos!$A57,'Base de Datos'!$G$2:$G$6863,1) -> 0.082242103 | C57: =AVERAGEIFS('Base de Datos'!$C$2:$C$6863,'Base de Datos'!$B$2:$B$6863,Cálculos!$A57,'Base de Datos'!$G$2:$G$6863,2) -> 0.061488244 | D57: =AVERAGEIFS('Base de Datos'!$F$2:$F$6863,'Base de Datos'!$B$2:$B$6863,Cálculos!$A57,'Base de Datos'!$G$2:$G$6863,1) -> 0.019616441 | E57: =AVERAGEIFS('Base de Datos'!$F$2:$F$6863,'Base de Datos'!$B$2:$B$6863,Cálculos!$A57,'Base de Datos'!$G$2:$G$6863,2) -> 0.024504111 | G57: =B57-C57 -> 0.020753859 | H57: =+H56+G57 -> 0.015554466 | I57: =H57-(1.96*(_xlfn.STDEV.S($H$56:$H$75)/SQRT(COUNT($H$56:$H$75)))) -> 0.0014262915 | J57: =H57+(1.96*(_xlfn.STDEV.S($H$56:$H$75)/SQRT(COUNT($H$56:$H$75)))) -> 0.029682641 | L57: =(B57-D57)-(C57-E57) -> 0.02564153 | M57: =+M56+L57 -> 0.023338562 | N57: =M57-(1.96*(_xlfn.STDEV.S($M$56:$M$75)/SQRT(COUNT(M$56:M$75)))) -> 0.0042161933 | O57: =M57+(1.96*(_xlfn.STDEV.S($M$56:$M$75)/SQRT(COUNT($M$56:$M$75)))) -> 0.042460931
A58: 39264 | B58: =AVERAGEIFS('Base de Datos'!$C$2:$C$6863,'Base de Datos'!$B$2:$B$6863,Cálculos!$A58,'Base de Datos'!$G$2:$G$6863,1) -> -0.022047086 | C58: =AVERAGEIFS('Base de Datos'!$C$2:$C$6863,'Base de Datos'!$B$2:$B$6863,Cálculos!$A58,'Base de Datos'!$G$2:$G$6863,2) -> 0.0036113616 | D58: =AVERAGEIFS('Base de Datos'!$F$2:$F$6863,'Base de Datos'!$B$2:$B$6863,Cálculos!$A58,'Base de Datos'!$G$2:$G$6863,1) -> 0.020906187 | E58: =AVERAGEIFS('Base de Datos'!$F$2:$F$6863,'Base de Datos'!$B$2:$B$6863,Cálculos!$A58,'Base de Datos'!$G$2:$G$6863,2) -> 0.024638951 | G58: =B58-C58 -> -0.025658447 | H58: =+H57+G58 -> -0.010103981 | I58: =H58-(1.96*(_xlfn.STDEV.S($H$56:$H$75)/SQRT(COUNT($H$56:$H$75)))) -> -0.024232156 | J58: =H58+(1.96*(_xlfn.STDEV.S($H$56:$H$75)/SQRT(COUNT($H$56:$H$75)))) -> 0.004024194 | L58: =(B58-D58)-(C58-E58) -> -0.021925683 | M58: =+M57+L58 -> 0.0014128794 | N58: =M58-(1.96*(_xlfn.STDEV.S($M$56:$M$75)/SQRT(COUNT(M$56:M$75)))) -> -0.017709489 | O58: =M58+(1.96*(_xlfn.STDEV.S($M$56:$M$75)/SQRT(COUNT($M$56:$M$75)))) -> 0.020535248
A59: 39295 | B59: =AVERAGEIFS('Base de Datos'!$C$2:$C$6863,'Base de Datos'!$B$2:$B$6863,Cálculos!$A59,'Base de Datos'!$G$2:$G$6863,1) -> -0.015486608 | C59: =AVERAGEIFS('Base de Datos'!$C$2:$C$6863,'Base de Datos'!$B$2:$B$6863,Cálculos!$A59,'Base de Datos'!$G$2:$G$6863,2) -> -0.00054986592 | D59: =AVERAGEIFS('Base de Datos'!$F$2:$F$6863,'Base de Datos'!$B$2:$B$6863,Cálculos!$A59,'Base de Datos'!$G$2:$G$6863,1) -> 0.015899788 | E59: =AVERAGEIFS('Base de Datos'!$F$2:$F$6863,'Base de Datos'!$B$2:$B$6863,Cálculos!$A59,'Base de Datos'!$G$2:$G$6863,2) -> 0.020675621 | G59: =B59-C59 -> -0.014936742 | H59: =+H58+G59 -> -0.025040723 | I59: =H59-(1.96*(_xlfn.STDEV.S($H$56:$H$75)/SQRT(COUNT($H$56:$H$75)))) -> -0.039168898 | J59: =H59+(1.96*(_xlfn.STDEV.S($H$56:$H$75)/SQRT(COUNT($H$56:$H$75)))) -> -0.010912548 | L59: =(B59-D59)-(C59-E59) -> -0.010160909 | M59: =+M58+L59 -> -0.0087480295 | N59: =M59-(1.96*(_xlfn.STDEV.S($M$56:$M$75)/SQRT(COUNT(M$56:M$75)))) -> -0.027870398 | O59: =M59+(1.96*(_xlfn.STDEV.S($M$56:$M$75)/SQRT(COUNT($M$56:$M$75)))) -> 0.010374339
A60: 39326 | B60: =AVERAGEIFS('Base de Datos'!$C$2:$C$6863,'Base de Datos'!$B$2:$B$6863,Cálculos!$A60,'Base de Datos'!$G$2:$G$6863,1) -> -0.012568448 | C60: =AVERAGEIFS('Base de Datos'!$C$2:$C$6863,'Base de Datos'!$B$2:$B$6863,Cálculos!$A60,'Base de Datos'!$G$2:$G$6863,2) -> 0.011519475 | D60: =AVERAGEIFS('Base de Datos'!$F$2:$F$6863,'Base de Datos'!$B$2:$B$6863,Cálculos!$A60,'Base de Datos'!$G$2:$G$6863,1) -> 0.016081043 | E60: =AVERAGEIFS('Base de Datos'!$F$2:$F$6863,'Base de Datos'!$B$2:$B$6863,Cálculos!$A60,'Base de Datos'!$G$2:$G$6863,2) -> 0.021667372 | G60: =B60-C60 -> -0.024087923 | H60: =+H59+G60 -> -0.049128645 | I60: =H60-(1.96*(_xlfn.STDEV.S($H$56:$H$75)/SQRT(COUNT($H$56:$H$75)))) -> -0.06325682 | J60: =H60+(1.96*(_xlfn.STDEV.S($H$56:$H$75)/SQRT(COUNT($H$56:$H$75)))) -> -0.03500047 | L60: =(B60-D60)-(C60-E60) -> -0.018501594 | M60: =+M59+L60 -> -0.027249623 | N60: =M60-(1.96*(_xlfn.STDEV.S($M$56:$M$75)/SQRT(COUNT(M$56:M$75)))) -> -0.046371992 | O60: =M60+(1.96*(_xlfn.STDEV.S($M$56:$M$75)/SQRT(COUNT($M$56:$M$75)))) -> -0.0081272546
A61: 39356 | B61: =AVERAGEIFS('Base de Datos'!$C$2:$C$6863,'Base de Datos'!$B$2:$B$6863,Cálculos!$A61,'Base de Datos'!$G$2:$G$6863,1) -> 0.034680729 | C61: =AVERAGEIFS('Base de Datos'!$C$2:$C$6863,'Base de Datos'!$B$2:$B$6863,Cálculos!$A61,'Base de Datos'!$G$2:$G$6863,2) -> 0.029669184 | D61: =AVERAGEIFS('Base de Datos'!$F$2:$F$6863,'Base de Datos'!$B$2:$B$6863,Cálculos!$A61,'Base de Datos'!$G$2:$G$6863,1) -> 0.014748752 | E61: =AVERAGEIFS('Base de Datos'!$F$2:$F$6863,'Base de Datos'!$B$2:$B$6863,Cálculos!$A61,'Base de Datos'!$G$2:$G$6863,2) -> 0.020149511 | G61: =B61-C61 -> 0.0050115452 | H61: =+H60+G61 -> -0.0441171 | I61: =H61-(1.96*(_xlfn.STDEV.S($H$56:$H$75)/SQRT(COUNT($H$56:$H$75)))) -> -0.058245275 | J61: =H61+(1.96*(_xlfn.STDEV.S($H$56:$H$75)/SQRT(COUNT($H$56:$H$75)))) -> -0.029988925 | L61: =(B61-D61)-(C61-E61) -> 0.010412305 | M61: =+M60+L61 -> -0.016837318 | N61: =M61-(1.96*(_xlfn.STDEV.S($M$56:$M$75)/SQRT(COUNT(M$56:M$75)))) -> -0.035959687 | O61: =M61+(1.96*(_xlfn.STDEV.S($M$56:$M$75)/SQRT(COUNT($M$56:$M$75)))) -> 0.0022850504
A62: 39387 | B62: =AVERAGEIFS('Base de Datos'!$C$2:$C$6863,'Base de Datos'!$B$2:$B$6863,Cálculos!$A62,'Base de Datos'!$G$2:$G$6863,1) -> -0.082967238 | C62: =AVERAGEIFS('Base de Datos'!$C$2:$C$6863,'Base de Datos'!$B$2:$B$6863,Cálculos!$A62,'Base de Datos'!$G$2:$G$6863,2) -> -0.044034613 | D62: =AVERAGEIFS('Base de Datos'!$F$2:$F$6863,'Base de Datos'!$B$2:$B$6863,Cálculos!$A62,'Base de Datos'!$G$2:$G$6863,1) -> 0.013665319 | E62: =AVERAGEIFS('Base de Datos'!$F$2:$F$6863,'Base de Datos'!$B$2:$B$6863,Cálculos!$A62,'Base de Datos'!$G$2:$G$6863,2) -> 0.019907497 | G62: =B62-C62 -> -0.038932625 | H62: =+H61+G62 -> -0.083049725 | I62: =H62-(1.96*(_xlfn.STDEV.S($H$56:$H$75)/SQRT(COUNT($H$56:$H$75)))) -> -0.0971779 | J62: =H62+(1.96*(_xlfn.STDEV.S($H$56:$H$75)/SQRT(COUNT($H$56:$H$75)))) -> -0.06892155 | L62: =(B62-D62)-(C62-E62) -> -0.032690446 | M62: =+M61+L62 -> -0.049527765 | N62: =M62-(1.96*(_xlfn.STDEV.S($M$56:$M$75)/SQRT(COUNT(M$56:M$75)))) -> -0.068650133 | O62: =M62+(1.96*(_xlfn.STDEV.S($M$56:$M$75)/SQRT(COUNT($M$56:$M$75)))) -> -0.030405396
A63: 39417 | B63: =AVERAGEIFS('Base de Datos'!$C$2:$C$6863,'Base de Datos'!$B$2:$B$6863,Cálculos!$A63,'Base de Datos'!$G$2:$G$6863,1) -> -0.042422244 | C63: =AVERAGEIFS('Base de Datos'!$C$2:$C$6863,'Base de Datos'!$B$2:$B$6863,Cálculos!$A63,'Base de Datos'!$G$2:$G$6863,2) -> -0.035315327 | D63: =AVERAGEIFS('Base de Datos'!$F$2:$F$6863,'Base de Datos'!$B$2:$B$6863,Cálculos!$A63,'Base de Datos'!$G$2:$G$6863,1) -> 0.010683864 | E63: =AVERAGEIFS('Base de Datos'!$F$2:$F$6863,'Base de Datos'!$B$2:$B$6863,Cálculos!$A63,'Base de Datos'!$G$2:$G$6863,2) -> 0.017303799 | G63: =B63-C63 -> -0.007106917 | H63: =+H62+G63 -> -0.090156642 | I63: =H63-(1.96*(_xlfn.STDEV.S($H$56:$H$75)/SQRT(COUNT($H$56:$H$75)))) -> -0.10428482 | J63: =H63+(1.96*(_xlfn.STDEV.S($H$56:$H$75)/SQRT(COUNT($H$56:$H$75)))) -> -0.076028467 | L63: =(B63-D63)-(C63-E63) -> -0.00048698274 | M63: =+M62+L63 -> -0.050014747 | N63: =M63-(1.96*(_xlfn.STDEV.S($M$56:$M$75)/SQRT(COUNT(M$56:M$75)))) -> -0.069137116 | O63: =M63+(1.96*(_xlfn.STDEV.S($M$56:$M$75)/SQRT(COUNT($M$56:$M$75)))) -> -0.030892379
A64: 39448 | B64: =AVERAGEIFS('Base de Datos'!$C$2:$C$6863,'Base de Datos'!$B$2:$B$6863,Cálculos!$A64,'Base de Datos'!$G$2:$G$6863,1) -> -0.096746911 | C64: =AVERAGEIFS('Base de Datos'!$C$2:$C$6863,'Base de Datos'!$B$2:$B$6863,Cálculos!$A64,'Base de Datos'!$G$2:$G$6863,2) -> -0.099869614 | D64: =AVERAGEIFS('Base de Datos'!$F$2:$F$6863,'Base de Datos'!$B$2:$B$6863,Cálculos!$A64,'Base de Datos'!$G$2:$G$6863,1) -> 0.007171186 | E64: =AVERAGEIFS('Base de Datos'!$F$2:$F$6863,'Base de Datos'!$B$2:$B$6863,Cálculos!$A64,'Base de Datos'!$G$2:$G$6863,2) -> 0.013849017 | G64: =B64-C64 -> 0.0031227034 | H64: =+H63+G64 -> -0.087033939 | I64: =H64-(1.96*(_xlfn.STDEV.S($H$56:$H$75)/SQRT(COUNT($H$56:$H$75)))) -> -0.10116211 | J64: =H64+(1.96*(_xlfn.STDEV.S($H$56:$H$75)/SQRT(COUNT($H$56:$H$75)))) -> -0.072905764 | L64: =(B64-D64)-(C64-E64) -> 0.0098005345 | M64: =+M63+L64 -> -0.040214213 | N64: =M64-(1.96*(_xlfn.STDEV.S($M$56:$M$75)/SQRT(COUNT(M$56:M$75)))) -> -0.059336582 | O64: =M64+(1.96*(_xlfn.STDEV.S($M$56:$M$75)/SQRT(COUNT($M$56:$M$75)))) -> -0.021091844
A65: 39479 | B65: =AVERAGEIFS('Base de Datos'!$C$2:$C$6863,'Base de Datos'!$B$2:$B$6863,Cálculos!$A65,'Base de Datos'!$G$2:$G$6863,1) -> 0.032651751 | C65: =AVERAGEIFS('Base de Datos'!$C$2:$C$6863,'Base de Datos'!$B$2:$B$6863,Cálculos!$A65,'Base de Datos'!$G$2:$G$6863,2) -> 0.030176235 | D65: =AVERAGEIFS('Base de Datos'!$F$2:$F$6863,'Base de Datos'!$B$2:$B$6863,Cálculos!$A65,'Base de Datos'!$G$2:$G$6863,1) -> 0.0046782244 | E65: =AVERAGEIFS('Base de Datos'!$F$2:$F$6863,'Base de Datos'!$B$2:$B$6863,Cálculos!$A65,'Base de Datos'!$G$2:$G$6863,2) -> 0.011566894 | G65: =B65-C65 -> 0.0024755159 | H65: =+H64+G65 -> -0.084558423 | I65: =H65-(1.96*(_xlfn.STDEV.S($H$56:$H$75)/SQRT(COUNT($H$56:$H$75)))) -> -0.098686598 | J65: =H65+(1.96*(_xlfn.STDEV.S($H$56:$H$75)/SQRT(COUNT($H$56:$H$75)))) -> -0.070430248 | L65: =(B65-D65)-(C65-E65) -> 0.0093641853 | M65: =+M64+L65 -> -0.030850028 | N65: =M65-(1.96*(_xlfn.STDEV.S($M$56:$M$75)/SQRT(COUNT(M$56:M$75)))) -> -0.049972396 | O65: =M65+(1.96*(_xlfn.STDEV.S($M$56:$M$75)/SQRT(COUNT($M$56:$M$75)))) -> -0.011727659
A66: 39508 | B66: =AVERAGEIFS('Base de Datos'!$C$2:$C$6863,'Base de Datos'!$B$2:$B$6863,Cálculos!$A66,'Base de Datos'!$G$2:$G$6863,1) -> 0.0010065154 | C66: =AVERAGEIFS('Base de Datos'!$C$2:$C$6863,'Base de Datos'!$B$2:$B$6863,Cálculos!$A66,'Base de Datos'!$G$2:$G$6863,2) -> -0.031159741 | D66: =AVERAGEIFS('Base de Datos'!$F$2:$F$6863,'Base de Datos'!$B$2:$B$6863,Cálculos!$A66,'Base de Datos'!$G$2:$G$6863,1) -> 0.006765594 | E66: =AVERAGEIFS('Base de Datos'!$F$2:$F$6863,'Base de Datos'!$B$2:$B$6863,Cálculos!$A66,'Base de Datos'!$G$2:$G$6863,2) -> 0.01299357 | G66: =B66-C66 -> 0.032166256 | H66: =+H65+G66 -> -0.052392166 | I66: =H66-(1.96*(_xlfn.STDEV.S($H$56:$H$75)/SQRT(COUNT($H$56:$H$75)))) -> -0.066520341 | J66: =H66+(1.96*(_xlfn.STDEV.S($H$56:$H$75)/SQRT(COUNT($H$56:$H$75)))) -> -0.038263992 | L66: =(B66-D66)-(C66-E66) -> 0.038394232 | M66: =+M65+L66 -> 0.0075442044 | N66: =M66-(1.96*(_xlfn.STDEV.S($M$56:$M$75)/SQRT(COUNT(M$56:M$75)))) -> -0.011578164 | O66: =M66+(1.96*(_xlfn.STDEV.S($M$56:$M$75)/SQRT(COUNT($M$56:$M$75)))) -> 0.026666573
A67: 39539 | B67: =AVERAGEIFS('Base de Datos'!$C$2:$C$6863,'Base de Datos'!$B$2:$B$6863,Cálculos!$A67,'Base de Datos'!$G$2:$G$6863,1) -> 0.060904437 | C67: =AVERAGEIFS('Base de Datos'!$C$2:$C$6863,'Base de Datos'!$B$2:$B$6863,Cálculos!$A67,'Base de Datos'!$G$2:$G$6863,2) -> 0.035694956 | D67: =AVERAGEIFS('Base de Datos'!$F$2:$F$6863,'Base de Datos'!$B$2:$B$6863,Cálculos!$A67,'Base de Datos'!$G$2:$G$6863,1) -> 0.0073260787 | E67: =AVERAGEIFS('Base de Datos'!$F$2:$F$6863,'Base de Datos'!$B$2:$B$6863,Cálculos!$A67,'Base de Datos'!$G$2:$G$6863,2) -> 0.011519114 | G67: =B67-C67 -> 0.025209481 | H67: =+H66+G67 -> -0.027182685 | I67: =H67-(1.96*(_xlfn.STDEV.S($H$56:$H$75)/SQRT(COUNT($H$56:$H$75)))) -> -0.04131086 | J67: =H67+(1.96*(_xlfn.STDEV.S($H$56:$H$75)/SQRT(COUNT($H$56:$H$75)))) -> -0.01305451 | L67: =(B67-D67)-(C67-E67) -> 0.029402517 | M67: =+M66+L67 -> 0.036946721 | N67: =M67-(1.96*(_xlfn.STDEV.S($M$56:$M$75)/SQRT(COUNT(M$56:M$75)))) -> 0.017824353 | O67: =M67+(1.96*(_xlfn.STDEV.S($M$56:$M$75)/SQRT(COUNT($M$56:$M$75)))) -> 0.05606909
A68: 39569 | B68: =AVERAGEIFS('Base de Datos'!$C$2:$C$6863,'Base de Datos'!$B$2:$B$6863,Cálculos!$A68,'Base de Datos'!$G$2:$G$6863,1) -> 0.032432776 | C68: =AVERAGEIFS('Base de Datos'!$C$2:$C$6863,'Base de Datos'!$B$2:$B$6863,Cálculos!$A68,'Base de Datos'!$G$2:$G$6863,2) -> 0.0009482657 | D68: =AVERAGEIFS('Base de Datos'!$F$2:$F$6863,'Base de Datos'!$B$2:$B$6863,Cálculos!$A68,'Base de Datos'!$G$2:$G$6863,1) -> 0.0079173029 | E68: =AVERAGEIFS('Base de Datos'!$F$2:$F$6863,'Base de Datos'!$B$2:$B$6863,Cálculos!$A68,'Base de Datos'!$G$2:$G$6863,2) -> 0.011794145 | G68: =B68-C68 -> 0.03148451 | H68: =+H67+G68 -> 0.004301825 | I68: =H68-(1.96*(_xlfn.STDEV.S($H$56:$H$75)/SQRT(COUNT($H$56:$H$75)))) -> -0.0098263499 | J68: =H68+(1.96*(_xlfn.STDEV.S($H$56:$H$75)/SQRT(COUNT($H$56:$H$75)))) -> 0.01843 | L68: =(B68-D68)-(C68-E68) -> 0.035361352 | M68: =+M67+L68 -> 0.072308073 | N68: =M68-(1.96*(_xlfn.STDEV.S($M$56:$M$75)/SQRT(COUNT(M$56:M$75)))) -> 0.053185705 | O68: =M68+(1.96*(_xlfn.STDEV.S($M$56:$M$75)/SQRT(COUNT($M$56:$M$75)))) -> 0.091430442
... A75: 39783 | B75: =AVERAGEIFS('Base de Datos'!$C$2:$C$6863,'Base de Datos'!$B$2:$B$6863,Cálculos!$A75,'Base de Datos'!$G$2:$G$6863,1) -> -0.022139406 | C75: =AVERAGEIFS('Base de Datos'!$C$2:$C$6863,'Base de Datos'!$B$2:$B$6863,Cálculos!$A75,'Base de Datos'!$G$2:$G$6863,2) -> -0.02998649 | D75: =AVERAGEIFS('Base de Datos'!$F$2:$F$6863,'Base de Datos'!$B$2:$B$6863,Cálculos!$A75,'Base de Datos'!$G$2:$G$6863,1) -> 0.0041578621 | E75: =AVERAGEIFS('Base de Datos'!$F$2:$F$6863,'Base de Datos'!$B$2:$B$6863,Cálculos!$A75,'Base de Datos'!$G$2:$G$6863,2) -> 0.0079412156 | G75: =B75-C75 -> 0.0078470833 | H75: =+H74+G75 -> -0.021983752 | I75: =H75-(1.96*(_xlfn.STDEV.S($H$56:$H$75)/SQRT(COUNT($H$56:$H$75)))) -> -0.036111927 | J75: =H75+(1.96*(_xlfn.STDEV.S($H$56:$H$75)/SQRT(COUNT($H$56:$H$75)))) -> -0.0078555771 | L75: =(B75-D75)-(C75-E75) -> 0.011630437 | M75: =+M74+L75 -> 0.064146433 | N75: =M75-(1.96*(_xlfn.STDEV.S($M$56:$M$75)/SQRT(COUNT(M$56:M$75)))) -> 0.045024065 | O75: =M75+(1.96*(_xlfn.STDEV.S($M$56:$M$75)/SQRT(COUNT($M$56:$M$75)))) -> 0.083268802

Sheet Gráficos
A1: =Cálculos!A2 -> fecha | B1: =Cálculos!H2 -> SpreadCUM | C1: =Cálculos!I2 -> INN | D1: =Cálculos!J2 -> INP | E1: =Cálculos!M2 -> SpreadRA | F1: =Cálculos!N2 -> INNRA | G1: =Cálculos!O2 -> INPRA
A2: =Cálculos!A56 -> 39203 | B2: =Cálculos!H56 -> -0.0051993925 | C2: =Cálculos!I56 -> -0.019327567 | D2: =Cálculos!J56 -> 0.0089287824 | E2: =Cálculos!M56 -> -0.0023029679 | F2: =Cálculos!N56 -> -0.021425337 | G2: =Cálculos!O56 -> 0.016819401
A3: =Cálculos!A57 -> 39234 | B3: =Cálculos!H57 -> 0.015554466 | C3: =Cálculos!I57 -> 0.0014262915 | D3: =Cálculos!J57 -> 0.029682641 | E3: =Cálculos!M57 -> 0.023338562 | F3: =Cálculos!N57 -> 0.0042161933 | G3: =Cálculos!O57 -> 0.042460931
A4: =Cálculos!A58 -> 39264 | B4: =Cálculos!H58 -> -0.010103981 | C4: =Cálculos!I58 -> -0.024232156 | D4: =Cálculos!J58 -> 0.004024194 | E4: =Cálculos!M58 -> 0.0014128794 | F4: =Cálculos!N58 -> -0.017709489 | G4: =Cálculos!O58 -> 0.020535248
A5: =Cálculos!A59 -> 39295 | B5: =Cálculos!H59 -> -0.025040723 | C5: =Cálculos!I59 -> -0.039168898 | D5: =Cálculos!J59 -> -0.010912548 | E5: =Cálculos!M59 -> -0.0087480295 | F5: =Cálculos!N59 -> -0.027870398 | G5: =Cálculos!O59 -> 0.010374339
A6: =Cálculos!A60 -> 39326 | B6: =Cálculos!H60 -> -0.049128645 | C6: =Cálculos!I60 -> -0.06325682 | D6: =Cálculos!J60 -> -0.03500047 | E6: =Cálculos!M60 -> -0.027249623 | F6: =Cálculos!N60 -> -0.046371992 | G6: =Cálculos!O60 -> -0.0081272546
A7: =Cálculos!A61 -> 39356 | B7: =Cálculos!H61 -> -0.0441171 | C7: =Cálculos!I61 -> -0.058245275 | D7: =Cálculos!J61 -> -0.029988925 | E7: =Cálculos!M61 -> -0.016837318 | F7: =Cálculos!N61 -> -0.035959687 | G7: =Cálculos!O61 -> 0.0022850504
A8: =Cálculos!A62 -> 39387 | B8: =Cálculos!H62 -> -0.083049725 | C8: =Cálculos!I62 -> -0.0971779 | D8: =Cálculos!J62 -> -0.06892155 | E8: =Cálculos!M62 -> -0.049527765 | F8: =Cálculos!N62 -> -0.068650133 | G8: =Cálculos!O62 -> -0.030405396
A9: =Cálculos!A63 -> 39417 | B9: =Cálculos!H63 -> -0.090156642 | C9: =Cálculos!I63 -> -0.10428482 | D9: =Cálculos!J63 -> -0.076028467 | E9: =Cálculos!M63 -> -0.050014747 | F9: =Cálculos!N63 -> -0.069137116 | G9: =Cálculos!O63 -> -0.030892379
A10: =Cálculos!A64 -> 39448 | B10: =Cálculos!H64 -> -0.087033939 | C10: =Cálculos!I64 -> -0.10116211 | D10: =Cálculos!J64 -> -0.072905764 | E10: =Cálculos!M64 -> -0.040214213 | F10: =Cálculos!N64 -> -0.059336582 | G10: =Cálculos!O64 -> -0.021091844
A11: =Cálculos!A65 -> 39479 | B11: =Cálculos!H65 -> -0.084558423 | C11: =Cálculos!I65 -> -0.098686598 | D11: =Cálculos!J65 -> -0.070430248 | E11: =Cálculos!M65 -> -0.030850028 | F11: =Cálculos!N65 -> -0.049972396 | G11: =Cálculos!O65 -> -0.011727659
A12: =Cálculos!A66 -> 39508 | B12: =Cálculos!H66 -> -0.052392166 | C12: =Cálculos!I66 -> -0.066520341 | D12: =Cálculos!J66 -> -0.038263992 | E12: =Cálculos!M66 -> 0.0075442044 | F12: =Cálculos!N66 -> -0.011578164 | G12: =Cálculos!O66 -> 0.026666573
A13: =Cálculos!A67 -> 39539 | B13: =Cálculos!H67 -> -0.027182685 | C13: =Cálculos!I67 -> -0.04131086 | D13: =Cálculos!J67 -> -0.01305451 | E13: =Cálculos!M67 -> 0.036946721 | F13: =Cálculos!N67 -> 0.017824353 | G13: =Cálculos!O67 -> 0.05606909
... A21: =Cálculos!A75 -> 39783 | B21: =Cálculos!H75 -> -0.021983752 | C21: =Cálculos!I75 -> -0.036111927 | D21: =Cálculos!J75 -> -0.0078555771 | E21: =Cálculos!M75 -> 0.064146433 | F21: =Cálculos!N75 -> 0.045024065 | G21: =Cálculos!O75 -> 0.083268802
