Workbook

Sheet Portafolio
A1: fecha | B1: AAPL | C1: JPM | D1: MSFT | H1: SD | P1: VaR | X1: CVaR
A2: 2024-01-02 | B2: 184.93822 | C2: 168.0667 | D2: 368.8541 | E2: AAPL | F2: JPM | G2: MSFT | H2: Portafolio | P2: Portafolio | X2: Portafolio
A3: 2024-01-03 | B3: 183.55348 | C3: 167.33418 | D3: 368.58557 | E3: =LN(B3/B2) -> -0.0075157276 | F3: =LN(C3/C2) -> -0.0043679949 | G3: =LN(D3/D2) -> -0.00072826083 | H3: =SUMPRODUCT(E3:G3,$K$15:$M$15) -> -0.003193079 | K3: Matriz de Covarianza-Varianza | P3: =SUMPRODUCT(E3:G3,$S$15:$U$15) -> -0.0031914182 | S3: Matriz de Covarianza-Varianza | X3: =SUMPRODUCT(E3:G3,$AA$15:$AC$15) -> -0.0031384189 | AA3: Matriz de Covarianza-Varianza
A4: 2024-01-04 | B4: 181.22234 | C4: 168.44463 | D4: 365.94 | E4: =LN(B4/B3) -> -0.012781429 | F4: =LN(C4/C3) -> 0.0066141592 | G4: =LN(D4/D3) -> -0.0072035078 | H4: =SUMPRODUCT(E4:G4,$K$15:$M$15) -> -0.0015849665 | K4: AAPL | L4: JPM | M4: MSFT | P4: =SUMPRODUCT(E4:G4,$S$15:$U$15) -> -0.0015772476 | S4: AAPL | T4: JPM | U4: MSFT | X4: =SUMPRODUCT(E4:G4,$AA$15:$AC$15) -> -0.0036093691 | AA4: AAPL | AB4: JPM | AC4: MSFT
A5: 2024-01-05 | B5: 180.49507 | C5: 169.28975 | D5: 365.75107 | E5: =LN(B5/B4) -> -0.0040211799 | F5: =LN(C5/C4) -> 0.0050046725 | G5: =LN(D5/D4) -> -0.0005164319 | H5: =SUMPRODUCT(E5:G5,$K$15:$M$15) -> 0.0015763662 | J5: AAPL | K5: =VAR(E3:E125) -> 0.00022810696 | L5: =COVAR(E3:E125,F3:F125) -> -2.5044799e-05 | M5: =COVAR(E3:E125,G3:G125) -> 6.6909284e-05 | P5: =SUMPRODUCT(E5:G5,$S$15:$U$15) -> 0.0015800213 | R5: AAPL | S5: =VAR(E3:E125) -> 0.00022810696 | T5: =COVAR(E3:E125,F3:F125) -> -2.5044799e-05 | U5: =COVAR(E3:E125,G3:G125) -> 6.6909284e-05 | X5: =SUMPRODUCT(E5:G5,$AA$15:$AC$15) -> 0.00069351791 | Z5: AAPL | AA5: =VAR(E3:E125) -> 0.00022810696 | AB5: =COVAR(E3:E125,F3:F125) -> -2.5044799e-05 | AC5: =COVAR(E3:E125,G3:G125) -> 6.6909284e-05
A6: 2024-01-08 | B6: 184.85852 | C6: 169.04408 | D6: 372.65335 | E6: =LN(B6/B5) -> 0.023887306 | F6: =LN(C6/C5) -> -0.0014522139 | G6: =LN(D6/D5) -> 0.018695673 | H6: =SUMPRODUCT(E6:G6,$K$15:$M$15) -> 0.010152267 | J6: JPM | K6: =COVAR(E3:E125,F3:F125) -> -2.5044799e-05 | L6: =VAR(F3:F125) -> 0.00014318033 | M6: =COVAR(F3:F125,G3:G125) -> 1.7859878e-06 | P6: =SUMPRODUCT(E6:G6,$S$15:$U$15) -> 0.010142328 | R6: JPM | S6: =COVAR(E3:E125,F3:F125) -> -2.5044799e-05 | T6: =VAR(F3:F125) -> 0.00014318033 | U6: =COVAR(F3:F125,G3:G125) -> 1.7859878e-06 | X6: =SUMPRODUCT(E6:G6,$AA$15:$AC$15) -> 0.01293359 | Z6: JPM | AA6: =COVAR(E3:E125,F3:F125) -> -2.5044799e-05 | AB6: =VAR(F3:F125) -> 0.00014318033 | AC6: =COVAR(F3:F125,G3:G125) -> 1.7859878e-06
A7: 2024-01-09 | B7: 184.44011 | C7: 167.70761 | D7: 373.74734 | E7: =LN(B7/B6) -> -0.0022659785 | F7: =LN(C7/C6) -> -0.0079374717 | G7: =LN(D7/D6) -> 0.0029313879 | H7: =SUMPRODUCT(E7:G7,$K$15:$M$15) -> -0.0026313546 | J7: MSFT | K7: =COVAR(E3:E125,G3:G125) -> 6.6909284e-05 | L7: =COVAR(F3:F125,G3:G125) -> 1.7859878e-06 | M7: =VAR(G3:G125) -> 0.00014327713 | P7: =SUMPRODUCT(E7:G7,$S$15:$U$15) -> -0.0026331379 | R7: MSFT | S7: =COVAR(E3:E125,G3:G125) -> 6.6909284e-05 | T7: =COVAR(F3:F125,G3:G125) -> 1.7859878e-06 | U7: =VAR(G3:G125) -> 0.00014327713 | X7: =SUMPRODUCT(E7:G7,$AA$15:$AC$15) -> -0.0015945524 | Z7: MSFT | AA7: =COVAR(E3:E125,G3:G125) -> 6.6909284e-05 | AB7: =COVAR(F3:F125,G3:G125) -> 1.7859878e-06 | AC7: =VAR(G3:G125) -> 0.00014327713
A8: 2024-01-10 | B8: 185.48614 | C8: 168.06139 | D8: 380.68942 | E8: =LN(B8/B7) -> 0.0056553893 | F8: =LN(C8/C7) -> 0.0021072531 | G8: =LN(D8/D7) -> 0.018403858 | H8: =SUMPRODUCT(E8:G8,$K$15:$M$15) -> 0.0094720816 | P8: =SUMPRODUCT(E8:G8,$S$15:$U$15) -> 0.0094716249 | X8: =SUMPRODUCT(E8:G8,$AA$15:$AC$15) -> 0.010739402
A9: 2024-01-11 | B9: 184.88841 | C9: 167.35384 | D9: 382.53931 | E9: =LN(B9/B8) -> -0.0032277218 | F9: =LN(C9/C8) -> -0.0042189561 | G9: =LN(D9/D8) -> 0.0048475314 | H9: =SUMPRODUCT(E9:G9,$K$15:$M$15) -> -0.00023880911 | J9: Estadística | K9: AAPL | L9: JPM | M9: MSFT | P9: =SUMPRODUCT(E9:G9,$S$15:$U$15) -> -0.00023862353 | R9: Estadística | S9: AAPL | T9: JPM | U9: MSFT | X9: =SUMPRODUCT(E9:G9,$AA$15:$AC$15) -> 0.00040929129 | Z9: Estadística | AA9: AAPL | AB9: JPM | AC9: MSFT
A10: 2024-01-12 | B10: 185.21716 | C10: 166.12546 | D10: 386.35843 | E10: =LN(B10/B9) -> 0.0017765238 | F10: =LN(C10/C9) -> -0.0073670772 | G10: =LN(D10/D9) -> 0.0099341008 | H10: =SUMPRODUCT(E10:G10,$K$15:$M$15) -> 0.0010930566 | J10: Media | K10: =AVERAGE(E3:E125) -> 0.0010477795 | L10: =AVERAGE(F3:F125) -> 0.0014110405 | M10: =AVERAGE(G3:G125) -> 0.0015467058 | P10: =SUMPRODUCT(E10:G10,$S$15:$U$15) -> 0.0010901661 | R10: Media | S10: =AVERAGE(E3:E125) -> 0.0010477795 | T10: =AVERAGE(F3:F125) -> 0.0014110405 | U10: =AVERAGE(G3:G125) -> 0.0015467058 | X10: =SUMPRODUCT(E10:G10,$AA$15:$AC$15) -> 0.002750154 | Z10: Media | AA10: =AVERAGE(E3:E125) -> 0.0010477795 | AB10: =AVERAGE(F3:F125) -> 0.0014110405 | AC10: =AVERAGE(G3:G125) -> 0.0015467058
A11: 2024-01-16 | B11: 182.93582 | C11: 165.0838 | D11: 388.14865 | E11: =LN(B11/B10) -> -0.012393602 | F11: =LN(C11/C10) -> -0.0062900411 | G11: =LN(D11/D10) -> 0.0046228765 | H11: =SUMPRODUCT(E11:G11,$K$15:$M$15) -> -0.0023696334 | J11: Sd | K11: =STDEV(E3:E125) -> 0.01510321 | L11: =STDEV(F3:F125) -> 0.011965798 | M11: =STDEV(G3:G125) -> 0.011969843 | P11: =SUMPRODUCT(E11:G11,$S$15:$U$15) -> -0.0023661454 | R11: Sd | S11: =STDEV(E3:E125) -> 0.01510321 | T11: =STDEV(F3:F125) -> 0.011965798 | U11: =STDEV(G3:G125) -> 0.011969843 | X11: =SUMPRODUCT(E11:G11,$AA$15:$AC$15) -> -0.0020124852 | Z11: Sd | AA11: =STDEV(E3:E125) -> 0.01510321 | AB11: =STDEV(G3:G125) -> 0.011969843 | AC11: =STDEV(G3:G125) -> 0.011969843
A12: 2024-01-17 | B12: 181.98941 | C12: 164.19936 | D12: 387.353 | E12: =LN(B12/B11) -> -0.0051868884 | F12: =LN(C12/C11) -> -0.0053719561 | G12: =LN(D12/D11) -> -0.0020519739 | H12: =SUMPRODUCT(E12:G12,$K$15:$M$15) -> -0.0039357185 | J12: Sharpe | K12: =K10/K11 -> 0.069374623 | L12: =L10/L11 -> 0.1179228 | M12: =M10/M11 -> 0.12921688 | P12: =SUMPRODUCT(E12:G12,$S$15:$U$15) -> -0.003935571 | R12: Sharpe | S12: =S10/S11 -> 0.069374623 | T12: =T10/T11 -> 0.1179228 | U12: =U10/U11 -> 0.12921688 | X12: =SUMPRODUCT(E12:G12,$AA$15:$AC$15) -> -0.003708708 | Z12: Sharpe | AA12: =AA10/AA11 -> 0.069374623 | AB12: =AB10/AB11 -> 0.11788296 | AC12: =AC10/AC11 -> 0.12921688
A13: 2024-01-18 | B13: 187.91693 | C13: 164.52365 | D13: 391.72906 | E13: =LN(B13/B12) -> 0.032051509 | F13: =LN(C13/C12) -> 0.00197306 | G13: =LN(D13/D12) -> 0.011234026 | H13: =SUMPRODUCT(E13:G13,$K$15:$M$15) -> 0.0095054398 | P13: =SUMPRODUCT(E13:G13,$S$15:$U$15) -> 0.0094926251 | X13: =SUMPRODUCT(E13:G13,$AA$15:$AC$15) -> 0.011852209
A14: 2024-01-19 | B14: 190.83585 | C14: 167.36365 | D14: 396.50299 | E14: =LN(B14/B13) -> 0.015413603 | F14: =LN(C14/C13) -> 0.017114639 | G14: =LN(D14/D13) -> 0.012113144 | H14: =SUMPRODUCT(E14:G14,$K$15:$M$15) -> 0.014781335 | J14: Pesos | K14: AAPL | L14: JPM | M14: MSFT | N14: Total | P14: =SUMPRODUCT(E14:G14,$S$15:$U$15) -> 0.014781749 | R14: Pesos | S14: AAPL | T14: JPM | U14: MSFT | V14: Total | X14: =SUMPRODUCT(E14:G14,$AA$15:$AC$15) -> 0.014356909 | Z14: Pesos | AA14: AAPL | AB14: JPM | AC14: MSFT | AD14: Total
A15: 2024-01-22 | B15: 193.15703 | C15: 167.1671 | D15: 394.35477 | E15: =LN(B15/B14) -> 0.012089863 | F15: =LN(C15/C14) -> -0.00117507 | G15: =LN(D15/D14) -> -0.0054326563 | H15: =SUMPRODUCT(E15:G15,$K$15:$M$15) -> -0.0014064286 | J15: wi | K15: 0.11927555 | L15: 0.45476931 | M15: 0.42595514 | N15: =SUM(K15:M15) -> 1 | P15: =SUMPRODUCT(E15:G15,$S$15:$U$15) -> -0.0014126588 | R15: wi | S15: 0.11882815 | T15: 0.45514733 | U15: 0.42602453 | V15: =SUM(S15:U15) -> 1 | X15: =SUMPRODUCT(E15:G15,$AA$15:$AC$15) -> -0.00091491016 | Z15: wi | AA15: 0.17723913 | AB15: 0.33165978 | AC15: 0.49110109 | AD15: =SUM(AA15:AC15) -> 1
A16: 2024-01-23 | B16: 194.44215 | C16: 166.0665 | D16: 396.73175 | E16: =LN(B16/B15) -> 0.0066312339 | F16: =LN(C16/C15) -> -0.0066056077 | G16: =LN(D16/D15) -> 0.0060094334 | H16: =SUMPRODUCT(E16:G16,$K$15:$M$15) -> 0.0003466655 | P16: =SUMPRODUCT(E16:G16,$S$15:$U$15) -> 0.00034161855 | X16: =SUMPRODUCT(E16:G16,$AA$15:$AC$15) -> 0.0019357389
A17: 2024-01-24 | B17: 193.76472 | C17: 167.55037 | D17: 400.37183 | E17: =LN(B17/B16) -> -0.0034900458 | F17: =LN(C17/C16) -> 0.008895721 | G17: =LN(D17/D16) -> 0.00913332 | H17: =SUMPRODUCT(E17:G17,$K$15:$M$15) -> 0.0075196083 | J17: Retorno | K17: =AVERAGE(H3:H125) -> 0.0014254997 | M17: Rf | N17: 0.0452 | P17: =SUMPRODUCT(E17:G17,$S$15:$U$15) -> 0.0075251663 | R17: Retorno | S17: =AVERAGE(P3:P125) -> 0.0014256716 | X17: =SUMPRODUCT(E17:G17,$AA$15:$AC$15) -> 0.0068171636 | Z17: Retorno | AA17: =AVERAGE(X3:X125) -> 0.0014132818
A18: 2024-01-25 | B18: 193.43597 | C18: 169.94815 | D18: 402.66928 | E18: =LN(B18/B17) -> -0.0016980893 | F18: =LN(C18/C17) -> 0.014209376 | G18: =LN(D18/D17) -> 0.0057219015 | H18: =SUMPRODUCT(E18:G18,$K$15:$M$15) -> 0.0086967208 | J18: Riesgo SD | K18: {=SQRT(MMULT(MMULT(K15:M15,K5:M7),TRANSPOSE(K15:M15)))} -> 0.0079766322 | M18: Rf Diario | N18: =N17/250 -> 0.0001808 | P18: =SUMPRODUCT(E18:G18,$S$15:$U$15) -> 0.008703249 | R18: Riesgo SD | S18: {=MMULT(MMULT(S15:U15,S5:U7),TRANSPOSE(S15:U15))} -> 6.3644311e-05 | X18: =SUMPRODUCT(E18:G18,$AA$15:$AC$15) -> 0.0072217427 | Z18: Riesgo SD | AA18: {=MMULT(MMULT(AA15:AC15,AA5:AC7),TRANSPOSE(AA15:AC15))} -> 6.675614e-05
A19: 2024-01-26 | B19: 191.6926 | C19: 169.29958 | D19: 401.73438 | E19: =LN(B19/B18) -> -0.009053546 | F19: =LN(C19/C18) -> -0.0038236105 | G19: =LN(D19/D18) -> -0.0023244708 | H19: =SUMPRODUCT(E19:G19,$K$15:$M$15) -> -0.0038088477 | J19: Sharpe SD | K19: =(K17-N18)/K18 -> 0.15604326 | P19: =SUMPRODUCT(E19:G19,$S$15:$U$15) -> -0.0038064038 | R19: Riesgo VaR | S19: =STDEV(P3:P125)*NORMSINV(1-95%)*SQRT(1) -> -0.013126232 | X19: =SUMPRODUCT(E19:G19,$AA$15:$AC$15) -> -0.0040143306 | Z19: Riesgo VaR | AA19: =STDEV(X3:X125)*NORMSINV(1-95%)*SQRT(1) -> -0.013446842
A20: 2024-01-29 | B20: 191.0052 | C20: 169.74178 | D20: 407.49292 | E20: =LN(B20/B19) -> -0.003592359 | F20: =LN(C20/C19) -> 0.0026085311 | G20: =LN(D20/D19) -> 0.014232447 | H20: =SUMPRODUCT(E20:G20,$K$15:$M$15) -> 0.006820183 | P20: =SUMPRODUCT(E20:G20,$S$15:$U$15) -> 0.0068237639 | R20: Sharpe VaR | S20: =-(S17-N18)/S19 -> 0.094838458 | X20: =SUMPRODUCT(E20:G20,$AA$15:$AC$15) -> 0.0072180083 | Z20: Riesgo CVaR | AA20: =AVERAGEIF(X3:X125,"<="&AA19,X3:X125) -> -0.018511155
A21: 2024-01-30 | B21: 187.32915 | C21: 173.22055 | D21: 406.36908 | E21: =LN(B21/B20) -> -0.019433454 | F21: =LN(C21/C20) -> 0.020287326 | G21: =LN(D21/D20) -> -0.0027617483 | H21: =SUMPRODUCT(E21:G21,$K$15:$M$15) -> 0.0057317365 | P21: =SUMPRODUCT(E21:G21,$S$15:$U$15) -> 0.0057479085 | X21: =SUMPRODUCT(E21:G21,$AA$15:$AC$15) -> 0.0019278242 | Z21: Sharpe CVaR | AA21: =-(AA17-N18)/AA20 -> 0.066580492
A22: 2024-01-31 | B22: 183.70291 | C22: 171.3436 | D22: 395.41891 | E22: =LN(B22/B21) -> -0.019547375 | F22: =LN(C22/C21) -> -0.010894759 | G22: =LN(D22/D21) -> -0.027316063 | H22: =SUMPRODUCT(E22:G22,$K$15:$M$15) -> -0.018921543 | P22: =SUMPRODUCT(E22:G22,$S$15:$U$15) -> -0.018918812 | S22: AAPL | T22: JPM | U22: MSFT | X22: =SUMPRODUCT(E22:G22,$AA$15:$AC$15) -> -0.020492861
A23: 2024-02-01 | B23: 186.15363 | C23: 170.72449 | D23: 401.58521 | E23: =LN(B23/B22) -> 0.013252436 | F23: =LN(C23/C22) -> -0.0036198102 | G23: =LN(D23/D22) -> 0.015473981 | H23: =SUMPRODUCT(E23:G23,$K$15:$M$15) -> 0.0065257348 | P23: =SUMPRODUCT(E23:G23,$S$15:$U$15) -> 0.0065195109 | R23: VaR Activos | S23: =STDEV(E3:E125)*NORMSINV(1-95%)*SQRT(1) -> -0.02484257 | T23: =STDEV(F3:F125)*NORMSINV(1-95%)*SQRT(1) -> -0.019681987 | U23: =STDEV(G3:G125)*NORMSINV(1-95%)*SQRT(1) -> -0.019688639 | X23: =SUMPRODUCT(E23:G23,$AA$15:$AC$15) -> 0.0087475936 | AA23: AAPL | AB23: JPM | AC23: MSFT
A24: 2024-02-02 | B24: 185.14743 | C24: 171.70718 | D24: 408.98474 | E24: =LN(B24/B23) -> -0.0054198476 | F24: =LN(C24/C23) -> 0.0057395345 | G24: =LN(D24/D23) -> 0.01825812 | H24: =SUMPRODUCT(E24:G24,$K$15:$M$15) -> 0.0097408489 | P24: =SUMPRODUCT(E24:G24,$S$15:$U$15) -> 0.0097467102 | X24: =SUMPRODUCT(E24:G24,$AA$15:$AC$15) -> 0.0099095463 | Z24: CVaR | AA24: =AVERAGEIF(E3:E125,"<"&S23,E3:E125) -> -0.032092581 | AB24: =AVERAGEIF(F3:F125,"<"&T23,F3:F125) -> -0.046511046 | AC24: =AVERAGEIF(G3:G125,"<"&U23,G3:G125) -> -0.026449913
A25: 2024-02-05 | B25: 186.9705 | C25: 171.48116 | D25: 403.44507 | E25: =LN(B25/B24) -> 0.0097984473 | F25: =LN(C25/C24) -> -0.0013172268 | G25: =LN(D25/D24) -> -0.013637507 | H25: =SUMPRODUCT(E25:G25,$K$15:$M$15) -> -0.0052392854 | P25: =SUMPRODUCT(E25:G25,$S$15:$U$15) -> -0.0052451134 | X25: =SUMPRODUCT(E25:G25,$AA$15:$AC$15) -> -0.0053975975
A26: 2024-02-06 | B26: 188.5844 | C26: 172.07079 | D26: 403.28589 | E26: =LN(B26/B25) -> 0.0085947569 | F26: =LN(C26/C25) -> 0.0034325562 | G26: =LN(D26/D25) -> -0.00039462897 | H26: =SUMPRODUCT(E26:G26,$K$15:$M$15) -> 0.0024180714 | P26: =SUMPRODUCT(E26:G26,$S$15:$U$15) -> 0.0024154962 | X26: =SUMPRODUCT(E26:G26,$AA$15:$AC$15) -> 0.0024679654
A27: 2024-02-07 | B27: 188.69398 | C27: 172.39507 | D27: 411.79941 | E27: =LN(B27/B26) -> 0.00058094292 | F27: =LN(C27/C26) -> 0.0018827985 | G27: =LN(D27/D26) -> 0.020890645 | H27: =SUMPRODUCT(E27:G27,$K$15:$M$15) -> 0.009824009 | P27: =SUMPRODUCT(E27:G27,$S$15:$U$15) -> 0.0098259103 | X27: =SUMPRODUCT(E27:G27,$AA$15:$AC$15) -> 0.010986833
A28: 2024-02-08 | B28: 187.60811 | C28: 171.77599 | D28: 411.85904 | E28: =LN(B28/B27) -> -0.005771318 | F28: =LN(C28/C27) -> -0.003597515 | G28: =LN(D28/D27) -> 0.00014479618 | H28: =SUMPRODUCT(E28:G28,$K$15:$M$15) -> -0.0022627399 | P28: =SUMPRODUCT(E28:G28,$S$15:$U$15) -> -0.0022615077 | X28: =SUMPRODUCT(E28:G28,$AA$15:$AC$15) -> -0.0021449449
A29: 2024-02-09 | B29: 188.37616 | C29: 171.98235 | D29: 418.26404 | E29: =LN(B29/B28) -> 0.0040855553 | F29: =LN(C29/C28) -> 0.0012006105 | G29: =LN(D29/D28) -> 0.01543175 | H29: =SUMPRODUCT(E29:G29,$K$15:$M$15) -> 0.0076065409 | P29: =SUMPRODUCT(E29:G29,$S$15:$U$15) -> 0.0076062376 | X29: =SUMPRODUCT(E29:G29,$AA$15:$AC$15) -> 0.0087008637
A30: 2024-02-12 | B30: 186.68042 | C30: 172.74884 | D30: 413.00284 | E30: =LN(B30/B29) -> -0.0090426429 | F30: =LN(C30/C29) -> 0.0044469198 | G30: =LN(D30/D29) -> -0.012658438 | H30: =SUMPRODUCT(E30:G30,$K$15:$M$15) -> -0.0044481705 | P30: =SUMPRODUCT(E30:G30,$S$15:$U$15) -> -0.004443322 | X30: =SUMPRODUCT(E30:G30,$AA$15:$AC$15) -> -0.0063444185
A31: 2024-02-13 | B31: 184.57571 | C31: 171.24532 | D31: 404.11139 | E31: =LN(B31/B30) -> -0.011338417 | F31: =LN(C31/C30) -> -0.0087416268 | G31: =LN(D31/D30) -> -0.021763909 | H31: =SUMPRODUCT(E31:G31,$K$15:$M$15) -> -0.014598268 | P31: =SUMPRODUCT(E31:G31,$S$15:$U$15) -> -0.01459801 | X31: =SUMPRODUCT(E31:G31,$AA$15:$AC$15) -> -0.015597137
A32: 2024-02-14 | B32: 183.68794 | C32: 172.9847 | D32: 408.01727 | E32: =LN(B32/B31) -> -0.0048214007 | F32: =LN(C32/C31) -> 0.010106002 | G32: =LN(D32/D31) -> 0.0096189532 | H32: =SUMPRODUCT(E32:G32,$K$15:$M$15) -> 0.0081180669 | P32: =SUMPRODUCT(E32:G32,$S$15:$U$15) -> 0.0081247117 | X32: =SUMPRODUCT(E32:G32,$AA$15:$AC$15) -> 0.007221092
A33: 2024-02-15 | B33: 183.39868 | C33: 176.75827 | D33: 405.09784 | E33: =LN(B33/B32) -> -0.001575982 | F33: =LN(C33/C32) -> 0.02157997 | G33: =LN(D33/D32) -> -0.0071808924 | H33: =SUMPRODUCT(E33:G33,$K$15:$M$15) -> 0.0065671938 | P33: =SUMPRODUCT(E33:G33,$S$15:$U$15) -> 0.0065755584 | X33: =SUMPRODUCT(E33:G33,$AA$15:$AC$15) -> 0.0033513385
A34: 2024-02-16 | B34: 181.85255 | C34: 175.9328 | D34: 402.60684 | E34: =LN(B34/B33) -> -0.0084661536 | F34: =LN(C34/C33) -> -0.004680989 | G34: =LN(D34/D33) -> -0.0061681091 | H34: =SUMPRODUCT(E34:G34,$K$15:$M$15) -> -0.005765913 | P34: =SUMPRODUCT(E34:G34,$S$15:$U$15) -> -0.0057643227 | X34: =SUMPRODUCT(E34:G34,$AA$15:$AC$15) -> -0.0060821946
A35: 2024-02-20 | B35: 181.10445 | C35: 176.62068 | D35: 401.3414 | E35: =LN(B35/B34) -> -0.0041223008 | F35: =LN(C35/C34) -> 0.0039022866 | G35: =LN(D35/D34) -> -0.0031480707 | H35: =SUMPRODUCT(E35:G35,$K$15:$M$15) -> -5.7986401e-05 | P35: =SUMPRODUCT(E35:G35,$S$15:$U$15) -> -5.4885344e-05 | X35: =SUMPRODUCT(E35:G35,$AA$15:$AC$15) -> -0.00098242238
A36: 2024-02-21 | B36: 181.86255 | C36: 177.77045 | D36: 400.73358 | E36: =LN(B36/B35) -> 0.0041772586 | F36: =LN(C36/C35) -> 0.006488701 | G36: =LN(D36/D35) -> -0.0015156157 | H36: =SUMPRODUCT(E36:G36,$K$15:$M$15) -> 0.0028035226 | P36: =SUMPRODUCT(E36:G36,$S$15:$U$15) -> 0.0028040014 | X36: =SUMPRODUCT(E36:G36,$AA$15:$AC$15) -> 0.0021480943
... A125: 2024-06-28 | B125: 210.37648 | C125: 199.92032 | D125: 446.14587 | E125: =LN(B125/B124) -> -0.016387734 | F125: =LN(C125/C124) -> 0.01539529 | G125: =LN(D125/D124) -> -0.013114188 | H125: =SUMPRODUCT(E125:G125,$K$15:$M$15) -> -0.00053940675 | P125: =SUMPRODUCT(E125:G125,$S$15:$U$15) -> -0.00052716497 | X125: =SUMPRODUCT(E125:G125,$AA$15:$AC$15) -> -0.0042389414

Sheet RiskSim
A1: SLoYkPQu0APGq0MGAJtL/Znx8FCpo3cRlNPQCK/SFyLT/B4QTyMLOyBSaZwWhemND+QaxRaqbaokYwzkNEKoudMcp2llkonQIJ8RUhZJLOcPf2KwlDB5vgyLtFsNjh9EnCdjI3bdFnNru3MQvVP68pLjTs1Ebhh5aWEnoJXwgMOw5JbeZDEVdhYD46hUVw72MNXCm4OHn5HIa8OrHDPNCDMhyPJJKX+hfq5QpBAvnlz8fFXn4OdGPRGRFdk=
A2: T2a7vcJY8J2+z0mX6gRaNagWwrZIfxPoekbaItC/DSSe1cem8TSS+Kvyhvf24QZhXISq/X4mD/EWa8vVLE4dzJNDedyREdfBMjJ9dhm+aRn0vXP232GxGGW/8cmIQ7lAr2S6r9kLXj/Ek1LHi/uQLCHNQ8v3u09iBQIees9ijrBxckAI7+z459S+pp+y0CxRvAEuRkcDbXF6CYBAo6D6fYtuvc7UqtXAObQdMK8p0WG83A906d6+LVtIbxg=
A3: 7A5bNajf2TFfp/E4YGD+Nr/7/Pm1zuVMsNY0ybMwOjo1OnPXmdmFJc3UME3/Zn4IZKLkDoNz4XtkDBrH/Q7PiSWYYzIesMvcIhK7MAoiUeeRqHWZebhdyB5I0uL+pAWW6+GaogivWEY5knZQmcDtAfZXFjKRfKmQWSXTpHcF91/kLwje96Y1d5OM4eJ9kkbgKTxHq5bxpYsnbe/fOjIwUB9dRziww+pHuM63fifM4ULVEpoCsTRX9IAouN4=
A4: 9DQSPsqoGyKknCmm61UvtfwWJacEa4cAljTfje99pSxbjAwWjLv5rktXHg3HK1uaEIxAhNAS3U5k0XulY4sAT0QIY+/531IXda7CSURY/w7zzW9qaReEErZVIhVfP2cBWVuuLtQjNumu33dbXoCf9u0Hgw+1NmL+wBBiEW8kmh8N2m1lO7Y+rHW1bY9Mw7L22uhBYBZLHgn4gu7T0lkbv3oKNIrddOoBGK4dQ7dY4stIb09bejYKf3ZX2nM=
A5: Zi1iVarUxV0eFrpsrdbo4WWWhc82X9rUGd30kmdwe5on7UD2g9bkLdNRRr/29QVQqab/vmrRjpDOUli4CmWYvXg26Q5XP5amuJdK7M5qV6qpCsHjq/6SU2PN4h1rSef6f2v8ARQQIIXXaGM8cM1QSKmHaaswZ8iKBwM85VguELc2lSxXu4wWWWLs2iMBJPP2U85cU14B/z1cyObK7HFJGH1EWR4Ynn4sH2VS/Tj1bWW3anTa/VQM4QpUWTo=
A6: gvXComL7ZgteLTFNWqsMtTjM9s4WE0iYYh++UfiO5JBHqQ+GmSetj3md9EBZ0dn970uMI5dfbWywqJ3Wp7dkiVRDi/tAatOPtJqaFywxETzwlc9Npf+d9LeV5UUXeSH4EHdSAq/OuNxgs3TSoAV/9jTM5gTmehrMKiQp3yNQJch3XZEz3vlCKu0e0rdwxjMSYoAWqNg4dLatHZMdJONl9MEsj7xP5pkQrue5Hsw9VC61BkRIG14DAK4PsPM=
A7: SZTA2KEIrIymh2DUuiC4rdegfin7KWRF+kQ9F8ZwIHmQtSTCDLB7p6gzk2E1EZyl2F9Ffo1G3o/QL79h5NvWFDDZJ7B8QDL8DArippdI2dLKLgHgjBGlE4EwZXbRtat3JpOBS7lBb9yMN5OQcmMQCyTmwDIAlWeTtiCIMKRYg/TrCJb83U58kyOoX3um1C3pDV+NIGgBqft8hAaFL4iM2XkQoiI3OumzdbD2bby5ykMnBOrl+XAYOcZeKtY=
A8: LQEVHhq9AAXwVYGUzDYY7w/hHwWXfh0DDwnFDw2zuBoE0TL+232tz7MX26XuQGhRMzu/97KddCM3cWrx54bRbiT9eTVJF25I5MxevKbgIMEIW9ZmGYHPTmuN00kk1cxfluhUD7xrVmVK/S4fmcMNpaGsxP0NA4L3maeGrw/gOsCyFx5tAFT0rRDkexRakO16SJ4azgOO5RCdepxS8M1ntBnVPAfs8H+wkum1uc4sN4jRWNv6fvrbqcPL9TI=
A9: 5E9pNi4Mfj+lc5K+0pdq8ExCfs9+hE+8ibba7TQ4bRL9OerUduYf0T87kv6oaIpAKJCGJDE7/GvoPN+RUblqXBE5WLvSEvA6WJKCaoA5Kj4ZWq1ZaOHEsz1YY4956RUzc/dnztIDZZvJgrfof25oEjyFUmXmVdBfP3tubmj4azbN9M5hXCxT4ao6MaA25uQ/q3B4QgCQFcHe51xBwrv09VeBojsrPwEO+Tlc+gZXac5N4LYrqWjvZmSsgko=
A10: mew55anf7a6xtdeS9OTSDK2tAdJXINVQEf9mRP5GFpSSZ1RWpeQNYfFHHB7bhtHrh8YPrijEbOX8sEpZtRl+Eiu+I11CucjTx5yJcDMhBHM+Dc2XdZz+O04yX8KvE2zmYpsPUkdVE9po8NKb/NUrfmc3IHaOVPJTyJWvUcDXto5T1DNyuPXrN2zcw6hr+eIRSoAB/irfTPmf3CxdY+BBuPv9GD84X9z/zU+K1yQtqNLxwopPapcfAY6nyvs=
A11: y0qP9JIPba87sEI8cLfowiLL75njcy6B4Twa+r5rAsniCaWhScm/QgXzhG7YAUzyK03LznRYDhPd4p+M76u7QmssJGynuLnaasLiTkOI0wngnkS3AHXVR/kixmdkJVuzzpRsNWs1ZpfFAz8q2hoRGkqzadb68MFl+7d5yE+AzY+GWCmtvv5eCC6GN6y/8eMZoNGSwtKwIffiIi15tnmbFRlwfpWQV4Ayg+7wtxbyhuABFtSLrBl1P5KUMIA=
A12: XELWMnr/C+mnrFt7FMDjV//IgqGztibx5kUxhYZe6eRR3JXh5DVOiJbZLF8Q9VcW58zIL5uF8Smepm8ijC7zZN9kMvVxeD+6zpadg4d8vq+Wq+74fDh+waiH0iGEIC4JoGZ+QofGyUELkxh2vodWFxVoDRjwcYrODE5QUzC2N7eE20G4Va/whB4Beq+FGA9poxPT7KlG8OQs6n/bhdPhFs66AVyddEAG2+4QbBKKg/NRFcRh8cw9Z25oOUk=
... A919: QH2PJRqsOCb9GivWyr781aHR3Cvw5K+4AXRiB0XZfJP9YZ1cBm9Y+Q==

Sheet VaR SD
A1: =Portafolio!A1 -> fecha
A2: =Portafolio!A2 -> 2024-01-02 | B2: =Portafolio!E2 -> AAPL | C2: =Portafolio!F2 -> JPM | D2: =Portafolio!G2 -> MSFT | E2: =Portafolio!H2 -> Portafolio
A3: =Portafolio!A3 -> 2024-01-03 | B3: =Portafolio!E3 -> -0.0075157276 | C3: =Portafolio!F3 -> -0.0043679949 | D3: =Portafolio!G3 -> -0.00072826083 | E3: =Portafolio!H3 -> -0.003193079 | G3: VaR Delta- Normal
A4: =Portafolio!A4 -> 2024-01-04 | B4: =Portafolio!E4 -> -0.012781429 | C4: =Portafolio!F4 -> 0.0066141592 | D4: =Portafolio!G4 -> -0.0072035078 | E4: =Portafolio!H4 -> -0.0015849665
A5: =Portafolio!A5 -> 2024-01-05 | B5: =Portafolio!E5 -> -0.0040211799 | C5: =Portafolio!F5 -> 0.0050046725 | D5: =Portafolio!G5 -> -0.0005164319 | E5: =Portafolio!H5 -> 0.0015763662 | G5: Nivel de Confianza | H5: 0.95
A6: =Portafolio!A6 -> 2024-01-08 | B6: =Portafolio!E6 -> 0.023887306 | C6: =Portafolio!F6 -> -0.0014522139 | D6: =Portafolio!G6 -> 0.018695673 | E6: =Portafolio!H6 -> 0.010152267 | G6: Horizonte de tiempo | H6: 1
A7: =Portafolio!A7 -> 2024-01-09 | B7: =Portafolio!E7 -> -0.0022659785 | C7: =Portafolio!F7 -> -0.0079374717 | D7: =Portafolio!G7 -> 0.0029313879 | E7: =Portafolio!H7 -> -0.0026313546
A8: =Portafolio!A8 -> 2024-01-10 | B8: =Portafolio!E8 -> 0.0056553893 | C8: =Portafolio!F8 -> 0.0021072531 | D8: =Portafolio!G8 -> 0.018403858 | E8: =Portafolio!H8 -> 0.0094720816 | H8: AAPL | I8: JPM | J8: MSFT | K8: Portafolio
A9: =Portafolio!A9 -> 2024-01-11 | B9: =Portafolio!E9 -> -0.0032277218 | C9: =Portafolio!F9 -> -0.0042189561 | D9: =Portafolio!G9 -> 0.0048475314 | E9: =Portafolio!H9 -> -0.00023880911 | G9: Desviación Estandar | H9: =STDEV(B3:B125) -> 0.01510321 | I9: =STDEV(C3:C125) -> 0.011965798 | J9: =STDEV(D3:D125) -> 0.011969843 | K9: =STDEV(E3:E125) -> 0.0079790845
A10: =Portafolio!A10 -> 2024-01-12 | B10: =Portafolio!E10 -> 0.0017765238 | C10: =Portafolio!F10 -> -0.0073670772 | D10: =Portafolio!G10 -> 0.0099341008 | E10: =Portafolio!H10 -> 0.0010930566 | G10: VaR por activo | H10: =H9*NORMSINV(1-$H$5)*SQRT($H$6) -> -0.02484257 | I10: =I9*NORMSINV(1-$H$5)*SQRT($H$6) -> -0.019681987 | J10: =J9*NORMSINV(1-$H$5)*SQRT($H$6) -> -0.019688639 | K10: =K9*NORMSINV(1-$H$5)*SQRT($H$6) -> -0.013124426
A11: =Portafolio!A11 -> 2024-01-16 | B11: =Portafolio!E11 -> -0.012393602 | C11: =Portafolio!F11 -> -0.0062900411 | D11: =Portafolio!G11 -> 0.0046228765 | E11: =Portafolio!H11 -> -0.0023696334
A12: =Portafolio!A12 -> 2024-01-17 | B12: =Portafolio!E12 -> -0.0051868884 | C12: =Portafolio!F12 -> -0.0053719561 | D12: =Portafolio!G12 -> -0.0020519739 | E12: =Portafolio!H12 -> -0.0039357185 | G12: VaR(%) No Diversificado | H12: =SUM(H10:J10) -> -0.064213196 | J12: CVaR
A13: =Portafolio!A13 -> 2024-01-18 | B13: =Portafolio!E13 -> 0.032051509 | C13: =Portafolio!F13 -> 0.00197306 | D13: =Portafolio!G13 -> 0.011234026 | E13: =Portafolio!H13 -> 0.0095054398 | G13: VaR(%) Diversificado | H13: =K10 -> -0.013124426 | J13: =AVERAGEIF(E3:E125,"<"&H13,$E$3:$E$125) -> -0.020743251
A14: =Portafolio!A14 -> 2024-01-19 | B14: =Portafolio!E14 -> 0.015413603 | C14: =Portafolio!F14 -> 0.017114639 | D14: =Portafolio!G14 -> 0.012113144 | E14: =Portafolio!H14 -> 0.014781335
A15: =Portafolio!A15 -> 2024-01-22 | B15: =Portafolio!E15 -> 0.012089863 | C15: =Portafolio!F15 -> -0.00117507 | D15: =Portafolio!G15 -> -0.0054326563 | E15: =Portafolio!H15 -> -0.0014064286 | G15: Exposición | H15: 100000000
A16: =Portafolio!A16 -> 2024-01-23 | B16: =Portafolio!E16 -> 0.0066312339 | C16: =Portafolio!F16 -> -0.0066056077 | D16: =Portafolio!G16 -> 0.0060094334 | E16: =Portafolio!H16 -> 0.0003466655 | G16: VaR($) No Diversificado | H16: =H12*H15 -> -6421319.6
A17: =Portafolio!A17 -> 2024-01-24 | B17: =Portafolio!E17 -> -0.0034900458 | C17: =Portafolio!F17 -> 0.008895721 | D17: =Portafolio!G17 -> 0.00913332 | E17: =Portafolio!H17 -> 0.0075196083 | G17: VaR($) Diversificado | H17: =H13*H15 -> -1312442.6
A18: =Portafolio!A18 -> 2024-01-25 | B18: =Portafolio!E18 -> -0.0016980893 | C18: =Portafolio!F18 -> 0.014209376 | D18: =Portafolio!G18 -> 0.0057219015 | E18: =Portafolio!H18 -> 0.0086967208
A19: =Portafolio!A19 -> 2024-01-26 | B19: =Portafolio!E19 -> -0.009053546 | C19: =Portafolio!F19 -> -0.0038236105 | D19: =Portafolio!G19 -> -0.0023244708 | E19: =Portafolio!H19 -> -0.0038088477
A20: =Portafolio!A20 -> 2024-01-29 | B20: =Portafolio!E20 -> -0.003592359 | C20: =Portafolio!F20 -> 0.0026085311 | D20: =Portafolio!G20 -> 0.014232447 | E20: =Portafolio!H20 -> 0.006820183
A21: =Portafolio!A21 -> 2024-01-30 | B21: =Portafolio!E21 -> -0.019433454 | C21: =Portafolio!F21 -> 0.020287326 | D21: =Portafolio!G21 -> -0.0027617483 | E21: =Portafolio!H21 -> 0.0057317365
A22: =Portafolio!A22 -> 2024-01-31 | B22: =Portafolio!E22 -> -0.019547375 | C22: =Portafolio!F22 -> -0.010894759 | D22: =Portafolio!G22 -> -0.027316063 | E22: =Portafolio!H22 -> -0.018921543
A23: =Portafolio!A23 -> 2024-02-01 | B23: =Portafolio!E23 -> 0.013252436 | C23: =Portafolio!F23 -> -0.0036198102 | D23: =Portafolio!G23 -> 0.015473981 | E23: =Portafolio!H23 -> 0.0065257348
A24: =Portafolio!A24 -> 2024-02-02 | B24: =Portafolio!E24 -> -0.0054198476 | C24: =Portafolio!F24 -> 0.0057395345 | D24: =Portafolio!G24 -> 0.01825812 | E24: =Portafolio!H24 -> 0.0097408489
A25: =Portafolio!A25 -> 2024-02-05 | B25: =Portafolio!E25 -> 0.0097984473 | C25: =Portafolio!F25 -> -0.0013172268 | D25: =Portafolio!G25 -> -0.013637507 | E25: =Portafolio!H25 -> -0.0052392854
A26: =Portafolio!A26 -> 2024-02-06 | B26: =Portafolio!E26 -> 0.0085947569 | C26: =Portafolio!F26 -> 0.0034325562 | D26: =Portafolio!G26 -> -0.00039462897 | E26: =Portafolio!H26 -> 0.0024180714
A27: =Portafolio!A27 -> 2024-02-07 | B27: =Portafolio!E27 -> 0.00058094292 | C27: =Portafolio!F27 -> 0.0018827985 | D27: =Portafolio!G27 -> 0.020890645 | E27: =Portafolio!H27 -> 0.009824009
A28: =Portafolio!A28 -> 2024-02-08 | B28: =Portafolio!E28 -> -0.005771318 | C28: =Portafolio!F28 -> -0.003597515 | D28: =Portafolio!G28 -> 0.00014479618 | E28: =Portafolio!H28 -> -0.0022627399
A29: =Portafolio!A29 -> 2024-02-09 | B29: =Portafolio!E29 -> 0.0040855553 | C29: =Portafolio!F29 -> 0.0012006105 | D29: =Portafolio!G29 -> 0.01543175 | E29: =Portafolio!H29 -> 0.0076065409
... A125: =Portafolio!A125 -> 2024-06-28 | B125: =Portafolio!E125 -> -0.016387734 | C125: =Portafolio!F125 -> 0.01539529 | D125: =Portafolio!G125 -> -0.013114188 | E125: =Portafolio!H125 -> -0.00053940675

Sheet VaR Semi-SD
A1: =Portafolio!A1 -> fecha
A2: =Portafolio!A2 -> 2024-01-02 | B2: =Portafolio!E2 -> AAPL | C2: =Portafolio!F2 -> JPM | D2: =Portafolio!G2 -> MSFT | E2: =Portafolio!H2 -> Portafolio | F2: AAPL | G2: JPM | H2: MSFT | I2: Portafolio
A3: =Portafolio!A3 -> 2024-01-03 | B3: =Portafolio!E3 -> -0.0075157276 | C3: =Portafolio!F3 -> -0.0043679949 | D3: =Portafolio!G3 -> -0.00072826083 | E3: =Portafolio!H3 -> -0.003193079 | F3: =MIN((B3-AVERAGE($B$3:$B$125)),0)^2 -> 7.3333654e-05 | G3: =MIN((C3-AVERAGE($C$3:$C$125)),0)^2 -> 3.339725e-05 | H3: =MIN((D3-AVERAGE($D$3:$D$125)),0)^2 -> 5.175473e-06 | I3: =MIN((E3-AVERAGE($E$3:$E$125)),0)^2 -> 2.1331269e-05 | K3: VaR Delta- Normal
A4: =Portafolio!A4 -> 2024-01-04 | B4: =Portafolio!E4 -> -0.012781429 | C4: =Portafolio!F4 -> 0.0066141592 | D4: =Portafolio!G4 -> -0.0072035078 | E4: =Portafolio!H4 -> -0.0015849665 | F4: =MIN((B4-AVERAGE($B$3:$B$125)),0)^2 -> 0.000191247 | G4: =MIN((C4-AVERAGE($C$3:$C$125)),0)^2 -> 0 | H4: =MIN((D4-AVERAGE($D$3:$D$125)),0)^2 -> 7.6566237e-05 | I4: =MIN((E4-AVERAGE($E$3:$E$125)),0)^2 -> 9.0629067e-06
A5: =Portafolio!A5 -> 2024-01-05 | B5: =Portafolio!E5 -> -0.0040211799 | C5: =Portafolio!F5 -> 0.0050046725 | D5: =Portafolio!G5 -> -0.0005164319 | E5: =Portafolio!H5 -> 0.0015763662 | F5: =MIN((B5-AVERAGE($B$3:$B$125)),0)^2 -> 2.5694349e-05 | G5: =MIN((C5-AVERAGE($C$3:$C$125)),0)^2 -> 0 | H5: =MIN((D5-AVERAGE($D$3:$D$125)),0)^2 -> 4.256537e-06 | I5: =MIN((E5-AVERAGE($E$3:$E$125)),0)^2 -> 0 | K5: Nivel de Confianza | L5: 0.95
A6: =Portafolio!A6 -> 2024-01-08 | B6: =Portafolio!E6 -> 0.023887306 | C6: =Portafolio!F6 -> -0.0014522139 | D6: =Portafolio!G6 -> 0.018695673 | E6: =Portafolio!H6 -> 0.010152267 | F6: =MIN((B6-AVERAGE($B$3:$B$125)),0)^2 -> 0 | G6: =MIN((C6-AVERAGE($C$3:$C$125)),0)^2 -> 8.1982255e-06 | H6: =MIN((D6-AVERAGE($D$3:$D$125)),0)^2 -> 0 | I6: =MIN((E6-AVERAGE($E$3:$E$125)),0)^2 -> 0 | K6: Horizonte de tiempo | L6: 1
A7: =Portafolio!A7 -> 2024-01-09 | B7: =Portafolio!E7 -> -0.0022659785 | C7: =Portafolio!F7 -> -0.0079374717 | D7: =Portafolio!G7 -> 0.0029313879 | E7: =Portafolio!H7 -> -0.0026313546 | F7: =MIN((B7-AVERAGE($B$3:$B$125)),0)^2 -> 1.0980992e-05 | G7: =MIN((C7-AVERAGE($C$3:$C$125)),0)^2 -> 8.739468e-05 | H7: =MIN((D7-AVERAGE($D$3:$D$125)),0)^2 -> 0 | I7: =MIN((E7-AVERAGE($E$3:$E$125)),0)^2 -> 1.6458066e-05
A8: =Portafolio!A8 -> 2024-01-10 | B8: =Portafolio!E8 -> 0.0056553893 | C8: =Portafolio!F8 -> 0.0021072531 | D8: =Portafolio!G8 -> 0.018403858 | E8: =Portafolio!H8 -> 0.0094720816 | F8: =MIN((B8-AVERAGE($B$3:$B$125)),0)^2 -> 0 | G8: =MIN((C8-AVERAGE($C$3:$C$125)),0)^2 -> 0 | H8: =MIN((D8-AVERAGE($D$3:$D$125)),0)^2 -> 0 | I8: =MIN((E8-AVERAGE($E$3:$E$125)),0)^2 -> 0 | L8: AAPL | M8: JPM | N8: MSFT | O8: Portafolio
A9: =Portafolio!A9 -> 2024-01-11 | B9: =Portafolio!E9 -> -0.0032277218 | C9: =Portafolio!F9 -> -0.0042189561 | D9: =Portafolio!G9 -> 0.0048475314 | E9: =Portafolio!H9 -> -0.00023880911 | F9: =MIN((B9-AVERAGE($B$3:$B$125)),0)^2 -> 1.8279912e-05 | G9: =MIN((C9-AVERAGE($C$3:$C$125)),0)^2 -> 3.1696861e-05 | H9: =MIN((D9-AVERAGE($D$3:$D$125)),0)^2 -> 0 | I9: =MIN((E9-AVERAGE($E$3:$E$125)),0)^2 -> 2.7699237e-06 | K9: Semi Desviación Estandar | L9: =SQRT(AVERAGE(F3:F125)) -> 0.0093930147 | M9: =SQRT(AVERAGE(G3:G125)) -> 0.0095252322 | N9: =SQRT(AVERAGE(H3:H125)) -> 0.008899706 | O9: =SQRT(AVERAGE(I3:I125)) -> 0.0061049844
A10: =Portafolio!A10 -> 2024-01-12 | B10: =Portafolio!E10 -> 0.0017765238 | C10: =Portafolio!F10 -> -0.0073670772 | D10: =Portafolio!G10 -> 0.0099341008 | E10: =Portafolio!H10 -> 0.0010930566 | F10: =MIN((B10-AVERAGE($B$3:$B$125)),0)^2 -> 0 | G10: =MIN((C10-AVERAGE($C$3:$C$125)),0)^2 -> 7.705535e-05 | H10: =MIN((D10-AVERAGE($D$3:$D$125)),0)^2 -> 0 | I10: =MIN((E10-AVERAGE($E$3:$E$125)),0)^2 -> 1.105184e-07 | K10: VaR por activo | L10: =L9*NORMSINV(1-$L$5)*SQRT($L$6) -> -0.015450134 | M10: =M9*NORMSINV(1-$L$5)*SQRT($L$6) -> -0.015667613 | N10: =N9*NORMSINV(1-$L$5)*SQRT($L$6) -> -0.014638714 | O10: =O9*NORMSINV(1-$L$5)*SQRT($L$6) -> -0.010041806
A11: =Portafolio!A11 -> 2024-01-16 | B11: =Portafolio!E11 -> -0.012393602 | C11: =Portafolio!F11 -> -0.0062900411 | D11: =Portafolio!G11 -> 0.0046228765 | E11: =Portafolio!H11 -> -0.0023696334 | F11: =MIN((B11-AVERAGE($B$3:$B$125)),0)^2 -> 0.00018067074 | G11: =MIN((C11-AVERAGE($C$3:$C$125)),0)^2 -> 5.9306658e-05 | H11: =MIN((D11-AVERAGE($D$3:$D$125)),0)^2 -> 0 | I11: =MIN((E11-AVERAGE($E$3:$E$125)),0)^2 -> 1.4403035e-05
A12: =Portafolio!A12 -> 2024-01-17 | B12: =Portafolio!E12 -> -0.0051868884 | C12: =Portafolio!F12 -> -0.0053719561 | D12: =Portafolio!G12 -> -0.0020519739 | E12: =Portafolio!H12 -> -0.0039357185 | F12: =MIN((B12-AVERAGE($B$3:$B$125)),0)^2 -> 3.8871084e-05 | G12: =MIN((C12-AVERAGE($C$3:$C$125)),0)^2 -> 4.6009042e-05 | H12: =MIN((D12-AVERAGE($D$3:$D$125)),0)^2 -> 1.2950496e-05 | I12: =MIN((E12-AVERAGE($E$3:$E$125)),0)^2 -> 2.8742661e-05 | K12: VaR(%) No Diversificado | L12: =SUM(L10:N10) -> -0.045756461 | N12: CVaR
A13: =Portafolio!A13 -> 2024-01-18 | B13: =Portafolio!E13 -> 0.032051509 | C13: =Portafolio!F13 -> 0.00197306 | D13: =Portafolio!G13 -> 0.011234026 | E13: =Portafolio!H13 -> 0.0095054398 | F13: =MIN((B13-AVERAGE($B$3:$B$125)),0)^2 -> 0 | G13: =MIN((C13-AVERAGE($C$3:$C$125)),0)^2 -> 0 | H13: =MIN((D13-AVERAGE($D$3:$D$125)),0)^2 -> 0 | I13: =MIN((E13-AVERAGE($E$3:$E$125)),0)^2 -> 0 | K13: VaR(%) Diversificado | L13: =O10 -> -0.010041806 | N13: =AVERAGEIF(E3:E125,"<"&L13,$E$3:$E$125) -> -0.01650035
A14: =Portafolio!A14 -> 2024-01-19 | B14: =Portafolio!E14 -> 0.015413603 | C14: =Portafolio!F14 -> 0.017114639 | D14: =Portafolio!G14 -> 0.012113144 | E14: =Portafolio!H14 -> 0.014781335 | F14: =MIN((B14-AVERAGE($B$3:$B$125)),0)^2 -> 0 | G14: =MIN((C14-AVERAGE($C$3:$C$125)),0)^2 -> 0 | H14: =MIN((D14-AVERAGE($D$3:$D$125)),0)^2 -> 0 | I14: =MIN((E14-AVERAGE($E$3:$E$125)),0)^2 -> 0
A15: =Portafolio!A15 -> 2024-01-22 | B15: =Portafolio!E15 -> 0.012089863 | C15: =Portafolio!F15 -> -0.00117507 | D15: =Portafolio!G15 -> -0.0054326563 | E15: =Portafolio!H15 -> -0.0014064286 | F15: =MIN((B15-AVERAGE($B$3:$B$125)),0)^2 -> 0 | G15: =MIN((C15-AVERAGE($C$3:$C$125)),0)^2 -> 6.6879674e-06 | H15: =MIN((D15-AVERAGE($D$3:$D$125)),0)^2 -> 4.8711495e-05 | I15: =MIN((E15-AVERAGE($E$3:$E$125)),0)^2 -> 8.0198176e-06 | K15: Exposición | L15: 100000000
A16: =Portafolio!A16 -> 2024-01-23 | B16: =Portafolio!E16 -> 0.0066312339 | C16: =Portafolio!F16 -> -0.0066056077 | D16: =Portafolio!G16 -> 0.0060094334 | E16: =Portafolio!H16 -> 0.0003466655 | F16: =MIN((B16-AVERAGE($B$3:$B$125)),0)^2 -> 0 | G16: =MIN((C16-AVERAGE($C$3:$C$125)),0)^2 -> 6.4266648e-05 | H16: =MIN((D16-AVERAGE($D$3:$D$125)),0)^2 -> 0 | I16: =MIN((E16-AVERAGE($E$3:$E$125)),0)^2 -> 1.1638831e-06 | K16: VaR($) No Diversificado | L16: =L12*L15 -> -4575646.1
A17: =Portafolio!A17 -> 2024-01-24 | B17: =Portafolio!E17 -> -0.0034900458 | C17: =Portafolio!F17 -> 0.008895721 | D17: =Portafolio!G17 -> 0.00913332 | E17: =Portafolio!H17 -> 0.0075196083 | F17: =MIN((B17-AVERAGE($B$3:$B$125)),0)^2 -> 2.0591858e-05 | G17: =MIN((C17-AVERAGE($C$3:$C$125)),0)^2 -> 0 | H17: =MIN((D17-AVERAGE($D$3:$D$125)),0)^2 -> 0 | I17: =MIN((E17-AVERAGE($E$3:$E$125)),0)^2 -> 0 | K17: VaR($) Diversificado | L17: =L13*L15 -> -1004180.6
A18: =Portafolio!A18 -> 2024-01-25 | B18: =Portafolio!E18 -> -0.0016980893 | C18: =Portafolio!F18 -> 0.014209376 | D18: =Portafolio!G18 -> 0.0057219015 | E18: =Portafolio!H18 -> 0.0086967208 | F18: =MIN((B18-AVERAGE($B$3:$B$125)),0)^2 -> 7.5397954e-06 | G18: =MIN((C18-AVERAGE($C$3:$C$125)),0)^2 -> 0 | H18: =MIN((D18-AVERAGE($D$3:$D$125)),0)^2 -> 0 | I18: =MIN((E18-AVERAGE($E$3:$E$125)),0)^2 -> 0
A19: =Portafolio!A19 -> 2024-01-26 | B19: =Portafolio!E19 -> -0.009053546 | C19: =Portafolio!F19 -> -0.0038236105 | D19: =Portafolio!G19 -> -0.0023244708 | E19: =Portafolio!H19 -> -0.0038088477 | F19: =MIN((B19-AVERAGE($B$3:$B$125)),0)^2 -> 0.00010203678 | G19: =MIN((C19-AVERAGE($C$3:$C$125)),0)^2 -> 2.7401571e-05 | H19: =MIN((D19-AVERAGE($D$3:$D$125)),0)^2 -> 1.4986008e-05 | I19: =MIN((E19-AVERAGE($E$3:$E$125)),0)^2 -> 2.7398392e-05
A20: =Portafolio!A20 -> 2024-01-29 | B20: =Portafolio!E20 -> -0.003592359 | C20: =Portafolio!F20 -> 0.0026085311 | D20: =Portafolio!G20 -> 0.014232447 | E20: =Portafolio!H20 -> 0.006820183 | F20: =MIN((B20-AVERAGE($B$3:$B$125)),0)^2 -> 2.1530885e-05 | G20: =MIN((C20-AVERAGE($C$3:$C$125)),0)^2 -> 0 | H20: =MIN((D20-AVERAGE($D$3:$D$125)),0)^2 -> 0 | I20: =MIN((E20-AVERAGE($E$3:$E$125)),0)^2 -> 0
A21: =Portafolio!A21 -> 2024-01-30 | B21: =Portafolio!E21 -> -0.019433454 | C21: =Portafolio!F21 -> 0.020287326 | D21: =Portafolio!G21 -> -0.0027617483 | E21: =Portafolio!H21 -> 0.0057317365 | F21: =MIN((B21-AVERAGE($B$3:$B$125)),0)^2 -> 0.00041948092 | G21: =MIN((C21-AVERAGE($C$3:$C$125)),0)^2 -> 0 | H21: =MIN((D21-AVERAGE($D$3:$D$125)),0)^2 -> 1.8562777e-05 | I21: =MIN((E21-AVERAGE($E$3:$E$125)),0)^2 -> 0
A22: =Portafolio!A22 -> 2024-01-31 | B22: =Portafolio!E22 -> -0.019547375 | C22: =Portafolio!F22 -> -0.010894759 | D22: =Portafolio!G22 -> -0.027316063 | E22: =Portafolio!H22 -> -0.018921543 | F22: =MIN((B22-AVERAGE($B$3:$B$125)),0)^2 -> 0.00042416038 | G22: =MIN((C22-AVERAGE($C$3:$C$125)),0)^2 -> 0.0001514327 | H22: =MIN((D22-AVERAGE($D$3:$D$125)),0)^2 -> 0.00083305942 | I22: =MIN((E22-AVERAGE($E$3:$E$125)),0)^2 -> 0.00041400216
A23: =Portafolio!A23 -> 2024-02-01 | B23: =Portafolio!E23 -> 0.013252436 | C23: =Portafolio!F23 -> -0.0036198102 | D23: =Portafolio!G23 -> 0.015473981 | E23: =Portafolio!H23 -> 0.0065257348 | F23: =MIN((B23-AVERAGE($B$3:$B$125)),0)^2 -> 0 | G23: =MIN((C23-AVERAGE($C$3:$C$125)),0)^2 -> 2.5309459e-05 | H23: =MIN((D23-AVERAGE($D$3:$D$125)),0)^2 -> 0 | I23: =MIN((E23-AVERAGE($E$3:$E$125)),0)^2 -> 0
A24: =Portafolio!A24 -> 2024-02-02 | B24: =Portafolio!E24 -> -0.0054198476 | C24: =Portafolio!F24 -> 0.0057395345 | D24: =Portafolio!G24 -> 0.01825812 | E24: =Portafolio!H24 -> 0.0097408489 | F24: =MIN((B24-AVERAGE($B$3:$B$125)),0)^2 -> 4.18302e-05 | G24: =MIN((C24-AVERAGE($C$3:$C$125)),0)^2 -> 0 | H24: =MIN((D24-AVERAGE($D$3:$D$125)),0)^2 -> 0 | I24: =MIN((E24-AVERAGE($E$3:$E$125)),0)^2 -> 0
A25: =Portafolio!A25 -> 2024-02-05 | B25: =Portafolio!E25 -> 0.0097984473 | C25: =Portafolio!F25 -> -0.0013172268 | D25: =Portafolio!G25 -> -0.013637507 | E25: =Portafolio!H25 -> -0.0052392854 | F25: =MIN((B25-AVERAGE($B$3:$B$125)),0)^2 -> 0 | G25: =MIN((C25-AVERAGE($C$3:$C$125)),0)^2 -> 7.4434421e-06 | H25: =MIN((D25-AVERAGE($D$3:$D$125)),0)^2 -> 0.00023056032 | I25: =MIN((E25-AVERAGE($E$3:$E$125)),0)^2 -> 4.4419359e-05
A26: =Portafolio!A26 -> 2024-02-06 | B26: =Portafolio!E26 -> 0.0085947569 | C26: =Portafolio!F26 -> 0.0034325562 | D26: =Portafolio!G26 -> -0.00039462897 | E26: =Portafolio!H26 -> 0.0024180714 | F26: =MIN((B26-AVERAGE($B$3:$B$125)),0)^2 -> 0 | G26: =MIN((C26-AVERAGE($C$3:$C$125)),0)^2 -> 0 | H26: =MIN((D26-AVERAGE($D$3:$D$125)),0)^2 -> 3.7687806e-06 | I26: =MIN((E26-AVERAGE($E$3:$E$125)),0)^2 -> 0
A27: =Portafolio!A27 -> 2024-02-07 | B27: =Portafolio!E27 -> 0.00058094292 | C27: =Portafolio!F27 -> 0.0018827985 | D27: =Portafolio!G27 -> 0.020890645 | E27: =Portafolio!H27 -> 0.009824009 | F27: =MIN((B27-AVERAGE($B$3:$B$125)),0)^2 -> 2.179364e-07 | G27: =MIN((C27-AVERAGE($C$3:$C$125)),0)^2 -> 0 | H27: =MIN((D27-AVERAGE($D$3:$D$125)),0)^2 -> 0 | I27: =MIN((E27-AVERAGE($E$3:$E$125)),0)^2 -> 0
A28: =Portafolio!A28 -> 2024-02-08 | B28: =Portafolio!E28 -> -0.005771318 | C28: =Portafolio!F28 -> -0.003597515 | D28: =Portafolio!G28 -> 0.00014479618 | E28: =Portafolio!H28 -> -0.0022627399 | F28: =MIN((B28-AVERAGE($B$3:$B$125)),0)^2 -> 4.650009e-05 | G28: =MIN((C28-AVERAGE($C$3:$C$125)),0)^2 -> 2.5085628e-05 | H28: =MIN((D28-AVERAGE($D$3:$D$125)),0)^2 -> 1.9653505e-06 | I28: =MIN((E28-AVERAGE($E$3:$E$125)),0)^2 -> 1.3603111e-05
A29: =Portafolio!A29 -> 2024-02-09 | B29: =Portafolio!E29 -> 0.0040855553 | C29: =Portafolio!F29 -> 0.0012006105 | D29: =Portafolio!G29 -> 0.01543175 | E29: =Portafolio!H29 -> 0.0076065409 | F29: =MIN((B29-AVERAGE($B$3:$B$125)),0)^2 -> 0 | G29: =MIN((C29-AVERAGE($C$3:$C$125)),0)^2 -> 4.4280789e-08 | H29: =MIN((D29-AVERAGE($D$3:$D$125)),0)^2 -> 0 | I29: =MIN((E29-AVERAGE($E$3:$E$125)),0)^2 -> 0
... A125: =Portafolio!A125 -> 2024-06-28 | B125: =Portafolio!E125 -> -0.016387734 | C125: =Portafolio!F125 -> 0.01539529 | D125: =Portafolio!G125 -> -0.013114188 | E125: =Portafolio!H125 -> -0.00053940675 | F125: =MIN((B125-AVERAGE($B$3:$B$125)),0)^2 -> 0.00030399714 | G125: =MIN((C125-AVERAGE($C$3:$C$125)),0)^2 -> 0 | H125: =MIN((D125-AVERAGE($D$3:$D$125)),0)^2 -> 0.00021494182 | I125: =MIN((E125-AVERAGE($E$3:$E$125)),0)^2 -> 3.8608572e-06

Sheet VaR No Parametrico
A1: =Portafolio!A1 -> fecha
A2: =Portafolio!A2 -> 2024-01-02 | B2: =Portafolio!E2 -> AAPL | C2: =Portafolio!F2 -> JPM | D2: =Portafolio!G2 -> MSFT | E2: =Portafolio!H2 -> Portafolio
A3: =Portafolio!A3 -> 2024-01-03 | B3: =Portafolio!E3 -> -0.0075157276 | C3: =Portafolio!F3 -> -0.0043679949 | D3: =Portafolio!G3 -> -0.00072826083 | E3: =Portafolio!H3 -> -0.003193079 | G3: VaR No-Parametrico
A4: =Portafolio!A4 -> 2024-01-04 | B4: =Portafolio!E4 -> -0.012781429 | C4: =Portafolio!F4 -> 0.0066141592 | D4: =Portafolio!G4 -> -0.0072035078 | E4: =Portafolio!H4 -> -0.0015849665
A5: =Portafolio!A5 -> 2024-01-05 | B5: =Portafolio!E5 -> -0.0040211799 | C5: =Portafolio!F5 -> 0.0050046725 | D5: =Portafolio!G5 -> -0.0005164319 | E5: =Portafolio!H5 -> 0.0015763662
A6: =Portafolio!A6 -> 2024-01-08 | B6: =Portafolio!E6 -> 0.023887306 | C6: =Portafolio!F6 -> -0.0014522139 | D6: =Portafolio!G6 -> 0.018695673 | E6: =Portafolio!H6 -> 0.010152267 | G6: Horizonte de tiempo | H6: 1
A7: =Portafolio!A7 -> 2024-01-09 | B7: =Portafolio!E7 -> -0.0022659785 | C7: =Portafolio!F7 -> -0.0079374717 | D7: =Portafolio!G7 -> 0.0029313879 | E7: =Portafolio!H7 -> -0.0026313546
A8: =Portafolio!A8 -> 2024-01-10 | B8: =Portafolio!E8 -> 0.0056553893 | C8: =Portafolio!F8 -> 0.0021072531 | D8: =Portafolio!G8 -> 0.018403858 | E8: =Portafolio!H8 -> 0.0094720816 | H8: AAPL | I8: JPM | J8: MSFT | K8: Portafolio
A9: =Portafolio!A9 -> 2024-01-11 | B9: =Portafolio!E9 -> -0.0032277218 | C9: =Portafolio!F9 -> -0.0042189561 | D9: =Portafolio!G9 -> 0.0048475314 | E9: =Portafolio!H9 -> -0.00023880911 | G9: Rentabilidad al 5% | H9: =_xlfn.PERCENTILE.INC(B3:B125,5%) -> -0.019535983 | I9: =_xlfn.PERCENTILE.INC(C3:C125,5%) -> -0.012300017 | J9: =_xlfn.PERCENTILE.INC(D3:D125,5%) -> -0.020798288 | K9: =_xlfn.PERCENTILE.INC(E3:E125,5%) -> -0.011206536
A10: =Portafolio!A10 -> 2024-01-12 | B10: =Portafolio!E10 -> 0.0017765238 | C10: =Portafolio!F10 -> -0.0073670772 | D10: =Portafolio!G10 -> 0.0099341008 | E10: =Portafolio!H10 -> 0.0010930566 | G10: VaR por activo | H10: =H9*SQRT($H$6) -> -0.019535983 | I10: =I9*SQRT($H$6) -> -0.012300017 | J10: =J9*SQRT($H$6) -> -0.020798288 | K10: =K9*SQRT($H$6) -> -0.011206536
A11: =Portafolio!A11 -> 2024-01-16 | B11: =Portafolio!E11 -> -0.012393602 | C11: =Portafolio!F11 -> -0.0062900411 | D11: =Portafolio!G11 -> 0.0046228765 | E11: =Portafolio!H11 -> -0.0023696334
A12: =Portafolio!A12 -> 2024-01-17 | B12: =Portafolio!E12 -> -0.0051868884 | C12: =Portafolio!F12 -> -0.0053719561 | D12: =Portafolio!G12 -> -0.0020519739 | E12: =Portafolio!H12 -> -0.0039357185 | G12: VaR(%) No Diversificado | H12: =SUM(H10:J10) -> -0.052634288 | J12: CVaR
A13: =Portafolio!A13 -> 2024-01-18 | B13: =Portafolio!E13 -> 0.032051509 | C13: =Portafolio!F13 -> 0.00197306 | D13: =Portafolio!G13 -> 0.011234026 | E13: =Portafolio!H13 -> 0.0095054398 | G13: VaR(%) Diversificado | H13: =K10 -> -0.011206536 | J13: =AVERAGEIF(E3:E125,"<"&H13,$E$3:$E$125) -> -0.018090595
A14: =Portafolio!A14 -> 2024-01-19 | B14: =Portafolio!E14 -> 0.015413603 | C14: =Portafolio!F14 -> 0.017114639 | D14: =Portafolio!G14 -> 0.012113144 | E14: =Portafolio!H14 -> 0.014781335
A15: =Portafolio!A15 -> 2024-01-22 | B15: =Portafolio!E15 -> 0.012089863 | C15: =Portafolio!F15 -> -0.00117507 | D15: =Portafolio!G15 -> -0.0054326563 | E15: =Portafolio!H15 -> -0.0014064286 | G15: Exposición | H15: 100000000
A16: =Portafolio!A16 -> 2024-01-23 | B16: =Portafolio!E16 -> 0.0066312339 | C16: =Portafolio!F16 -> -0.0066056077 | D16: =Portafolio!G16 -> 0.0060094334 | E16: =Portafolio!H16 -> 0.0003466655 | G16: VaR($) No Diversificado | H16: =H12*H15 -> -5263428.8
A17: =Portafolio!A17 -> 2024-01-24 | B17: =Portafolio!E17 -> -0.0034900458 | C17: =Portafolio!F17 -> 0.008895721 | D17: =Portafolio!G17 -> 0.00913332 | E17: =Portafolio!H17 -> 0.0075196083 | G17: VaR($) Diversificado | H17: =H13*H15 -> -1120653.6
A18: =Portafolio!A18 -> 2024-01-25 | B18: =Portafolio!E18 -> -0.0016980893 | C18: =Portafolio!F18 -> 0.014209376 | D18: =Portafolio!G18 -> 0.0057219015 | E18: =Portafolio!H18 -> 0.0086967208
A19: =Portafolio!A19 -> 2024-01-26 | B19: =Portafolio!E19 -> -0.009053546 | C19: =Portafolio!F19 -> -0.0038236105 | D19: =Portafolio!G19 -> -0.0023244708 | E19: =Portafolio!H19 -> -0.0038088477
A20: =Portafolio!A20 -> 2024-01-29 | B20: =Portafolio!E20 -> -0.003592359 | C20: =Portafolio!F20 -> 0.0026085311 | D20: =Portafolio!G20 -> 0.014232447 | E20: =Portafolio!H20 -> 0.006820183
A21: =Portafolio!A21 -> 2024-01-30 | B21: =Portafolio!E21 -> -0.019433454 | C21: =Portafolio!F21 -> 0.020287326 | D21: =Portafolio!G21 -> -0.0027617483 | E21: =Portafolio!H21 -> 0.0057317365
A22: =Portafolio!A22 -> 2024-01-31 | B22: =Portafolio!E22 -> -0.019547375 | C22: =Portafolio!F22 -> -0.010894759 | D22: =Portafolio!G22 -> -0.027316063 | E22: =Portafolio!H22 -> -0.018921543
A23: =Portafolio!A23 -> 2024-02-01 | B23: =Portafolio!E23 -> 0.013252436 | C23: =Portafolio!F23 -> -0.0036198102 | D23: =Portafolio!G23 -> 0.015473981 | E23: =Portafolio!H23 -> 0.0065257348
A24: =Portafolio!A24 -> 2024-02-02 | B24: =Portafolio!E24 -> -0.0054198476 | C24: =Portafolio!F24 -> 0.0057395345 | D24: =Portafolio!G24 -> 0.01825812 | E24: =Portafolio!H24 -> 0.0097408489
A25: =Portafolio!A25 -> 2024-02-05 | B25: =Portafolio!E25 -> 0.0097984473 | C25: =Portafolio!F25 -> -0.0013172268 | D25: =Portafolio!G25 -> -0.013637507 | E25: =Portafolio!H25 -> -0.0052392854
A26: =Portafolio!A26 -> 2024-02-06 | B26: =Portafolio!E26 -> 0.0085947569 | C26: =Portafolio!F26 -> 0.0034325562 | D26: =Portafolio!G26 -> -0.00039462897 | E26: =Portafolio!H26 -> 0.0024180714
A27: =Portafolio!A27 -> 2024-02-07 | B27: =Portafolio!E27 -> 0.00058094292 | C27: =Portafolio!F27 -> 0.0018827985 | D27: =Portafolio!G27 -> 0.020890645 | E27: =Portafolio!H27 -> 0.009824009
A28: =Portafolio!A28 -> 2024-02-08 | B28: =Portafolio!E28 -> -0.005771318 | C28: =Portafolio!F28 -> -0.003597515 | D28: =Portafolio!G28 -> 0.00014479618 | E28: =Portafolio!H28 -> -0.0022627399
A29: =Portafolio!A29 -> 2024-02-09 | B29: =Portafolio!E29 -> 0.0040855553 | C29: =Portafolio!F29 -> 0.0012006105 | D29: =Portafolio!G29 -> 0.01543175 | E29: =Portafolio!H29 -> 0.0076065409
... A125: =Portafolio!A125 -> 2024-06-28 | B125: =Portafolio!E125 -> -0.016387734 | C125: =Portafolio!F125 -> 0.01539529 | D125: =Portafolio!G125 -> -0.013114188 | E125: =Portafolio!H125 -> -0.00053940675

Sheet VaR Montecarlo
A1: =Portafolio!A1 -> fecha
A2: =Portafolio!A2 -> 2024-01-02 | B2: =Portafolio!E2 -> AAPL | C2: =Portafolio!F2 -> JPM | D2: =Portafolio!G2 -> MSFT | E2: =Portafolio!H2 -> Portafolio
A3: =Portafolio!A3 -> 2024-01-03 | B3: =Portafolio!E3 -> -0.0075157276 | C3: =Portafolio!F3 -> -0.0043679949 | D3: =Portafolio!G3 -> -0.00072826083 | E3: =Portafolio!H3 -> -0.003193079 | G3: VaR - Simulación por Montecarlo
A4: =Portafolio!A4 -> 2024-01-04 | B4: =Portafolio!E4 -> -0.012781429 | C4: =Portafolio!F4 -> 0.0066141592 | D4: =Portafolio!G4 -> -0.0072035078 | E4: =Portafolio!H4 -> -0.0015849665
A5: =Portafolio!A5 -> 2024-01-05 | B5: =Portafolio!E5 -> -0.0040211799 | C5: =Portafolio!F5 -> 0.0050046725 | D5: =Portafolio!G5 -> -0.0005164319 | E5: =Portafolio!H5 -> 0.0015763662 | G5: Horizonte de tiempo | H5: 1
A6: =Portafolio!A6 -> 2024-01-08 | B6: =Portafolio!E6 -> 0.023887306 | C6: =Portafolio!F6 -> -0.0014522139 | D6: =Portafolio!G6 -> 0.018695673 | E6: =Portafolio!H6 -> 0.010152267
A7: =Portafolio!A7 -> 2024-01-09 | B7: =Portafolio!E7 -> -0.0022659785 | C7: =Portafolio!F7 -> -0.0079374717 | D7: =Portafolio!G7 -> 0.0029313879 | E7: =Portafolio!H7 -> -0.0026313546 | H7: AAPL | I7: JPM | J7: MSFT | K7: Portafolio
A8: =Portafolio!A8 -> 2024-01-10 | B8: =Portafolio!E8 -> 0.0056553893 | C8: =Portafolio!F8 -> 0.0021072531 | D8: =Portafolio!G8 -> 0.018403858 | E8: =Portafolio!H8 -> 0.0094720816 | G8: Distribución Entrada | H8: 0.0010477795 | I8: 0.0014110405 | J8: 0.0015467058 | K8: 0.001366095
A9: =Portafolio!A9 -> 2024-01-11 | B9: =Portafolio!E9 -> -0.0032277218 | C9: =Portafolio!F9 -> -0.0042189561 | D9: =Portafolio!G9 -> 0.0048475314 | E9: =Portafolio!H9 -> -0.00023880911 | G9: Retronos Simulados al 5% | H9: =H8 -> 0.0010477795 | I9: =I8 -> 0.0014110405 | J9: =J8 -> 0.0015467058 | K9: =K8 -> 0.001366095
A10: =Portafolio!A10 -> 2024-01-12 | B10: =Portafolio!E10 -> 0.0017765238 | C10: =Portafolio!F10 -> -0.0073670772 | D10: =Portafolio!G10 -> 0.0099341008 | E10: =Portafolio!H10 -> 0.0010930566 | G10: VaR por activo | H10: {=_xll.ROV.RiskSim.RSFunctions.RSForecastStatistic(H9,"Percentile0.05")*SQRT($H$5)} -> -0.019217653 | I10: {=_xll.ROV.RiskSim.RSFunctions.RSForecastStatistic(I9,"Percentile0.05")*SQRT($H$5)} -> -0.014338209 | J10: {=_xll.ROV.RiskSim.RSFunctions.RSForecastStatistic(J9,"Percentile0.05")*SQRT($H$5)} -> -0.01745371 | K10: {=_xll.ROV.RiskSim.RSFunctions.RSForecastStatistic(K9,"Percentile0.05")*SQRT($H$5)} -> -0.010822775
A11: =Portafolio!A11 -> 2024-01-16 | B11: =Portafolio!E11 -> -0.012393602 | C11: =Portafolio!F11 -> -0.0062900411 | D11: =Portafolio!G11 -> 0.0046228765 | E11: =Portafolio!H11 -> -0.0023696334
A12: =Portafolio!A12 -> 2024-01-17 | B12: =Portafolio!E12 -> -0.0051868884 | C12: =Portafolio!F12 -> -0.0053719561 | D12: =Portafolio!G12 -> -0.0020519739 | E12: =Portafolio!H12 -> -0.0039357185 | G12: VaR(%) No Diversificado | H12: =SUM(H10:J10) -> -0.051009572 | J12: CVaR
A13: =Portafolio!A13 -> 2024-01-18 | B13: =Portafolio!E13 -> 0.032051509 | C13: =Portafolio!F13 -> 0.00197306 | D13: =Portafolio!G13 -> 0.011234026 | E13: =Portafolio!H13 -> 0.0095054398 | G13: VaR(%) Diversificado | H13: =K10 -> -0.010822775 | J13: =AVERAGEIF(E3:E125,"<"&H13,$E$3:$E$125) -> -0.017211633
A14: =Portafolio!A14 -> 2024-01-19 | B14: =Portafolio!E14 -> 0.015413603 | C14: =Portafolio!F14 -> 0.017114639 | D14: =Portafolio!G14 -> 0.012113144 | E14: =Portafolio!H14 -> 0.014781335
A15: =Portafolio!A15 -> 2024-01-22 | B15: =Portafolio!E15 -> 0.012089863 | C15: =Portafolio!F15 -> -0.00117507 | D15: =Portafolio!G15 -> -0.0054326563 | E15: =Portafolio!H15 -> -0.0014064286 | G15: Exposición | H15: 100000000
A16: =Portafolio!A16 -> 2024-01-23 | B16: =Portafolio!E16 -> 0.0066312339 | C16: =Portafolio!F16 -> -0.0066056077 | D16: =Portafolio!G16 -> 0.0060094334 | E16: =Portafolio!H16 -> 0.0003466655 | G16: VaR($) No Diversificado | H16: =H12*H15 -> -5100957.2
A17: =Portafolio!A17 -> 2024-01-24 | B17: =Portafolio!E17 -> -0.0034900458 | C17: =Portafolio!F17 -> 0.008895721 | D17: =Portafolio!G17 -> 0.00913332 | E17: =Portafolio!H17 -> 0.0075196083 | G17: VaR($) Diversificado | H17: =H13*H15 -> -1082277.5
A18: =Portafolio!A18 -> 2024-01-25 | B18: =Portafolio!E18 -> -0.0016980893 | C18: =Portafolio!F18 -> 0.014209376 | D18: =Portafolio!G18 -> 0.0057219015 | E18: =Portafolio!H18 -> 0.0086967208
A19: =Portafolio!A19 -> 2024-01-26 | B19: =Portafolio!E19 -> -0.009053546 | C19: =Portafolio!F19 -> -0.0038236105 | D19: =Portafolio!G19 -> -0.0023244708 | E19: =Portafolio!H19 -> -0.0038088477
A20: =Portafolio!A20 -> 2024-01-29 | B20: =Portafolio!E20 -> -0.003592359 | C20: =Portafolio!F20 -> 0.0026085311 | D20: =Portafolio!G20 -> 0.014232447 | E20: =Portafolio!H20 -> 0.006820183
A21: =Portafolio!A21 -> 2024-01-30 | B21: =Portafolio!E21 -> -0.019433454 | C21: =Portafolio!F21 -> 0.020287326 | D21: =Portafolio!G21 -> -0.0027617483 | E21: =Portafolio!H21 -> 0.0057317365
A22: =Portafolio!A22 -> 2024-01-31 | B22: =Portafolio!E22 -> -0.019547375 | C22: =Portafolio!F22 -> -0.010894759 | D22: =Portafolio!G22 -> -0.027316063 | E22: =Portafolio!H22 -> -0.018921543
A23: =Portafolio!A23 -> 2024-02-01 | B23: =Portafolio!E23 -> 0.013252436 | C23: =Portafolio!F23 -> -0.0036198102 | D23: =Portafolio!G23 -> 0.015473981 | E23: =Portafolio!H23 -> 0.0065257348
A24: =Portafolio!A24 -> 2024-02-02 | B24: =Portafolio!E24 -> -0.0054198476 | C24: =Portafolio!F24 -> 0.0057395345 | D24: =Portafolio!G24 -> 0.01825812 | E24: =Portafolio!H24 -> 0.0097408489
A25: =Portafolio!A25 -> 2024-02-05 | B25: =Portafolio!E25 -> 0.0097984473 | C25: =Portafolio!F25 -> -0.0013172268 | D25: =Portafolio!G25 -> -0.013637507 | E25: =Portafolio!H25 -> -0.0052392854
A26: =Portafolio!A26 -> 2024-02-06 | B26: =Portafolio!E26 -> 0.0085947569 | C26: =Portafolio!F26 -> 0.0034325562 | D26: =Portafolio!G26 -> -0.00039462897 | E26: =Portafolio!H26 -> 0.0024180714
A27: =Portafolio!A27 -> 2024-02-07 | B27: =Portafolio!E27 -> 0.00058094292 | C27: =Portafolio!F27 -> 0.0018827985 | D27: =Portafolio!G27 -> 0.020890645 | E27: =Portafolio!H27 -> 0.009824009
A28: =Portafolio!A28 -> 2024-02-08 | B28: =Portafolio!E28 -> -0.005771318 | C28: =Portafolio!F28 -> -0.003597515 | D28: =Portafolio!G28 -> 0.00014479618 | E28: =Portafolio!H28 -> -0.0022627399
A29: =Portafolio!A29 -> 2024-02-09 | B29: =Portafolio!E29 -> 0.0040855553 | C29: =Portafolio!F29 -> 0.0012006105 | D29: =Portafolio!G29 -> 0.01543175 | E29: =Portafolio!H29 -> 0.0076065409
... A125: =Portafolio!A125 -> 2024-06-28 | B125: =Portafolio!E125 -> -0.016387734 | C125: =Portafolio!F125 -> 0.01539529 | D125: =Portafolio!G125 -> -0.013114188 | E125: =Portafolio!H125 -> -0.00053940675

Sheet Ajuste Distribución MC
B1: Ajuste de Distribución de Variables Múltiples
B3: Resumen Estadístico
D5: Nombre de la Variable | E5: AAPL | H5: Nombre de la Variable | I5: JPM | L5: Nombre de la Variable | M5: MSFT
D6: Mejor Supuesto Ajustado | E6: 0.0010477795 | H6: Mejor Supuesto Ajustado | I6: 0.0014110405 | L6: Mejor Supuesto Ajustado | M6: 0.0015467058
D8: Distribución Ajustada | E8: Gumbel Máxima | H8: Distribución Ajustada | I8: Normal | L8: Distribución Ajustada | M8: Logística
D9: Alfa | E9: -0.0048845365 | H9: Media | I9: 0.0022611462 | L9: Alfa | M9: 0.0019352512
D10: Beta | E10: 0.011370615 | H10: Desv.Est | I10: 0.010259976 | L10: Beta | M10: 0.0064611129
D13: Estadístico Kolmogorov-Smirnov | E13: 0.058199618 | H13: Estadístico Kolmogorov-Smirnov | I13: 0.043001077 | L13: Estadístico Kolmogorov-Smirnov | M13: 0.044470329
D14: Prueba Estadística de P-Value | E14: 0.787311 | H14: Prueba Estadística de P-Value | I14: 0.97405333 | L14: Prueba Estadística de P-Value | M14: 0.96459556
D16: Real | E16: Teórica | H16: Real | I16: Teórica | L16: Real | M16: Teórica
C17: Media | D17: 0.0010477795 | E17: 0.0016787608 | G17: Media | H17: 0.0014110405 | I17: 0.0022611462 | K17: Media | L17: 0.0015467058 | M17: 0.0019352512
C18: Desviación Estándar | D18: 0.01510321 | E18: 0.014583381 | G18: Desviación Estándar | H18: 0.011965798 | I18: 0.010259976 | K18: Desviación Estándar | L18: 0.011969843 | M18: 0.011719163
C19: Asimetría | D19: 1.1626748 | E19: 1.1395471 | G19: Asimetría | H19: -1.9080999 | I19: 0 | K19: Asimetría | L19: -0.52595914 | M19: 0
C20: Curtosis | D20: 4.549767 | E20: 2.4 | G20: Curtosis | H20: 9.3075653 | I20: 0 | K20: Curtosis | L20: 0.60124165 | M20: 1.2
D23: Nombre de la Variable | E23: Portafolio
D24: Mejor Supuesto Ajustado | E24: 0.001366095
D26: Distribución Ajustada | E26: Beta Desplazada
D27: Ubicación | E27: -0.033432763
D28: Alfa | E28: 19.510149
D29: Beta | E29: 530.89667
D31: Estadístico Kolmogorov-Smirnov | E31: 0.050585439
D32: Prueba Estadística de P-Value | E32: 0.90407327
D34: Real | E34: Teórica
C35: Media | D35: 0.001366095 | E35: 0.002014016
C36: Desviación Estándar | D36: 0.0078073005 | E36: 0.0078743628
C37: Asimetría | D37: -0.81313858 | E37: 0.42718994
C38: Curtosis | D38: 2.4976101 | E38: 0.26240029
B40: Matriz de Correlación
C42: AAPL | D42: JPM | E42: MSFT | F42: Portafolio
B43: AAPL | C43: 1
B44: JPM | C44: -0.13971785 | D44: 1
B45: MSFT | C45: 0.37314185 | D45: 0.012571687 | E45: 1
B46: Portafolio | C46: 0.52516406 | D46: 0.65788794 | E46: 0.63556466 | F46: 1

Sheet VaR GARCH
A1: =Portafolio!A1 -> fecha | B1: AAPL | C1: JPM | D1: MSFT | E1: Portafolio
A2: =Portafolio!A2 -> 2024-01-02 | B2: 184.93822 | C2: 168.0667 | D2: 368.8541 | E2: =SUMPRODUCT(Portafolio!B2:D2,Portafolio!$K$15:$M$15) -> 255.60548 | F2: =Portafolio!H2 -> Portafolio
A3: =Portafolio!A3 -> 2024-01-03 | B3: 183.55348 | C3: 167.33418 | D3: 368.58557 | E3: =SUMPRODUCT(Portafolio!B3:D3,Portafolio!$K$15:$M$15) -> 254.99281 | F3: =Portafolio!H3 -> -0.003193079 | H3: VaR - Volatilidad Condicional al Tiempo
A4: =Portafolio!A4 -> 2024-01-04 | B4: 181.22234 | C4: 168.44463 | D4: 365.94 | E4: =SUMPRODUCT(Portafolio!B4:D4,Portafolio!$K$15:$M$15) -> 254.09287 | F4: =Portafolio!H4 -> -0.0015849665
A5: =Portafolio!A5 -> 2024-01-05 | B5: 180.49507 | C5: 169.28975 | D5: 365.75107 | E5: =SUMPRODUCT(Portafolio!B5:D5,Portafolio!$K$15:$M$15) -> 254.30998 | F5: =Portafolio!H5 -> 0.0015763662 | H5: Nivel de Confianza | I5: 0.95
A6: =Portafolio!A6 -> 2024-01-08 | B6: 184.85852 | C6: 169.04408 | D6: 372.65335 | E6: =SUMPRODUCT(Portafolio!B6:D6,Portafolio!$K$15:$M$15) -> 257.65877 | F6: =Portafolio!H6 -> 0.010152267 | H6: Horizonte de tiempo | I6: 1
A7: =Portafolio!A7 -> 2024-01-09 | B7: 184.44011 | C7: 167.70761 | D7: 373.74734 | E7: =SUMPRODUCT(Portafolio!B7:D7,Portafolio!$K$15:$M$15) -> 257.46707 | F7: =Portafolio!H7 -> -0.0026313546
A8: =Portafolio!A8 -> 2024-01-10 | B8: 185.48614 | C8: 168.06139 | D8: 380.68942 | E8: =SUMPRODUCT(Portafolio!B8:D8,Portafolio!$K$15:$M$15) -> 260.70974 | F8: =Portafolio!H8 -> 0.0094720816 | I8: AAPL | J8: JPM | K8: MSFT | L8: Portafolio
A9: =Portafolio!A9 -> 2024-01-11 | B9: 184.88841 | C9: 167.35384 | D9: 382.53931 | E9: =SUMPRODUCT(Portafolio!B9:D9,Portafolio!$K$15:$M$15) -> 261.10464 | F9: =Portafolio!H9 -> -0.00023880911 | H9: Desviación Estandar | I9: ='GARCH AAPL'!$D$141*SQRT(1/252) -> 0.015053796 | J9: ='GARCH JPM'!$D$141*SQRT(1/252) -> 0.011903914 | K9: ='GARCH MSFT'!$D$141*SQRT(1/252) -> 0.01192445 | L9: ='GARCH Portafolio'!$D$141*SQRT(1/252) -> 0.0081535267
A10: =Portafolio!A10 -> 2024-01-12 | B10: 185.21716 | C10: 166.12546 | D10: 386.35843 | E10: =SUMPRODUCT(Portafolio!B10:D10,Portafolio!$K$15:$M$15) -> 262.212 | F10: =Portafolio!H10 -> 0.0010930566 | H10: VaR por activo | I10: =I9*NORMSINV(1-$I$5)*SQRT($I$6) -> -0.024761291 | J10: =J9*NORMSINV(1-$I$5)*SQRT($I$6) -> -0.019580197 | K10: =K9*NORMSINV(1-$I$5)*SQRT($I$6) -> -0.019613974 | L10: =L9*NORMSINV(1-$I$5)*SQRT($I$6) -> -0.013411358
A11: =Portafolio!A11 -> 2024-01-16 | B11: 182.93582 | C11: 165.0838 | D11: 388.14865 | E11: =SUMPRODUCT(Portafolio!B11:D11,Portafolio!$K$15:$M$15) -> 262.22873 | F11: =Portafolio!H11 -> -0.0023696334
A12: =Portafolio!A12 -> 2024-01-17 | B12: 181.98941 | C12: 164.19936 | D12: 387.353 | E12: =SUMPRODUCT(Portafolio!B12:D12,Portafolio!$K$15:$M$15) -> 261.37472 | F12: =Portafolio!H12 -> -0.0039357185 | H12: VaR(%) No Diversificado | I12: =SUM(I10:K10) -> -0.063955462 | K12: CVaR
A13: =Portafolio!A13 -> 2024-01-18 | B13: 187.91693 | C13: 164.52365 | D13: 391.72906 | E13: =SUMPRODUCT(Portafolio!B13:D13,Portafolio!$K$15:$M$15) -> 264.09321 | F13: =Portafolio!H13 -> 0.0095054398 | H13: VaR(%) Diversificado | I13: =L10 -> -0.013411358 | K13: =AVERAGEIF(F3:F125,"<"&I13,$F$3:$F$125) -> -0.020743251
A14: =Portafolio!A14 -> 2024-01-19 | B14: 190.83585 | C14: 167.36365 | D14: 396.50299 | E14: =SUMPRODUCT(Portafolio!B14:D14,Portafolio!$K$15:$M$15) -> 267.76639 | F14: =Portafolio!H14 -> 0.014781335
A15: =Portafolio!A15 -> 2024-01-22 | B15: 193.15703 | C15: 167.1671 | D15: 394.35477 | E15: =SUMPRODUCT(Portafolio!B15:D15,Portafolio!$K$15:$M$15) -> 267.03882 | F15: =Portafolio!H15 -> -0.0014064286 | H15: Exposición | I15: 100000000
A16: =Portafolio!A16 -> 2024-01-23 | B16: 194.44215 | C16: 166.0665 | D16: 396.73175 | E16: =SUMPRODUCT(Portafolio!B16:D16,Portafolio!$K$15:$M$15) -> 267.70407 | F16: =Portafolio!H16 -> 0.0003466655 | H16: VaR($) No Diversificado | I16: =I12*I15 -> -6395546.2
A17: =Portafolio!A17 -> 2024-01-24 | B17: 193.76472 | C17: 167.55037 | D17: 400.37183 | E17: =SUMPRODUCT(Portafolio!B17:D17,Portafolio!$K$15:$M$15) -> 269.8486 | F17: =Portafolio!H17 -> 0.0075196083 | H17: VaR($) Diversificado | I17: =I13*I15 -> -1341135.8
A18: =Portafolio!A18 -> 2024-01-25 | B18: 193.43597 | C18: 169.94815 | D18: 402.66928 | E18: =SUMPRODUCT(Portafolio!B18:D18,Portafolio!$K$15:$M$15) -> 271.87844 | F18: =Portafolio!H18 -> 0.0086967208
A19: =Portafolio!A19 -> 2024-01-26 | B19: 191.6926 | C19: 169.29958 | D19: 401.73438 | E19: =SUMPRODUCT(Portafolio!B19:D19,Portafolio!$K$15:$M$15) -> 270.97731 | F19: =Portafolio!H19 -> -0.0038088477
A20: =Portafolio!A20 -> 2024-01-29 | B20: 191.0052 | C20: 169.74178 | D20: 407.49292 | E20: =SUMPRODUCT(Portafolio!B20:D20,Portafolio!$K$15:$M$15) -> 273.5493 | F20: =Portafolio!H20 -> 0.006820183
A21: =Portafolio!A21 -> 2024-01-30 | B21: 187.32915 | C21: 173.22055 | D21: 406.36908 | E21: =SUMPRODUCT(Portafolio!B21:D21,Portafolio!$K$15:$M$15) -> 274.21418 | F21: =Portafolio!H21 -> 0.0057317365
A22: =Portafolio!A22 -> 2024-01-31 | B22: 183.70291 | C22: 171.3436 | D22: 395.41891 | E22: =SUMPRODUCT(Portafolio!B22:D22,Portafolio!$K$15:$M$15) -> 268.26379 | F22: =Portafolio!H22 -> -0.018921543
