Workbook

Sheet Diccionario
B2: ¿QUÉ HACE ESTE CASO DIFERENTE?
B3: Este caso trabaja con las PROBABILIDADES que entrega el modelo, no con métricas agregadas. El modelo asigna a cada solicitante una probabilidad predicha de default (P(default)). Tú eliges un UMBRAL DE CORTE: si P(default) > umbral → RECHAZADO. Todas las métricas (TP, FP, Sensitivity, Specificity) y el impacto financiero se derivan automáticamente de cómo ese umbral divide la distribución de scores.
B5: CONCEPTOS CLAVE | D5: Matríz de Confusión | F5: Realidad
B6: ✦ Perfil de score: Agrupación de solicitantes por probabilidad predicha de default (ej: 20%-30%). | F6: Buen pagador | G6: Mal Pagador (Default)
B7: ✦ %PI Modelo (P̂): Probabilidad de default que asigna el modelo a esa banda. | D7: Modelo | E7: Buen pagador | F7: Verdadero Negativo (VN) | G7: Falso Negativo (FN)
B8: ✦ %PI Observada: Tasa de default observada históricamente en esa banda (ground truth). | F8: Gano margen | G8: Sufro pérdidas
B9: ✦ Umbral de corte: Si PD predicha ≥ umbral → RECHAZAR. Es la única palanca de decisión. | E9: Mal Pagador (Default) | F9: Falso Positivo (FP) | G9: Verdadero Positivo (VP)
B10: ✦ VP (Verdadero Positivo): Defaults correctamente rechazados. Evitas una pérdida. | F10: Pierdo margen | G10: Evito pérdida
B11: ✦ FP (Falso Positivo): Buenos clientes rechazados por error. Pierdes el margen.
B12: ✦ VN (Verdadero Negativo): Buenos clientes aprobados. Ganas el margen.
B13: ✦ FN (Falso Negativo): Defaults aprobados por error. Sufres la pérdida.
B14: ✦ Pérdida esperada (PE): EL = PD × LGD × EAD por cada préstamo aprobado.

Sheet Salida Modelo
A1: Id | B1: Default | C1: Probablidad
A2: 930 | B2: 0 | C2: 0.6038 | E2: Número de Clientes | F2: =+COUNT(A2:A501) -> 500
A3: 477 | B3: 0 | C3: 0.0179 | E3: Clientes Default (#) | F3: =+SUM(B2:B501) -> 129
A4: 914 | B4: 1 | C4: 0.6936 | E4: Clientes Default (%) | F4: =+AVERAGE(B2:B501) -> 0.258
A5: 946 | B5: 0 | C5: 0.0225
A6: 398 | B6: 0 | C6: 0.0181
A7: 639 | B7: 1 | C7: 0.5363
A8: 291 | B8: 1 | C8: 0.705
A9: 938 | B9: 0 | C9: 0.2576
A10: 772 | B10: 0 | C10: 0.3804
A11: 441 | B11: 0 | C11: 0.2101
A12: 248 | B12: 1 | C12: 0.4844
A13: 271 | B13: 1 | C13: 0.6212
A14: 158 | B14: 1 | C14: 0.6694
A15: 591 | B15: 1 | C15: 0.51
A16: 568 | B16: 0 | C16: 0.1327
... A501: 403 | B501: 0 | C501: 0.057

Sheet Análisis
B2: Id | C2: Default | D2: Probablidad | E2: Y(Prob.)
B3: 930 | C3: 0 | D3: 0.6038 | E3: =+IF(D3>=$H$3,1,0) -> 1 | G3: Umbral | H3: 0.5
B4: 477 | C4: 0 | D4: 0.0179 | E4: =+IF(D4>=$H$3,1,0) -> 0
B5: 914 | C5: 1 | D5: 0.6936 | E5: =+IF(D5>=$H$3,1,0) -> 1
B6: 946 | C6: 0 | D6: 0.0225 | E6: =+IF(D6>=$H$3,1,0) -> 0 | G6: Mátriz Confusión | H6: Observado
B7: 398 | C7: 0 | D7: 0.0181 | E7: =+IF(D7>=$H$3,1,0) -> 0 | H7: 0 | I7: 1 | J7: Total general
B8: 639 | C8: 1 | D8: 0.5363 | E8: =+IF(D8>=$H$3,1,0) -> 1 | G8: 0 | H8: =+COUNTIFS($C$3:$C$502,H7,$E$3:$E$502,G8) -> 346 | I8: =+COUNTIFS($C$3:$C$502,I7,$E$3:$E$502,G8) -> 87 | J8: =+SUM(H8:I8) -> 433 | L8: Accuaracy | M8: =+(H8+I9)/J10 -> 0.776
B9: 291 | C9: 1 | D9: 0.705 | E9: =+IF(D9>=$H$3,1,0) -> 1 | G9: 1 | H9: =+COUNTIFS($C$3:$C$502,H7,$E$3:$E$502,G9) -> 25 | I9: =+COUNTIFS($C$3:$C$502,I7,$E$3:$E$502,G9) -> 42 | J9: =+SUM(H9:I9) -> 67 | L9: Recall% | M9: =+I9/(I9+I8) -> 0.3255814
B10: 938 | C10: 0 | D10: 0.2576 | E10: =+IF(D10>=$H$3,1,0) -> 0 | G10: Total general | H10: =+SUM(H8:H9) -> 371 | I10: =+SUM(I8:I9) -> 129 | J10: =+SUM(J8:J9) -> 500 | L10: Precisión% | M10: =+I9/(I9+H9) -> 0.62686567
B11: 772 | C11: 0 | D11: 0.3804 | E11: =+IF(D11>=$H$3,1,0) -> 0
B12: 441 | C12: 0 | D12: 0.2101 | E12: =+IF(D12>=$H$3,1,0) -> 0 | G12: Perfiles | H12: #Clientes | I12: Probabilidad | J12: Default
B13: 248 | C13: 1 | D13: 0.4844 | E13: =+IF(D13>=$H$3,1,0) -> 0 | G13: 0,0008-0,1008 | H13: 169 | I13: 0.045432544 | J13: 0.065088757
B14: 271 | C14: 1 | D14: 0.6212 | E14: =+IF(D14>=$H$3,1,0) -> 1 | G14: 0,1008-0,2008 | H14: 114 | I14: 0.14964737 | J14: 0.14912281
B15: 158 | C15: 1 | D15: 0.6694 | E15: =+IF(D15>=$H$3,1,0) -> 1 | G15: 0,2008-0,3008 | H15: 50 | I15: 0.246946 | J15: 0.32
B16: 591 | C16: 1 | D16: 0.51 | E16: =+IF(D16>=$H$3,1,0) -> 1 | G16: 0,3008-0,4008 | H16: 70 | I16: 0.34773 | J16: 0.37142857
B17: 568 | C17: 0 | D17: 0.1327 | E17: =+IF(D17>=$H$3,1,0) -> 0 | G17: 0,4008-0,5008 | H17: 30 | I17: 0.45403333 | J17: 0.56666667
B18: 461 | C18: 0 | D18: 0.1901 | E18: =+IF(D18>=$H$3,1,0) -> 0 | G18: 0,5008-0,6008 | H18: 22 | I18: 0.54809091 | J18: 0.5
B19: 672 | C19: 0 | D19: 0.3522 | E19: =+IF(D19>=$H$3,1,0) -> 0 | G19: 0,6008-0,7008 | H19: 23 | I19: 0.64431739 | J19: 0.73913043
B20: 636 | C20: 0 | D20: 0.0699 | E20: =+IF(D20>=$H$3,1,0) -> 0 | G20: 0,7008-0,8008 | H20: 15 | I20: 0.74704667 | J20: 0.6
B21: 958 | C21: 0 | D21: 0.1945 | E21: =+IF(D21>=$H$3,1,0) -> 0 | G21: 0,8008-0,9008 | H21: 4 | I21: 0.850275 | J21: 0.5
B22: 102 | C22: 0 | D22: 0.1509 | E22: =+IF(D22>=$H$3,1,0) -> 0 | G22: 0,9008-1,0008 | H22: 3 | I22: 0.9386 | J22: 1
B23: 745 | C23: 0 | D23: 0.0062 | E23: =+IF(D23>=$H$3,1,0) -> 0 | G23: Total general | H23: 500 | I23: 0.2386944 | J23: 0.258
B24: 117 | C24: 1 | D24: 0.283 | E24: =+IF(D24>=$H$3,1,0) -> 0
B25: 919 | C25: 0 | D25: 0.2759 | E25: =+IF(D25>=$H$3,1,0) -> 0
B26: 765 | C26: 0 | D26: 0.2956 | E26: =+IF(D26>=$H$3,1,0) -> 0
B27: 262 | C27: 0 | D27: 0.1568 | E27: =+IF(D27>=$H$3,1,0) -> 0
B28: 294 | C28: 0 | D28: 0.1697 | E28: =+IF(D28>=$H$3,1,0) -> 0 | G28: Agrupación de perfiles
B29: 951 | C29: 1 | D29: 0.3903 | E29: =+IF(D29>=$H$3,1,0) -> 0 | G29: Perfiles | H29: #Clientes | I29: Probabilidad | J29: Default
B30: 631 | C30: 0 | D30: 0.0436 | E30: =+IF(D30>=$H$3,1,0) -> 0 | G30: 0.0000-0.1000 | H30: 168 | I30: 0.045208333 | J30: 0.06547619
B31: 405 | C31: 0 | D31: 0.5941 | E31: =+IF(D31>=$H$3,1,0) -> 1 | G31: 0.1000-0.1500 | H31: 56 | I31: 0.12317857 | J31: 0.089285714
B32: 561 | C32: 0 | D32: 0.0443 | E32: =+IF(D32>=$H$3,1,0) -> 0 | G32: 0.1500-0.2000 | H32: 56 | I32: 0.172625 | J32: 0.19642857
B33: 306 | C33: 0 | D33: 0.0275 | E33: =+IF(D33>=$H$3,1,0) -> 0 | G33: 0.2000-0.3000 | H33: 53 | I33: 0.24437736 | J33: 0.32075472
B34: 935 | C34: 0 | D34: 0.1355 | E34: =+IF(D34>=$H$3,1,0) -> 0 | G34: 0.3000-0.4500 | H34: 85 | I34: 0.36195294 | J34: 0.37647059
B35: 400 | C35: 0 | D35: 0.5057 | E35: =+IF(D35>=$H$3,1,0) -> 1 | G35: 0.4500-0.6000 | H35: 37 | I35: 0.52056757 | J35: 0.59459459
B36: 767 | C36: 1 | D36: 0.4897 | E36: =+IF(D36>=$H$3,1,0) -> 0 | G36: 0.6000-0.9000 | H36: 42 | I36: 0.70052381 | J36: 0.66666667
B37: 831 | C37: 1 | D37: 0.3327 | E37: =+IF(D37>=$H$3,1,0) -> 0 | G37: 0.9000-1.0000 | H37: 3 | I37: 0.93866667 | J37: 1
B38: 963 | C38: 0 | D38: 0.0928 | E38: =+IF(D38>=$H$3,1,0) -> 0 | G38: Total general | H38: =+SUM(H30:H37) -> 500 | I38: 0.238754 | J38: 0.258
B39: 901 | C39: 0 | D39: 0.4579 | E39: =+IF(D39>=$H$3,1,0) -> 0
B40: 552 | C40: 1 | D40: 0.1895 | E40: =+IF(D40>=$H$3,1,0) -> 0
B41: 563 | C41: 1 | D41: 0.7846 | E41: =+IF(D41>=$H$3,1,0) -> 1
...

Sheet CdN. Crédito
B2: CASO DE NEGOCIO: MODELO DE RIESGO DE CRÉDITO CON SCORING DE PROBABILIDADES
B5: A. SUPUESTOS FINANCIEROS
B6: Variable | E6: Valor | F6: Unidad | G6: Notas
B7: Monto promedio del préstamo (EAD) (X) | E7: 10000 | F7: USD | G7: Exposure at Default
B8: LGD — Pérdida dado el default (Y) | E8: 0.9 | F8: % | G8: % del préstamo no recuperado tras default
B9: Margen neto por préstamo cumplido (Z) | E9: 2500 | F9: USD | G9: Intereses - costo fondos - gastos operativos
B10: Costo operativo por decisión (modelo) (W) | E10: 0.5 | F10: USD/solicitud | G10: Con automatización; sin modelo sería $35
B12: B. DISTRIBUCIÓN DE SCORES + PÉRDIDA ESPERADA POR BANDA
B13: Perfil | C13: Rango Probabilidad | D13: %PI Modelo (A) | E13: # Solicitudes (B) | F13: #PI Observada (C) | G13: #Clientes en Default (D) | H13: PE Modelo (F) | I13: PE Observado | J13: Calibración | L13: Ingreso potencial (Observado) | M13: Ingreso potencial (Con Modelo)
G14: (B*C) | H14: (A*B)*X*Y | I14: (B*C)*X*Y | J14: (A)/(C) | L14: B*(1-C)*Z | M14: B*(1-C)*Z | O14: ¿Qué tan preciso es el Modelo? - ¿Qué tan bien estimi el modelo la pérdida futura?
B15: Perfil 1 | C15: =+Análisis!G30 -> 0.0000-0.1000 | D15: =+Análisis!I30 -> 0.045208333 | E15: =+Análisis!H30 -> 168 | F15: =+Análisis!J30 -> 0.06547619 | G15: =ROUND(E15*F15,0) -> 11 | H15: =E15*D15*E8*E7 -> 68355 | I15: =E15*F15*E8*E7 -> 99000 | J15: =IFERROR(D15/F15,"N/A") -> 0.69045455 | L15: =E15*(1-F15)*$E$9 -> 392500 | M15: =E15*(1-D15)*$E$9 -> 401012.5 | O15: Calibración | P15: =+J23 -> 0.9254031 | Q15: El modelo tiene una calibración global de 0.925 (ratio PD predicha / default real), lo que significa que el modelo es levemente optimista: subestima los defaults rea
B16: Perfil 2 | C16: =+Análisis!G31 -> 0.1000-0.1500 | D16: =+Análisis!I31 -> 0.12317857 | E16: =+Análisis!H31 -> 56 | F16: =+Análisis!J31 -> 0.089285714 | G16: =ROUND(E16*F16,0) -> 5 | H16: =E16*D16*E8*E7 -> 62082 | I16: =E16*F16*E8*E7 -> 45000 | J16: =IFERROR(D16/F16,"N/A") -> 1.3796 | L16: =E16*(1-F16)*$E$9 -> 127500 | M16: =E16*(1-D16)*$E$9 -> 122755
B17: Perfil 3 | C17: =+Análisis!G32 -> 0.1500-0.2000 | D17: =+Análisis!I32 -> 0.172625 | E17: =+Análisis!H32 -> 56 | F17: =+Análisis!J32 -> 0.19642857 | G17: =ROUND(E17*F17,0) -> 11 | H17: =E17*D17*E8*E7 -> 87003 | I17: =E17*F17*E8*E7 -> 99000 | J17: =IFERROR(D17/F17,"N/A") -> 0.87881818 | L17: =E17*(1-F17)*$E$9 -> 112500 | M17: =E17*(1-D17)*$E$9 -> 115832.5
B18: Perfil 4 | C18: =+Análisis!G33 -> 0.2000-0.3000 | D18: =+Análisis!I33 -> 0.24437736 | E18: =+Análisis!H33 -> 53 | F18: =+Análisis!J33 -> 0.32075472 | G18: =ROUND(E18*F18,0) -> 17 | H18: =E18*D18*E8*E7 -> 116568 | I18: =E18*F18*E8*E7 -> 153000 | J18: =IFERROR(D18/F18,"N/A") -> 0.76188235 | L18: =E18*(1-F18)*$E$9 -> 90000 | M18: =E18*(1-D18)*$E$9 -> 100120 | O18: Ingreso potencial (con modelo) | P18: =+M23-L23 -> 24057.5 | Q18: El modelo subestima ligeramente los defaults reales, por lo tanto sobreestima el ingreso esperado en ~$24K. Eso es una señal de que el modelo es optimista, no de que sea rentable.
B19: Perfil 5 | C19: =+Análisis!G34 -> 0.3000-0.4500 | D19: =+Análisis!I34 -> 0.36195294 | E19: =+Análisis!H34 -> 85 | F19: =+Análisis!J34 -> 0.37647059 | G19: =ROUND(E19*F19,0) -> 32 | H19: =E19*D19*E8*E7 -> 276894 | I19: =E19*F19*E8*E7 -> 288000 | J19: =IFERROR(D19/F19,"N/A") -> 0.9614375 | L19: =E19*(1-F19)*$E$9 -> 132500 | M19: =E19*(1-D19)*$E$9 -> 135585
B20: Perfil 6 | C20: =+Análisis!G35 -> 0.4500-0.6000 | D20: =+Análisis!I35 -> 0.52056757 | E20: =+Análisis!H35 -> 37 | F20: =+Análisis!J35 -> 0.59459459 | G20: =ROUND(E20*F20,0) -> 22 | H20: =E20*D20*E8*E7 -> 173349 | I20: =E20*F20*E8*E7 -> 198000 | J20: =IFERROR(D20/F20,"N/A") -> 0.8755 | L20: =E20*(1-F20)*$E$9 -> 37500 | M20: =E20*(1-D20)*$E$9 -> 44347.5
B21: Perfil 7 | C21: =+Análisis!G36 -> 0.6000-0.9000 | D21: =+Análisis!I36 -> 0.70052381 | E21: =+Análisis!H36 -> 42 | F21: =+Análisis!J36 -> 0.66666667 | G21: =ROUND(E21*F21,0) -> 28 | H21: =E21*D21*E8*E7 -> 264798 | I21: =E21*F21*E8*E7 -> 252000 | J21: =IFERROR(D21/F21,"N/A") -> 1.0507857 | L21: =E21*(1-F21)*$E$9 -> 35000 | M21: =E21*(1-D21)*$E$9 -> 31445 | O21: Ahorro en provisiones por PE (con modelo) | P21: =+I23-H23 -> 86607 | Q21: El modelo dejaría al banco sub-provisionado en $86K respecto a la pérdida real observada. Eso es un riesgo, no un beneficio.
B22: Perfil 8 | C22: =+Análisis!G37 -> 0.9000-1.0000 | D22: =+Análisis!I37 -> 0.93866667 | E22: =+Análisis!H37 -> 3 | F22: =+Análisis!J37 -> 1 | G22: =ROUND(E22*F22,0) -> 3 | H22: =E22*D22*E8*E7 -> 25344 | I22: =E22*F22*E8*E7 -> 27000 | J22: =IFERROR(D22/F22,"N/A") -> 0.93866667 | L22: =E22*(1-F22)*$E$9 -> 0 | M22: =E22*(1-D22)*$E$9 -> 460
B23: TOTAL (T) | E23: 500 | G23: =SUM(G15:G22) -> 129 | H23: =SUM(H15:H22) -> 1074393 | I23: =SUM(I15:I22) -> 1161000 | J23: =IFERROR(H23/I23,0) -> 0.9254031 | L23: =SUM(L15:L22) -> 927500 | M23: =SUM(M15:M22) -> 951557.5
B27: C. COMPARACIÓN MULTI-UMBRAL (beneficio neto por cada política de corte)
B28: Esta tabla simula qué pasaría si el banco aplicara cada umbral posible. Cada fila usa las bandas de la sección B para calcular los FP, FN y el Beneficio Neto resultante. Identifica el umbral que MAXIMIZA el Beneficio Neto.
B29: Umbral de corte (1) | C29: Perfil aprobadas (2) | D29: Aprobados total (3) | E29: FN (defaults aprobados) (4) | F29: Sufro Pérdidas (FN) (5) | G29: FP (buenos rechazados) (6) | H29: Pierdo Margen (FP) (7) | I29: Margen (VN) (8) | J29: Beneficio Neto (9) | L29: ¿Óptimo?
D30: (1)<(A) = (B) | E30: (1)<(A) = (D) | F30: (4)*X*Y | G30: (1)>(A) = (B-D) | H30: (6)*Z | I30: (1)<(A) = (B-D)*Z | J30: (8-7-5)-(T*W) | O30: ¿Cuánto mejor le va al banco cuando ACTÚA basándose en el modelo (umbral óptimo) vs. cuando aprueba a todos ciegamente (umbral al 99%)?
B31: 0.1 | C31: Perfil 1 | D31: =IF(D15<B31,E15,0)+IF(D16<B31,E16,0)+IF(D17<B31,E17,0)+IF(D18<B31,E18,0)+IF(D19<B31,E19,0)+IF(D20<B31,E20,0)+IF(D21<B31,E21,0)+IF(D22<B31,E22,0) -> 168 | E31: =IF(D15<B31,G15,0)+IF(D16<B31,G16,0)+IF(D17<B31,G17,0)+IF(D18<B31,G18,0)+IF(D19<B31,G19,0)+IF(D20<B31,G20,0)+IF(D21<B31,G21,0)+IF(D22<B31,G22,0) -> 11 | F31: =+E31*$E$7*$E$8 -> 99000 | G31: =IF(D15>=B31,(E15-G15),0)+IF(D16>=B31,(E16-G16),0)+IF(D17>=B31,(E17-G17),0)+IF(D18>=B31,(E18-G18),0)+IF(D19>=B31,(E19-G19),0)+IF(D20>=B31,(E20-G20),0)+IF(D21>=B31,(E21-G21),0)+IF(D22>=B31,(E22-G22),0) -> 214 | H31: =+G31*$E$9 -> 535000 | I31: =(IF(D15<B31,(E15-G15),0)+IF(D16<B31,(E16-G16),0)+IF(D17<B31,(E17-G17),0)+IF(D18<B31,(E18-G18),0)+IF(D19<B31,(E19-G19),0)+IF(D20<B31,(E20-G20),0)+IF(D21<B31,(E21-G21),0)+IF(D22<B31,(E22-G22),0))*E9 -> 392500 | J31: =+I31-H31-F31-($E$23*$E$10) -> -241750 | L31: =IF(J31=MAX(J31:J38),"⭐ ÓPTIMO","") | O31: Se ve el valor real: con el umbral óptimo de 30%, el banco obtiene un beneficio neto de $121,250, versus los -$233,750 de aprobar a todos sin modelo. Ese es el número que deberías presentar como el argumento de negocio.
B32: 0.2 | C32: Perfil 1–2 | D32: =IF(D15<B32,E15,0)+IF(D16<B32,E16,0)+IF(D17<B32,E17,0)+IF(D18<B32,E18,0)+IF(D19<B32,E19,0)+IF(D20<B32,E20,0)+IF(D21<B32,E21,0)+IF(D22<B32,E22,0) -> 280 | E32: =IF(D15<B32,G15,0)+IF(D16<B32,G16,0)+IF(D17<B32,G17,0)+IF(D18<B32,G18,0)+IF(D19<B32,G19,0)+IF(D20<B32,G20,0)+IF(D21<B32,G21,0)+IF(D22<B32,G22,0) -> 27 | F32: =+E32*$E$7*$E$8 -> 243000 | G32: =IF(D15>=B32,(E15-G15),0)+IF(D16>=B32,(E16-G16),0)+IF(D17>=B32,(E17-G17),0)+IF(D18>=B32,(E18-G18),0)+IF(D19>=B32,(E19-G19),0)+IF(D20>=B32,(E20-G20),0)+IF(D21>=B32,(E21-G21),0)+IF(D22>=B32,(E22-G22),0) -> 118 | H32: =+G32*$E$9 -> 295000 | I32: =(IF(D15<B32,(E15-G15),0)+IF(D16<B32,(E16-G16),0)+IF(D17<B32,(E17-G17),0)+IF(D18<B32,(E18-G18),0)+IF(D19<B32,(E19-G19),0)+IF(D20<B32,(E20-G20),0)+IF(D21<B32,(E21-G21),0)+IF(D22<B32,(E22-G22),0))*E9 -> 632500 | J32: =+I32-H32-F32-($E$23*$E$10) -> 94250 | L32: =IF(J32=MAX(J31:J38),"⭐ ÓPTIMO","")
B33: 0.3 | C33: Perfil 1–3 | D33: =IF(D15<B33,E15,0)+IF(D16<B33,E16,0)+IF(D17<B33,E17,0)+IF(D18<B33,E18,0)+IF(D19<B33,E19,0)+IF(D20<B33,E20,0)+IF(D21<B33,E21,0)+IF(D22<B33,E22,0) -> 333 | E33: =IF(D15<B33,G15,0)+IF(D16<B33,G16,0)+IF(D17<B33,G17,0)+IF(D18<B33,G18,0)+IF(D19<B33,G19,0)+IF(D20<B33,G20,0)+IF(D21<B33,G21,0)+IF(D22<B33,G22,0) -> 44 | F33: =+E33*$E$7*$E$8 -> 396000 | G33: =IF(D15>=B33,(E15-G15),0)+IF(D16>=B33,(E16-G16),0)+IF(D17>=B33,(E17-G17),0)+IF(D18>=B33,(E18-G18),0)+IF(D19>=B33,(E19-G19),0)+IF(D20>=B33,(E20-G20),0)+IF(D21>=B33,(E21-G21),0)+IF(D22>=B33,(E22-G22),0) -> 82 | H33: =+G33*$E$9 -> 205000 | I33: =(IF(D15<B33,(E15-G15),0)+IF(D16<B33,(E16-G16),0)+IF(D17<B33,(E17-G17),0)+IF(D18<B33,(E18-G18),0)+IF(D19<B33,(E19-G19),0)+IF(D20<B33,(E20-G20),0)+IF(D21<B33,(E21-G21),0)+IF(D22<B33,(E22-G22),0))*E9 -> 722500 | J33: =+I33-H33-F33-($E$23*$E$10) -> 121250 | L33: =IF(J33=MAX(J31:J38),"⭐ ÓPTIMO","") -> ⭐ ÓPTIMO
B34: 0.4 | C34: Perfil 1–4 | D34: =IF(D15<B34,E15,0)+IF(D16<B34,E16,0)+IF(D17<B34,E17,0)+IF(D18<B34,E18,0)+IF(D19<B34,E19,0)+IF(D20<B34,E20,0)+IF(D21<B34,E21,0)+IF(D22<B34,E22,0) -> 418 | E34: =IF(D15<B34,G15,0)+IF(D16<B34,G16,0)+IF(D17<B34,G17,0)+IF(D18<B34,G18,0)+IF(D19<B34,G19,0)+IF(D20<B34,G20,0)+IF(D21<B34,G21,0)+IF(D22<B34,G22,0) -> 76 | F34: =+E34*$E$7*$E$8 -> 684000 | G34: =IF(D15>=B34,(E15-G15),0)+IF(D16>=B34,(E16-G16),0)+IF(D17>=B34,(E17-G17),0)+IF(D18>=B34,(E18-G18),0)+IF(D19>=B34,(E19-G19),0)+IF(D20>=B34,(E20-G20),0)+IF(D21>=B34,(E21-G21),0)+IF(D22>=B34,(E22-G22),0) -> 29 | H34: =+G34*$E$9 -> 72500 | I34: =(IF(D15<B34,(E15-G15),0)+IF(D16<B34,(E16-G16),0)+IF(D17<B34,(E17-G17),0)+IF(D18<B34,(E18-G18),0)+IF(D19<B34,(E19-G19),0)+IF(D20<B34,(E20-G20),0)+IF(D21<B34,(E21-G21),0)+IF(D22<B34,(E22-G22),0))*E9 -> 855000 | J34: =+I34-H34-F34-($E$23*$E$10) -> 98250 | L34: =IF(J34=MAX(J31:J38),"⭐ ÓPTIMO","") | O34: El umbral 0.1 da −$241,750, peor que aprobar a todos. ¿Por qué? Porque rechazas a 214 buenos clientes (FP) y pierdes $535K en márgenes no capturados, y eso no lo compensa evitar solo 11 defaults. El modelo puede hacerte daño si el umbral es demasiado bajo.
B35: 0.5 | C35: Perfil 1–5 | D35: =IF(D15<B35,E15,0)+IF(D16<B35,E16,0)+IF(D17<B35,E17,0)+IF(D18<B35,E18,0)+IF(D19<B35,E19,0)+IF(D20<B35,E20,0)+IF(D21<B35,E21,0)+IF(D22<B35,E22,0) -> 418 | E35: =IF(D15<B35,G15,0)+IF(D16<B35,G16,0)+IF(D17<B35,G17,0)+IF(D18<B35,G18,0)+IF(D19<B35,G19,0)+IF(D20<B35,G20,0)+IF(D21<B35,G21,0)+IF(D22<B35,G22,0) -> 76 | F35: =+E35*$E$7*$E$8 -> 684000 | G35: =IF(D15>=B35,(E15-G15),0)+IF(D16>=B35,(E16-G16),0)+IF(D17>=B35,(E17-G17),0)+IF(D18>=B35,(E18-G18),0)+IF(D19>=B35,(E19-G19),0)+IF(D20>=B35,(E20-G20),0)+IF(D21>=B35,(E21-G21),0)+IF(D22>=B35,(E22-G22),0) -> 29 | H35: =+G35*$E$9 -> 72500 | I35: =(IF(D15<B35,(E15-G15),0)+IF(D16<B35,(E16-G16),0)+IF(D17<B35,(E17-G17),0)+IF(D18<B35,(E18-G18),0)+IF(D19<B35,(E19-G19),0)+IF(D20<B35,(E20-G20),0)+IF(D21<B35,(E21-G21),0)+IF(D22<B35,(E22-G22),0))*E9 -> 855000 | J35: =+I35-H35-F35-($E$23*$E$10) -> 98250 | L35: =IF(J35=MAX(J31:J38),"⭐ ÓPTIMO","")
B36: 0.6 | C36: Perfil 1–6 | D36: =IF(D15<B36,E15,0)+IF(D16<B36,E16,0)+IF(D17<B36,E17,0)+IF(D18<B36,E18,0)+IF(D19<B36,E19,0)+IF(D20<B36,E20,0)+IF(D21<B36,E21,0)+IF(D22<B36,E22,0) -> 455 | E36: =IF(D15<B36,G15,0)+IF(D16<B36,G16,0)+IF(D17<B36,G17,0)+IF(D18<B36,G18,0)+IF(D19<B36,G19,0)+IF(D20<B36,G20,0)+IF(D21<B36,G21,0)+IF(D22<B36,G22,0) -> 98 | F36: =+E36*$E$7*$E$8 -> 882000 | G36: =IF(D15>=B36,(E15-G15),0)+IF(D16>=B36,(E16-G16),0)+IF(D17>=B36,(E17-G17),0)+IF(D18>=B36,(E18-G18),0)+IF(D19>=B36,(E19-G19),0)+IF(D20>=B36,(E20-G20),0)+IF(D21>=B36,(E21-G21),0)+IF(D22>=B36,(E22-G22),0) -> 14 | H36: =+G36*$E$9 -> 35000 | I36: =(IF(D15<B36,(E15-G15),0)+IF(D16<B36,(E16-G16),0)+IF(D17<B36,(E17-G17),0)+IF(D18<B36,(E18-G18),0)+IF(D19<B36,(E19-G19),0)+IF(D20<B36,(E20-G20),0)+IF(D21<B36,(E21-G21),0)+IF(D22<B36,(E22-G22),0))*E9 -> 892500 | J36: =+I36-H36-F36-($E$23*$E$10) -> -24750 | L36: =IF(J36=MAX(J31:J38),"⭐ ÓPTIMO","")
B37: 0.7 | C37: Perfil 1–7 | D37: =IF(D15<B37,E15,0)+IF(D16<B37,E16,0)+IF(D17<B37,E17,0)+IF(D18<B37,E18,0)+IF(D19<B37,E19,0)+IF(D20<B37,E20,0)+IF(D21<B37,E21,0)+IF(D22<B37,E22,0) -> 455 | E37: =IF(D15<B37,G15,0)+IF(D16<B37,G16,0)+IF(D17<B37,G17,0)+IF(D18<B37,G18,0)+IF(D19<B37,G19,0)+IF(D20<B37,G20,0)+IF(D21<B37,G21,0)+IF(D22<B37,G22,0) -> 98 | F37: =+E37*$E$7*$E$8 -> 882000 | G37: =IF(D15>=B37,(E15-G15),0)+IF(D16>=B37,(E16-G16),0)+IF(D17>=B37,(E17-G17),0)+IF(D18>=B37,(E18-G18),0)+IF(D19>=B37,(E19-G19),0)+IF(D20>=B37,(E20-G20),0)+IF(D21>=B37,(E21-G21),0)+IF(D22>=B37,(E22-G22),0) -> 14 | H37: =+G37*$E$9 -> 35000 | I37: =(IF(D15<B37,(E15-G15),0)+IF(D16<B37,(E16-G16),0)+IF(D17<B37,(E17-G17),0)+IF(D18<B37,(E18-G18),0)+IF(D19<B37,(E19-G19),0)+IF(D20<B37,(E20-G20),0)+IF(D21<B37,(E21-G21),0)+IF(D22<B37,(E22-G22),0))*E9 -> 892500 | J37: =+I37-H37-F37-($E$23*$E$10) -> -24750 | L37: =IF(J37=MAX(J31:J38),"⭐ ÓPTIMO","") | O37: Mira el umbral 0.99 (aprobar a todos): el beneficio neto es −$233,750. Eso significa que el banco, si aprobara todo sin filtro, perdería dinero. El modelo no solo mejora resultados, es condición necesaria para que el negocio sea rentable.
B38: 0.99 | C38: Todas (1–8) | D38: =IF(D15<B38,E15,0)+IF(D16<B38,E16,0)+IF(D17<B38,E17,0)+IF(D18<B38,E18,0)+IF(D19<B38,E19,0)+IF(D20<B38,E20,0)+IF(D21<B38,E21,0)+IF(D22<B38,E22,0) -> 500 | E38: =IF(D15<B38,G15,0)+IF(D16<B38,G16,0)+IF(D17<B38,G17,0)+IF(D18<B38,G18,0)+IF(D19<B38,G19,0)+IF(D20<B38,G20,0)+IF(D21<B38,G21,0)+IF(D22<B38,G22,0) -> 129 | F38: =+E38*$E$7*$E$8 -> 1161000 | G38: =IF(D15>=B38,(E15-G15),0)+IF(D16>=B38,(E16-G16),0)+IF(D17>=B38,(E17-G17),0)+IF(D18>=B38,(E18-G18),0)+IF(D19>=B38,(E19-G19),0)+IF(D20>=B38,(E20-G20),0)+IF(D21>=B38,(E21-G21),0)+IF(D22>=B38,(E22-G22),0) -> 0 | H38: =+G38*$E$9 -> 0 | I38: =(IF(D15<B38,(E15-G15),0)+IF(D16<B38,(E16-G16),0)+IF(D17<B38,(E17-G17),0)+IF(D18<B38,(E18-G18),0)+IF(D19<B38,(E19-G19),0)+IF(D20<B38,(E20-G20),0)+IF(D21<B38,(E21-G21),0)+IF(D22<B38,(E22-G22),0))*E9 -> 927500 | J38: =+I38-H38-F38-($E$23*$E$10) -> -233750 | L38: =IF(J38=MAX(J31:J38),"⭐ ÓPTIMO","")
